Workbook

Sheet Column Definitions
A1: Column name | B1: Definition
A2: Population | B2: IDFG Progeny database collection ID
A3: Individual | B3: IDFG Progeny database individual ID
A4: LGRScaleGeneticsIDLink | B4: Individual genetics ID in metadata provided to IDFG Eagle Genetics Lab
A5: DateSampled | B5: Date sampled at Lower Granite Dam
A6: PhenotypicSex | B6: Sex as identified at the Dam
A7: Length | B7: Fork Length
A8: Clip | B8: Adipose fin status - AD is for Ad-clipped, AI is for ad-intact
A9: Wire | B9: 1 if CWT present, NA if absent
A10: GenComments | B10: Lists all genetic duplicates and samples that failed to genotype
A11: GenSex | B11: Genetic sex
A12: GenPa | B12: IDFG Progeny database ID of the PBT assigned sire
... A17: RepUnitProb | B17: Probability of assignment to the given GSI reporting unit

Sheet pvt tbl
A2: PopName | B2: (Multiple Items)
B4: Clip
B5: AD | C5: AI | D5: Grand Total
A6: Sum of count | B6: 1401 | C6: 2715 | D6: 4116

Sheet Individual Data
U1: NG | V1: =COUNTIF(V6:V5544,"NG") -> 82 | X1: sum | Z1: sum | AA1: night passage rate | AB1: sum @ LGR | AE1: fallback/reassension | AJ1: fallback only
D2: changed to 18% trap rate on: | S2: Run year | U2: total | V2: =SUM(X6:X5544) -> 5539 | X2: =SUM(X6:X5544) -> 5539 | Z2: =SUM(Z6:Z5544) -> 24263.968 | AB2: =SUM(AB6:AB5544) -> 50160.812 | AF2: jack | AG2: adlt | AK2: jack | AL2: adlt
D3: 45169 | S3: 2023 | U3: % NG | V3: =V1/V2 -> 0.014804116 | Y3: 70% period | Z3: 0.7 | AB3: ='LGD window'!R36 -> 0.56726619 | AE3: abv | AF3: 0.047 | AG3: 0.025 | AJ3: abv | AK3: 0 | AL3: 0
Y4: 18% period | Z4: 0.18 | AA4: 0 | AB4: ='LGD window'!R37 -> 0.47654049 | AE4: blw | AF4: 0.292 | AG4: 0.249 | AJ4: blw | AK4: 0.471 | AL4: 0.324
A5: Population | B5: Individual | C5: LGRScaleGeneticsIDLink | D5: DateSampled | E5: sample rate | F5: PhenotypicSex | G5: FL mm | H5: FL cm | I5: Clip | J5: Wire | K5: PIT tag | L5: GenComments | M5: GenSex | N5: best sex | O5: GenPa | P5: GenMa | Q5: PopName | R5: agePBT | S5: Brd Yr | T5: GSIRepUnit | U5: RepUnitProb | V5: Final group | W5: Tag rate | X5: count | Y5: pooled FL | Z5: trap rate expansion | AA5: Night passage expansion | AB5: PBT geno rate expansion | AC5: rel abv/blw LGR
A6: OtsLGRF23S | B6: OtsLGRF23S_0001 | C6: C-00001 | D6: 45156 | E6: =IF(D6<=$D$3,70,18) -> 70 | F6: F | G6: 790 | H6: =G6/10 -> 79 | I6: AI | J6: NA | K6: 3DD.003D7E4EA0 | L6: NA | M6: F | N6: =IF(M6="U",F6,M6) -> F | O6: NA | P6: NA | Q6: Unassigned | R6: NA | S6: =IFERROR($S$3-R6,"U") -> U | T6: FALL | U6: 1 | V6: Unassigned | W6: =VLOOKUP(Q6,'PBT Tag Rates'!$B$5:$E$44,4,FALSE) -> #N/A | X6: 1 | Y6: =IFERROR(LOOKUP(H6,{30,43,48,53,58,63,68,73,78,83,88,93,97},{42,47,52,57,62,67,72,77,82,87,92,99,100}),999) -> 82 | Z6: =IF(D6<$D$3,X6/$Z$3,X6/$Z$4) -> 1.4285714 | AA6: =Z6*(1+$AA$4) -> 1.4285714 | AB6: =IF(D6<$D$3,AA6/$AB$3,AA6/$AB$4) -> 2.5183441 | AC6: Abv | AF6: Questions/Issues
A7: OtsLGRF23S | B7: OtsLGRF23S_2837 | C7: C-02837 | D7: 45169 | E7: =IF(D7<=$D$6,70,18) -> 18 | F7: M | G7: 650 | H7: =G7/10 -> 65 | I7: AI | J7: NA | K7: NA | L7: NA | M7: M | N7: =IF(M7="U",F7,M7) -> M | O7: OtsLYON20S_1_0318 | P7: OtsLYON20S_1_0082 | Q7: OtsLYON20S_1 | R7: 3 | S7: =IFERROR($S$3-R7,"U") -> 2020 | T7: FALL | U7: 1 | V7: PLA1 | W7: =VLOOKUP(Q7,'PBT Tag Rates'!$B$5:$E$44,4,FALSE) -> 0.98961046 | X7: 1 | Y7: =IFERROR(LOOKUP(H7,{30,43,48,53,58,63,68,73,78,83,88,93,97},{42,47,52,57,62,67,72,77,82,87,92,99,100}),999) -> 67 | Z7: =IF(D7<$D$3,X7/$Z$3,X7/$Z$4) -> 5.5555556 | AA7: =Z7*(1+$AA$4) -> 5.5555556 | AB7: =IF(D7<$D$3,AA7/$AB$3,AA7/$AB$4) -> 11.658098 | AC7: Abv | AF7: reasc rate of LFH jacks >1, results in negative numbers.
A8: OtsLGRF23S | B8: OtsLGRF23S_4197 | C8: C-04197 | D8: 45176 | E8: =IF(D8<=$D$6,70,18) -> 18 | F8: M | G8: 750 | H8: =G8/10 -> 75 | I8: AI | J8: NA | K8: 3DD.003D7E48A1 | L8: NA | M8: M | N8: =IF(M8="U",F8,M8) -> M | O8: OtsNPFH19S_1_1335 | P8: OtsNPFH19S_1_1084 | Q8: OtsNPFH19S_1 | R8: 4 | S8: =IFERROR($S$3-R8,"U") -> 2019 | T8: FALL | U8: 1 | V8: NPTH | W8: =VLOOKUP(Q8,'PBT Tag Rates'!$B$5:$E$44,4,FALSE) -> 0.99705232 | X8: 1 | Y8: =IFERROR(LOOKUP(H8,{30,43,48,53,58,63,68,73,78,83,88,93,97},{42,47,52,57,62,67,72,77,82,87,92,99,100}),999) -> 77 | Z8: =IF(D8<$D$3,X8/$Z$3,X8/$Z$4) -> 5.5555556 | AA8: =Z8*(1+$AA$4) -> 5.5555556 | AB8: =IF(D8<$D$3,AA8/$AB$3,AA8/$AB$4) -> 11.658098 | AC8: Abv | AF8: changing to 1 (100% reasc) results in zero LFH jacks. Not possible since we sampled some
A9: OtsLGRF23S | B9: OtsLGRF23S_4523 | C9: C-04523 | D9: 45176 | E9: =IF(D9<=$D$6,70,18) -> 18 | F9: F | G9: 800 | H9: =G9/10 -> 80 | I9: AI | J9: NA | K9: 3DD.003D7E5396 | L9: NA | M9: F | N9: =IF(M9="U",F9,M9) -> F | O9: NA | P9: NA | Q9: Unassigned | R9: NA | S9: =IFERROR($S$3-R9,"U") -> U | T9: FALL | U9: 1 | V9: Unassigned | W9: =VLOOKUP(Q9,'PBT Tag Rates'!$B$5:$E$44,4,FALSE) -> #N/A | X9: 1 | Y9: =IFERROR(LOOKUP(H9,{30,43,48,53,58,63,68,73,78,83,88,93,97},{42,47,52,57,62,67,72,77,82,87,92,99,100}),999) -> 82 | Z9: =IF(D9<$D$3,X9/$Z$3,X9/$Z$4) -> 5.5555556 | AA9: =Z9*(1+$AA$4) -> 5.5555556 | AB9: =IF(D9<$D$3,AA9/$AB$3,AA9/$AB$4) -> 11.658098 | AC9: Abv
A10: OtsLGRF23S | B10: OtsLGRF23S_5154 | C10: C-05154 | D10: 45178 | E10: =IF(D10<=$D$6,70,18) -> 18 | F10: F | G10: 840 | H10: =G10/10 -> 84 | I10: AI | J10: NA | K10: 3DD.003D7E50F6 | L10: NA | M10: F | N10: =IF(M10="U",F10,M10) -> F | O10: NA | P10: NA | Q10: Unassigned | R10: NA | S10: =IFERROR($S$3-R10,"U") -> U | T10: FALL | U10: 1 | V10: Unassigned | W10: =VLOOKUP(Q10,'PBT Tag Rates'!$B$5:$E$44,4,FALSE) -> #N/A | X10: 1 | Y10: =IFERROR(LOOKUP(H10,{30,43,48,53,58,63,68,73,78,83,88,93,97},{42,47,52,57,62,67,72,77,82,87,92,99,100}),999) -> 87 | Z10: =IF(D10<$D$3,X10/$Z$3,X10/$Z$4) -> 5.5555556 | AA10: =Z10*(1+$AA$4) -> 5.5555556 | AB10: =IF(D10<$D$3,AA10/$AB$3,AA10/$AB$4) -> 11.658098 | AC10: Abv
A11: OtsLGRF23S | B11: OtsLGRF23S_7046 | C11: C-07046 | D11: 45184 | E11: =IF(D11<=$D$6,70,18) -> 18 | F11: F | G11: 800 | H11: =G11/10 -> 80 | I11: AI | J11: NA | K11: 3DD.003D7E5464 | L11: NA | M11: F | N11: =IF(M11="U",F11,M11) -> F | O11: OtsLYON19S_1_1811 | P11: OtsLYON19S_1_1524 | Q11: OtsLYON19S_1 | R11: 4 | S11: =IFERROR($S$3-R11,"U") -> 2019 | T11: FALL | U11: 1 | V11: IPCSR | W11: =VLOOKUP(Q11,'PBT Tag Rates'!$B$5:$E$44,4,FALSE) -> 0.95971981 | X11: 1 | Y11: =IFERROR(LOOKUP(H11,{30,43,48,53,58,63,68,73,78,83,88,93,97},{42,47,52,57,62,67,72,77,82,87,92,99,100}),999) -> 82 | Z11: =IF(D11<$D$3,X11/$Z$3,X11/$Z$4) -> 5.5555556 | AA11: =Z11*(1+$AA$4) -> 5.5555556 | AB11: =IF(D11<$D$3,AA11/$AB$3,AA11/$AB$4) -> 11.658098 | AC11: Abv | AF11: removal of duplicates: two ways to get dups
A12: OtsLGRF23S | B12: OtsLGRF23S_7106 | C12: C-07106 | D12: 45184 | E12: =IF(D12<=$D$6,70,18) -> 18 | F12: F | G12: 800 | H12: =G12/10 -> 80 | I12: AI | J12: NA | K12: 3DD.003D7E5459 | L12: NA | M12: F | N12: =IF(M12="U",F12,M12) -> F | O12: OtsLYON19S_1_0545 | P12: OtsLYON19S_1_0429 | Q12: OtsLYON19S_1 | R12: 4 | S12: =IFERROR($S$3-R12,"U") -> 2019 | T12: FALL | U12: 1 | V12: LFSO | W12: =VLOOKUP(Q12,'PBT Tag Rates'!$B$5:$E$44,4,FALSE) -> 0.95971981 | X12: 1 | Y12: =IFERROR(LOOKUP(H12,{30,43,48,53,58,63,68,73,78,83,88,93,97},{42,47,52,57,62,67,72,77,82,87,92,99,100}),999) -> 82 | Z12: =IF(D12<$D$3,X12/$Z$3,X12/$Z$4) -> 5.5555556 | AA12: =Z12*(1+$AA$4) -> 5.5555556 | AB12: =IF(D12<$D$3,AA12/$AB$3,AA12/$AB$4) -> 11.658098 | AC12: Blw | AF12: 1. fish trapped/sampled >1 | AL12: don't remove, adjusted for reasc rate later, otherwise gets removed twice
A13: OtsLGRF23S | B13: OtsLGRF23S_7127 | C13: C-07127 | D13: 45184 | E13: =IF(D13<=$D$6,70,18) -> 18 | F13: F | G13: 820 | H13: =G13/10 -> 82 | I13: AI | J13: NA | K13: 3DD.003D7E542B | L13: NA | M13: F | N13: =IF(M13="U",F13,M13) -> F | O13: OtsNPFH18S_1_5339 | P13: OtsNPFH18S_1_5047 | Q13: OtsNPFH18S_1 | R13: 5 | S13: =IFERROR($S$3-R13,"U") -> 2018 | T13: FALL | U13: 1 | V13: NPTH | W13: =VLOOKUP(Q13,'PBT Tag Rates'!$B$5:$E$44,4,FALSE) -> 0.96828397 | X13: 1 | Y13: =IFERROR(LOOKUP(H13,{30,43,48,53,58,63,68,73,78,83,88,93,97},{42,47,52,57,62,67,72,77,82,87,92,99,100}),999) -> 82 | Z13: =IF(D13<$D$3,X13/$Z$3,X13/$Z$4) -> 5.5555556 | AA13: =Z13*(1+$AA$4) -> 5.5555556 | AB13: =IF(D13<$D$3,AA13/$AB$3,AA13/$AB$4) -> 11.658098 | AC13: Abv | AF13: 2. fish sampled at LGR and hatchery (missing PIT) | AL13: remove duplicate samples, use LGR sample
A14: OtsLGRF23S | B14: OtsLGRF23S_7139 | C14: C-07139 | D14: 45184 | E14: =IF(D14<=$D$6,70,18) -> 18 | F14: F | G14: 850 | H14: =G14/10 -> 85 | I14: AI | J14: NA | K14: 3DD.003D7E5468 | L14: NA | M14: F | N14: =IF(M14="U",F14,M14) -> F | O14: NA | P14: NA | Q14: Unassigned | R14: NA | S14: =IFERROR($S$3-R14,"U") -> U | T14: FALL | U14: 1 | V14: Unassigned | W14: =VLOOKUP(Q14,'PBT Tag Rates'!$B$5:$E$44,4,FALSE) -> #N/A | X14: 1 | Y14: =IFERROR(LOOKUP(H14,{30,43,48,53,58,63,68,73,78,83,88,93,97},{42,47,52,57,62,67,72,77,82,87,92,99,100}),999) -> 87 | Z14: =IF(D14<$D$3,X14/$Z$3,X14/$Z$4) -> 5.5555556 | AA14: =Z14*(1+$AA$4) -> 5.5555556 | AB14: =IF(D14<$D$3,AA14/$AB$3,AA14/$AB$4) -> 11.658098 | AC14: Abv
A15: OtsLGRF23S | B15: OtsLGRF23S_7155 | C15: C-07155 | D15: 45184 | E15: =IF(D15<=$D$6,70,18) -> 18 | F15: F | G15: 800 | H15: =G15/10 -> 80 | I15: AI | J15: NA | K15: 3DD.003D7E5460 | L15: NA | M15: F | N15: =IF(M15="U",F15,M15) -> F | O15: OtsLYON19S_1_1725 | P15: OtsLYON19S_1_1952 | Q15: OtsLYON19S_1 | R15: 4 | S15: =IFERROR($S$3-R15,"U") -> 2019 | T15: FALL | U15: 1 | V15: IPCSR | W15: =VLOOKUP(Q15,'PBT Tag Rates'!$B$5:$E$44,4,FALSE) -> 0.95971981 | X15: 1 | Y15: =IFERROR(LOOKUP(H15,{30,43,48,53,58,63,68,73,78,83,88,93,97},{42,47,52,57,62,67,72,77,82,87,92,99,100}),999) -> 82 | Z15: =IF(D15<$D$3,X15/$Z$3,X15/$Z$4) -> 5.5555556 | AA15: =Z15*(1+$AA$4) -> 5.5555556 | AB15: =IF(D15<$D$3,AA15/$AB$3,AA15/$AB$4) -> 11.658098 | AC15: Abv | AF15: Night passage
A16: OtsLGRF23S | B16: OtsLGRF23S_7163 | C16: C-07163 | D16: 45184 | E16: =IF(D16<=$D$6,70,18) -> 18 | F16: M | G16: 850 | H16: =G16/10 -> 85 | I16: AD | J16: 1 | K16: 3DD.003D7E5431 | L16: NA | M16: M | N16: =IF(M16="U",F16,M16) -> M | O16: OtsLYON19S_1_1334 | P16: OtsLYON19S_1_1256 | Q16: OtsLYON19S_1 | R16: 4 | S16: =IFERROR($S$3-R16,"U") -> 2019 | T16: FALL | U16: 1 | V16: CJA2 | W16: =VLOOKUP(Q16,'PBT Tag Rates'!$B$5:$E$44,4,FALSE) -> 0.95971981 | X16: 1 | Y16: =IFERROR(LOOKUP(H16,{30,43,48,53,58,63,68,73,78,83,88,93,97},{42,47,52,57,62,67,72,77,82,87,92,99,100}),999) -> 87 | Z16: =IF(D16<$D$3,X16/$Z$3,X16/$Z$4) -> 5.5555556 | AA16: =Z16*(1+$AA$4) -> 5.5555556 | AB16: =IF(D16<$D$3,AA16/$AB$3,AA16/$AB$4) -> 11.658098 | AC16: Abv | AF16: discontinue night passage ajustment, window bias. Use set trap rate as it is likely more accurate than using the window in the rate calculation
A17: OtsLGRF23S | B17: OtsLGRF23S_7185 | C17: C-07185 | D17: 45184 | E17: =IF(D17<=$D$6,70,18) -> 18 | F17: M | G17: 840 | H17: =G17/10 -> 84 | I17: AI | J17: NA | K17: 3DD.003D7E5451 | L17: NA | M17: M | N17: =IF(M17="U",F17,M17) -> M | O17: NA | P17: NA | Q17: Unassigned | R17: NA | S17: =IFERROR($S$3-R17,"U") -> U | T17: FALL | U17: 1 | V17: Unassigned | W17: =VLOOKUP(Q17,'PBT Tag Rates'!$B$5:$E$44,4,FALSE) -> #N/A | X17: 1 | Y17: =IFERROR(LOOKUP(H17,{30,43,48,53,58,63,68,73,78,83,88,93,97},{42,47,52,57,62,67,72,77,82,87,92,99,100}),999) -> 87 | Z17: =IF(D17<$D$3,X17/$Z$3,X17/$Z$4) -> 5.5555556 | AA17: =Z17*(1+$AA$4) -> 5.5555556 | AB17: =IF(D17<$D$3,AA17/$AB$3,AA17/$AB$4) -> 11.658098 | AC17: Abv
A18: OtsLGRF23S | B18: OtsLGRF23S_7196 | C18: C-07196 | D18: 45184 | E18: =IF(D18<=$D$6,70,18) -> 18 | F18: F | G18: 810 | H18: =G18/10 -> 81 | I18: AD | J18: 1 | K18: 3DD.003D7E545D | L18: NA | M18: F | N18: =IF(M18="U",F18,M18) -> F | O18: OtsLYON19S_1_0548 | P18: OtsLYON19S_1_0410 | Q18: OtsLYON19S_1 | R18: 4 | S18: =IFERROR($S$3-R18,"U") -> 2019 | T18: FALL | U18: 1 | V18: LFSO | W18: =VLOOKUP(Q18,'PBT Tag Rates'!$B$5:$E$44,4,FALSE) -> 0.95971981 | X18: 1 | Y18: =IFERROR(LOOKUP(H18,{30,43,48,53,58,63,68,73,78,83,88,93,97},{42,47,52,57,62,67,72,77,82,87,92,99,100}),999) -> 82 | Z18: =IF(D18<$D$3,X18/$Z$3,X18/$Z$4) -> 5.5555556 | AA18: =Z18*(1+$AA$4) -> 5.5555556 | AB18: =IF(D18<$D$3,AA18/$AB$3,AA18/$AB$4) -> 11.658098 | AC18: Blw | AF18: reascension rate
A19: OtsLGRF23S | B19: OtsLGRF23S_7208 | C19: C-07208 | D19: 45184 | E19: =IF(D19<=$D$6,70,18) -> 18 | F19: M | G19: 880 | H19: =G19/10 -> 88 | I19: AI | J19: NA | K19: 3DD.003D7E545F | L19: NA | M19: M | N19: =IF(M19="U",F19,M19) -> M | O19: NA | P19: NA | Q19: Unassigned | R19: NA | S19: =IFERROR($S$3-R19,"U") -> U | T19: FALL | U19: 1 | V19: Unassigned | W19: =VLOOKUP(Q19,'PBT Tag Rates'!$B$5:$E$44,4,FALSE) -> #N/A | X19: 1 | Y19: =IFERROR(LOOKUP(H19,{30,43,48,53,58,63,68,73,78,83,88,93,97},{42,47,52,57,62,67,72,77,82,87,92,99,100}),999) -> 92 | Z19: =IF(D19<$D$3,X19/$Z$3,X19/$Z$4) -> 5.5555556 | AA19: =Z19*(1+$AA$4) -> 5.5555556 | AB19: =IF(D19<$D$3,AA19/$AB$3,AA19/$AB$4) -> 11.658098 | AC19: Abv | AF19: need to apply a multinomial:
A20: OtsLGRF23S | B20: OtsLGRF23S_7209 | C20: C-07209 | D20: 45184 | E20: =IF(D20<=$D$6,70,18) -> 18 | F20: F | G20: 800 | H20: =G20/10 -> 80 | I20: AI | J20: NA | K20: 3DD.003D7E544B | L20: NA | M20: F | N20: =IF(M20="U",F20,M20) -> F | O20: OtsLYON19S_1_0147 | P20: OtsLYON19S_1_0212 | Q20: OtsLYON19S_1 | R20: 4 | S20: =IFERROR($S$3-R20,"U") -> 2019 | T20: FALL | U20: 1 | V20: BCA2 | W20: =VLOOKUP(Q20,'PBT Tag Rates'!$B$5:$E$44,4,FALSE) -> 0.95971981 | X20: 1 | Y20: =IFERROR(LOOKUP(H20,{30,43,48,53,58,63,68,73,78,83,88,93,97},{42,47,52,57,62,67,72,77,82,87,92,99,100}),999) -> 82 | Z20: =IF(D20<$D$3,X20/$Z$3,X20/$Z$4) -> 5.5555556 | AA20: =Z20*(1+$AA$4) -> 5.5555556 | AB20: =IF(D20<$D$3,AA20/$AB$3,AA20/$AB$4) -> 11.658098 | AC20: Abv
A21: OtsLGRF23S | B21: OtsLGRF23S_7217 | C21: C-07217 | D21: 45184 | E21: =IF(D21<=$D$6,70,18) -> 18 | F21: F | G21: 830 | H21: =G21/10 -> 83 | I21: AI | J21: NA | K21: 3DD.003D7E5429 | L21: NA | M21: F | N21: =IF(M21="U",F21,M21) -> F | O21: OtsLYON19S_1_1811 | P21: OtsLYON19S_1_1524 | Q21: OtsLYON19S_1 | R21: 4 | S21: =IFERROR($S$3-R21,"U") -> 2019 | T21: FALL | U21: 1 | V21: IPCSR | W21: =VLOOKUP(Q21,'PBT Tag Rates'!$B$5:$E$44,4,FALSE) -> 0.95971981 | X21: 1 | Y21: =IFERROR(LOOKUP(H21,{30,43,48,53,58,63,68,73,78,83,88,93,97},{42,47,52,57,62,67,72,77,82,87,92,99,100}),999) -> 87 | Z21: =IF(D21<$D$3,X21/$Z$3,X21/$Z$4) -> 5.5555556 | AA21: =Z21*(1+$AA$4) -> 5.5555556 | AB21: =IF(D21<$D$3,AA21/$AB$3,AA21/$AB$4) -> 11.658098 | AC21: Abv
A22: OtsLGRF23S | B22: OtsLGRF23S_7260 | C22: C-07260 | D22: 45185 | E22: =IF(D22<=$D$6,70,18) -> 18 | F22: F | G22: 810 | H22: =G22/10 -> 81 | I22: AI | J22: NA | K22: 3DD.003D7E541C | L22: NA | M22: F | N22: =IF(M22="U",F22,M22) -> F | O22: OtsLYON19S_1_0709 | P22: OtsLYON19S_1_0811 | Q22: OtsLYON19S_1 | R22: 4 | S22: =IFERROR($S$3-R22,"U") -> 2019 | T22: FALL | U22: 1 | V22: CJA1 | W22: =VLOOKUP(Q22,'PBT Tag Rates'!$B$5:$E$44,4,FALSE) -> 0.95971981 | X22: 1 | Y22: =IFERROR(LOOKUP(H22,{30,43,48,53,58,63,68,73,78,83,88,93,97},{42,47,52,57,62,67,72,77,82,87,92,99,100}),999) -> 82 | Z22: =IF(D22<$D$3,X22/$Z$3,X22/$Z$4) -> 5.5555556 | AA22: =Z22*(1+$AA$4) -> 5.5555556 | AB22: =IF(D22<$D$3,AA22/$AB$3,AA22/$AB$4) -> 11.658098 | AC22: Abv
A23: OtsLGRF23S | B23: OtsLGRF23S_7281 | C23: C-07281 | D23: 45185 | E23: =IF(D23<=$D$6,70,18) -> 18 | F23: F | G23: 820 | H23: =G23/10 -> 82 | I23: AI | J23: NA | K23: 3DD.003D7E546D | L23: NA | M23: F | N23: =IF(M23="U",F23,M23) -> F | O23: OtsLYON19S_1_1821 | P23: OtsLYON19S_1_1543 | Q23: OtsLYON19S_1 | R23: 4 | S23: =IFERROR($S$3-R23,"U") -> 2019 | T23: FALL | U23: 1 | V23: IPCSR | W23: =VLOOKUP(Q23,'PBT Tag Rates'!$B$5:$E$44,4,FALSE) -> 0.95971981 | X23: 1 | Y23: =IFERROR(LOOKUP(H23,{30,43,48,53,58,63,68,73,78,83,88,93,97},{42,47,52,57,62,67,72,77,82,87,92,99,100}),999) -> 82 | Z23: =IF(D23<$D$3,X23/$Z$3,X23/$Z$4) -> 5.5555556 | AA23: =Z23*(1+$AA$4) -> 5.5555556 | AB23: =IF(D23<$D$3,AA23/$AB$3,AA23/$AB$4) -> 11.658098 | AC23: Abv
A24: OtsLGRF23S | B24: OtsLGRF23S_7286 | C24: C-07286 | D24: 45185 | E24: =IF(D24<=$D$6,70,18) -> 18 | F24: F | G24: 820 | H24: =G24/10 -> 82 | I24: AI | J24: NA | K24: 3DD.003D7E5440 | L24: NA | M24: F | N24: =IF(M24="U",F24,M24) -> F | O24: OtsNPFH19S_1_4302 | P24: OtsNPFH19S_1_4005 | Q24: OtsNPFH19S_1 | R24: 4 | S24: =IFERROR($S$3-R24,"U") -> 2019 | T24: FALL | U24: 1 | V24: NLVA | W24: =VLOOKUP(Q24,'PBT Tag Rates'!$B$5:$E$44,4,FALSE) -> 0.99705232 | X24: 1 | Y24: =IFERROR(LOOKUP(H24,{30,43,48,53,58,63,68,73,78,83,88,93,97},{42,47,52,57,62,67,72,77,82,87,92,99,100}),999) -> 82 | Z24: =IF(D24<$D$3,X24/$Z$3,X24/$Z$4) -> 5.5555556 | AA24: =Z24*(1+$AA$4) -> 5.5555556 | AB24: =IF(D24<$D$3,AA24/$AB$3,AA24/$AB$4) -> 11.658098 | AC24: Abv
A25: OtsLGRF23S | B25: OtsLGRF23S_7287 | C25: C-07287 | D25: 45185 | E25: =IF(D25<=$D$6,70,18) -> 18 | F25: F | G25: 820 | H25: =G25/10 -> 82 | I25: AI | J25: NA | K25: 3DD.003D7E5463 | L25: NA | M25: F | N25: =IF(M25="U",F25,M25) -> F | O25: OtsLYON19S_1_1859 | P25: OtsLYON19S_1_1638 | Q25: OtsLYON19S_1 | R25: 4 | S25: =IFERROR($S$3-R25,"U") -> 2019 | T25: FALL | U25: 1 | V25: IPCSR | W25: =VLOOKUP(Q25,'PBT Tag Rates'!$B$5:$E$44,4,FALSE) -> 0.95971981 | X25: 1 | Y25: =IFERROR(LOOKUP(H25,{30,43,48,53,58,63,68,73,78,83,88,93,97},{42,47,52,57,62,67,72,77,82,87,92,99,100}),999) -> 82 | Z25: =IF(D25<$D$3,X25/$Z$3,X25/$Z$4) -> 5.5555556 | AA25: =Z25*(1+$AA$4) -> 5.5555556 | AB25: =IF(D25<$D$3,AA25/$AB$3,AA25/$AB$4) -> 11.658098 | AC25: Abv
A26: OtsLGRF23S | B26: OtsLGRF23S_7298 | C26: C-07298 | D26: 45185 | E26: =IF(D26<=$D$6,70,18) -> 18 | F26: F | G26: 840 | H26: =G26/10 -> 84 | I26: AD | J26: 1 | K26: 3DD.003D7E5477 | L26: NA | M26: F | N26: =IF(M26="U",F26,M26) -> F | O26: OtsLYON19S_1_0538 | P26: OtsLYON19S_1_0393 | Q26: OtsLYON19S_1 | R26: 4 | S26: =IFERROR($S$3-R26,"U") -> 2019 | T26: FALL | U26: 1 | V26: LFSO | W26: =VLOOKUP(Q26,'PBT Tag Rates'!$B$5:$E$44,4,FALSE) -> 0.95971981 | X26: 1 | Y26: =IFERROR(LOOKUP(H26,{30,43,48,53,58,63,68,73,78,83,88,93,97},{42,47,52,57,62,67,72,77,82,87,92,99,100}),999) -> 87 | Z26: =IF(D26<$D$3,X26/$Z$3,X26/$Z$4) -> 5.5555556 | AA26: =Z26*(1+$AA$4) -> 5.5555556 | AB26: =IF(D26<$D$3,AA26/$AB$3,AA26/$AB$4) -> 11.658098 | AC26: Blw
A27: OtsLGRF23S | B27: OtsLGRF23S_7320 | C27: C-07320 | D27: 45185 | E27: =IF(D27<=$D$6,70,18) -> 18 | F27: M | G27: 830 | H27: =G27/10 -> 83 | I27: AI | J27: NA | K27: 3DD.003D7E542A | L27: NA | M27: M | N27: =IF(M27="U",F27,M27) -> M | O27: NA | P27: NA | Q27: Unassigned | R27: NA | S27: =IFERROR($S$3-R27,"U") -> U | T27: FALL | U27: 1 | V27: Unassigned | W27: =VLOOKUP(Q27,'PBT Tag Rates'!$B$5:$E$44,4,FALSE) -> #N/A | X27: 1 | Y27: =IFERROR(LOOKUP(H27,{30,43,48,53,58,63,68,73,78,83,88,93,97},{42,47,52,57,62,67,72,77,82,87,92,99,100}),999) -> 87 | Z27: =IF(D27<$D$3,X27/$Z$3,X27/$Z$4) -> 5.5555556 | AA27: =Z27*(1+$AA$4) -> 5.5555556 | AB27: =IF(D27<$D$3,AA27/$AB$3,AA27/$AB$4) -> 11.658098 | AC27: Abv
A28: OtsLGRF23S | B28: OtsLGRF23S_7329 | C28: C-07329 | D28: 45185 | E28: =IF(D28<=$D$6,70,18) -> 18 | F28: F | G28: 810 | H28: =G28/10 -> 81 | I28: AD | J28: 1 | K28: 3DD.003D7E5444 | L28: NA | M28: F | N28: =IF(M28="U",F28,M28) -> F | O28: OtsLYON19S_1_0709 | P28: OtsLYON19S_1_0809 | Q28: OtsLYON19S_1 | R28: 4 | S28: =IFERROR($S$3-R28,"U") -> 2019 | T28: FALL | U28: 1 | V28: CJA1 | W28: =VLOOKUP(Q28,'PBT Tag Rates'!$B$5:$E$44,4,FALSE) -> 0.95971981 | X28: 1 | Y28: =IFERROR(LOOKUP(H28,{30,43,48,53,58,63,68,73,78,83,88,93,97},{42,47,52,57,62,67,72,77,82,87,92,99,100}),999) -> 82 | Z28: =IF(D28<$D$3,X28/$Z$3,X28/$Z$4) -> 5.5555556 | AA28: =Z28*(1+$AA$4) -> 5.5555556 | AB28: =IF(D28<$D$3,AA28/$AB$3,AA28/$AB$4) -> 11.658098 | AC28: Abv
A29: OtsLGRF23S | B29: OtsLGRF23S_7335 | C29: C-07335 | D29: 45185 | E29: =IF(D29<=$D$6,70,18) -> 18 | F29: F | G29: 810 | H29: =G29/10 -> 81 | I29: AI | J29: NA | K29: 3DD.003D7E5426 | L29: NA | M29: F | N29: =IF(M29="U",F29,M29) -> F | O29: OtsLYON19S_1_0147 | P29: OtsLYON19S_1_0212 | Q29: OtsLYON19S_1 | R29: 4 | S29: =IFERROR($S$3-R29,"U") -> 2019 | T29: FALL | U29: 1 | V29: BCA2 | W29: =VLOOKUP(Q29,'PBT Tag Rates'!$B$5:$E$44,4,FALSE) -> 0.95971981 | X29: 1 | Y29: =IFERROR(LOOKUP(H29,{30,43,48,53,58,63,68,73,78,83,88,93,97},{42,47,52,57,62,67,72,77,82,87,92,99,100}),999) -> 82 | Z29: =IF(D29<$D$3,X29/$Z$3,X29/$Z$4) -> 5.5555556 | AA29: =Z29*(1+$AA$4) -> 5.5555556 | AB29: =IF(D29<$D$3,AA29/$AB$3,AA29/$AB$4) -> 11.658098 | AC29: Abv
A30: OtsLGRF23S | B30: OtsLGRF23S_7364 | C30: C-07364 | D30: 45186 | E30: =IF(D30<=$D$6,70,18) -> 18 | F30: M | G30: 870 | H30: =G30/10 -> 87 | I30: AI | J30: NA | K30: 3DD.003D7E5478 | L30: NA | M30: M | N30: =IF(M30="U",F30,M30) -> M | O30: OtsLYON19S_1_0579 | P30: OtsLYON19S_1_0637 | Q30: OtsLYON19S_1 | R30: 4 | S30: =IFERROR($S$3-R30,"U") -> 2019 | T30: FALL | U30: 1 | V30: CJA1 | W30: =VLOOKUP(Q30,'PBT Tag Rates'!$B$5:$E$44,4,FALSE) -> 0.95971981 | X30: 1 | Y30: =IFERROR(LOOKUP(H30,{30,43,48,53,58,63,68,73,78,83,88,93,97},{42,47,52,57,62,67,72,77,82,87,92,99,100}),999) -> 87 | Z30: =IF(D30<$D$3,X30/$Z$3,X30/$Z$4) -> 5.5555556 | AA30: =Z30*(1+$AA$4) -> 5.5555556 | AB30: =IF(D30<$D$3,AA30/$AB$3,AA30/$AB$4) -> 11.658098 | AC30: Abv
A31: OtsLGRF23S | B31: OtsLGRF23S_7377 | C31: C-07377 | D31: 45186 | E31: =IF(D31<=$D$6,70,18) -> 18 | F31: F | G31: 810 | H31: =G31/10 -> 81 | I31: AI | J31: NA | K31: 3DD.003D7E5423 | L31: NA | M31: F | N31: =IF(M31="U",F31,M31) -> F | O31: NA | P31: NA | Q31: Unassigned | R31: NA | S31: =IFERROR($S$3-R31,"U") -> U | T31: FALL | U31: 1 | V31: Unassigned | W31: =VLOOKUP(Q31,'PBT Tag Rates'!$B$5:$E$44,4,FALSE) -> #N/A | X31: 1 | Y31: =IFERROR(LOOKUP(H31,{30,43,48,53,58,63,68,73,78,83,88,93,97},{42,47,52,57,62,67,72,77,82,87,92,99,100}),999) -> 82 | Z31: =IF(D31<$D$3,X31/$Z$3,X31/$Z$4) -> 5.5555556 | AA31: =Z31*(1+$AA$4) -> 5.5555556 | AB31: =IF(D31<$D$3,AA31/$AB$3,AA31/$AB$4) -> 11.658098 | AC31: Abv
A32: OtsLGRF23S | B32: OtsLGRF23S_7380 | C32: C-07380 | D32: 45186 | E32: =IF(D32<=$D$6,70,18) -> 18 | F32: F | G32: 840 | H32: =G32/10 -> 84 | I32: AI | J32: NA | K32: 3DD.003D7E5415 | L32: NA | M32: F | N32: =IF(M32="U",F32,M32) -> F | O32: NA | P32: NA | Q32: Unassigned | R32: NA | S32: =IFERROR($S$3-R32,"U") -> U | T32: FALL | U32: 1 | V32: Unassigned | W32: =VLOOKUP(Q32,'PBT Tag Rates'!$B$5:$E$44,4,FALSE) -> #N/A | X32: 1 | Y32: =IFERROR(LOOKUP(H32,{30,43,48,53,58,63,68,73,78,83,88,93,97},{42,47,52,57,62,67,72,77,82,87,92,99,100}),999) -> 87 | Z32: =IF(D32<$D$3,X32/$Z$3,X32/$Z$4) -> 5.5555556 | AA32: =Z32*(1+$AA$4) -> 5.5555556 | AB32: =IF(D32<$D$3,AA32/$AB$3,AA32/$AB$4) -> 11.658098 | AC32: Abv
A33: OtsLGRF23S | B33: OtsLGRF23S_7451 | C33: C-07451 | D33: 45186 | E33: =IF(D33<=$D$6,70,18) -> 18 | F33: M | G33: 860 | H33: =G33/10 -> 86 | I33: AI | J33: NA | K33: 3DD.003D7E5432 | L33: NA | M33: M | N33: =IF(M33="U",F33,M33) -> M | O33: OtsNPFH19S_1_2315 | P33: OtsNPFH19S_1_2009 | Q33: OtsNPFH19S_1 | R33: 4 | S33: =IFERROR($S$3-R33,"U") -> 2019 | T33: FALL | U33: 1 | V33: NPTH | W33: =VLOOKUP(Q33,'PBT Tag Rates'!$B$5:$E$44,4,FALSE) -> 0.99705232 | X33: 1 | Y33: =IFERROR(LOOKUP(H33,{30,43,48,53,58,63,68,73,78,83,88,93,97},{42,47,52,57,62,67,72,77,82,87,92,99,100}),999) -> 87 | Z33: =IF(D33<$D$3,X33/$Z$3,X33/$Z$4) -> 5.5555556 | AA33: =Z33*(1+$AA$4) -> 5.5555556 | AB33: =IF(D33<$D$3,AA33/$AB$3,AA33/$AB$4) -> 11.658098 | AC33: Abv
A34: OtsLGRF23S | B34: OtsLGRF23S_7470 | C34: C-07470 | D34: 45186 | E34: =IF(D34<=$D$6,70,18) -> 18 | F34: M | G34: 860 | H34: =G34/10 -> 86 | I34: AI | J34: NA | K34: 3DD.003D7E5452 | L34: NA | M34: M | N34: =IF(M34="U",F34,M34) -> M | O34: OtsLYON19S_1_0555 | P34: OtsLYON19S_1_0453 | Q34: OtsLYON19S_1 | R34: 4 | S34: =IFERROR($S$3-R34,"U") -> 2019 | T34: FALL | U34: 1 | V34: LFSO | W34: =VLOOKUP(Q34,'PBT Tag Rates'!$B$5:$E$44,4,FALSE) -> 0.95971981 | X34: 1 | Y34: =IFERROR(LOOKUP(H34,{30,43,48,53,58,63,68,73,78,83,88,93,97},{42,47,52,57,62,67,72,77,82,87,92,99,100}),999) -> 87 | Z34: =IF(D34<$D$3,X34/$Z$3,X34/$Z$4) -> 5.5555556 | AA34: =Z34*(1+$AA$4) -> 5.5555556 | AB34: =IF(D34<$D$3,AA34/$AB$3,AA34/$AB$4) -> 11.658098 | AC34: Blw
A35: OtsLGRF23S | B35: OtsLGRF23S_7484 | C35: C-07484 | D35: 45186 | E35: =IF(D35<=$D$6,70,18) -> 18 | F35: F | G35: 850 | H35: =G35/10 -> 85 | I35: AI | J35: NA | K35: 3DD.003D7E5439 | L35: NA | M35: F | N35: =IF(M35="U",F35,M35) -> F | O35: NA | P35: NA | Q35: Unassigned | R35: NA | S35: =IFERROR($S$3-R35,"U") -> U | T35: FALL | U35: 1 | V35: Unassigned | W35: =VLOOKUP(Q35,'PBT Tag Rates'!$B$5:$E$44,4,FALSE) -> #N/A | X35: 1 | Y35: =IFERROR(LOOKUP(H35,{30,43,48,53,58,63,68,73,78,83,88,93,97},{42,47,52,57,62,67,72,77,82,87,92,99,100}),999) -> 87 | Z35: =IF(D35<$D$3,X35/$Z$3,X35/$Z$4) -> 5.5555556 | AA35: =Z35*(1+$AA$4) -> 5.5555556 | AB35: =IF(D35<$D$3,AA35/$AB$3,AA35/$AB$4) -> 11.658098 | AC35: Abv
A36: OtsLGRF23S | B36: OtsLGRF23S_7485 | C36: C-07485 | D36: 45186 | E36: =IF(D36<=$D$6,70,18) -> 18 | F36: M | G36: 800 | H36: =G36/10 -> 80 | I36: AI | J36: NA | K36: 3DD.003D7E5453 | L36: NA | M36: M | N36: =IF(M36="U",F36,M36) -> M | O36: OtsLYON19S_1_1742 | P36: OtsLYON19S_1_1973 | Q36: OtsLYON19S_1 | R36: 4 | S36: =IFERROR($S$3-R36,"U") -> 2019 | T36: FALL | U36: 1 | V36: IPCSR | W36: =VLOOKUP(Q36,'PBT Tag Rates'!$B$5:$E$44,4,FALSE) -> 0.95971981 | X36: 1 | Y36: =IFERROR(LOOKUP(H36,{30,43,48,53,58,63,68,73,78,83,88,93,97},{42,47,52,57,62,67,72,77,82,87,92,99,100}),999) -> 82 | Z36: =IF(D36<$D$3,X36/$Z$3,X36/$Z$4) -> 5.5555556 | AA36: =Z36*(1+$AA$4) -> 5.5555556 | AB36: =IF(D36<$D$3,AA36/$AB$3,AA36/$AB$4) -> 11.658098 | AC36: Abv
A37: OtsLGRF23S | B37: OtsLGRF23S_7508 | C37: C-07508 | D37: 45186 | E37: =IF(D37<=$D$6,70,18) -> 18 | F37: M | G37: 870 | H37: =G37/10 -> 87 | I37: AD | J37: 1 | K37: 3DD.003D7E5430 | L37: NA | M37: M | N37: =IF(M37="U",F37,M37) -> M | O37: OtsNPFH19S_1_3357 | P37: OtsNPFH19S_1_3075 | Q37: OtsNPFH19S_1 | R37: 4 | S37: =IFERROR($S$3-R37,"U") -> 2019 | T37: FALL | U37: 1 | V37: NLVA | W37: =VLOOKUP(Q37,'PBT Tag Rates'!$B$5:$E$44,4,FALSE) -> 0.99705232 | X37: 1 | Y37: =IFERROR(LOOKUP(H37,{30,43,48,53,58,63,68,73,78,83,88,93,97},{42,47,52,57,62,67,72,77,82,87,92,99,100}),999) -> 87 | Z37: =IF(D37<$D$3,X37/$Z$3,X37/$Z$4) -> 5.5555556 | AA37: =Z37*(1+$AA$4) -> 5.5555556 | AB37: =IF(D37<$D$3,AA37/$AB$3,AA37/$AB$4) -> 11.658098 | AC37: Abv
A38: OtsLGRF23S | B38: OtsLGRF23S_7563 | C38: C-07563 | D38: 45186 | E38: =IF(D38<=$D$6,70,18) -> 18 | F38: F | G38: 840 | H38: =G38/10 -> 84 | I38: AI | J38: NA | K38: 3DD.003D7E543E | L38: NA | M38: F | N38: =IF(M38="U",F38,M38) -> F | O38: OtsLYON18S_1_1918 | P38: OtsLYON18S_1_1522 | Q38: OtsLYON18S_1 | R38: 5 | S38: =IFERROR($S$3-R38,"U") -> 2018 | T38: FALL | U38: 1 | V38: LFH UNK | W38: =VLOOKUP(Q38,'PBT Tag Rates'!$B$5:$E$44,4,FALSE) -> 0.80551598 | X38: 1 | Y38: =IFERROR(LOOKUP(H38,{30,43,48,53,58,63,68,73,78,83,88,93,97},{42,47,52,57,62,67,72,77,82,87,92,99,100}),999) -> 87 | Z38: =IF(D38<$D$3,X38/$Z$3,X38/$Z$4) -> 5.5555556 | AA38: =Z38*(1+$AA$4) -> 5.5555556 | AB38: =IF(D38<$D$3,AA38/$AB$3,AA38/$AB$4) -> 11.658098 | AC38: Blw
A39: OtsLGRF23S | B39: OtsLGRF23S_7571 | C39: C-07571 | D39: 45186 | E39: =IF(D39<=$D$6,70,18) -> 18 | F39: F | G39: 840 | H39: =G39/10 -> 84 | I39: AI | J39: NA | K39: 3DD.003D7E541F | L39: NA | M39: F | N39: =IF(M39="U",F39,M39) -> F | O39: OtsLYON18S_1_0713 | P39: OtsLYON18S_1_0572 | Q39: OtsLYON18S_1 | R39: 5 | S39: =IFERROR($S$3-R39,"U") -> 2018 | T39: FALL | U39: 1 | V39: BCA2 | W39: =VLOOKUP(Q39,'PBT Tag Rates'!$B$5:$E$44,4,FALSE) -> 0.80551598 | X39: 1 | Y39: =IFERROR(LOOKUP(H39,{30,43,48,53,58,63,68,73,78,83,88,93,97},{42,47,52,57,62,67,72,77,82,87,92,99,100}),999) -> 87 | Z39: =IF(D39<$D$3,X39/$Z$3,X39/$Z$4) -> 5.5555556 | AA39: =Z39*(1+$AA$4) -> 5.5555556 | AB39: =IF(D39<$D$3,AA39/$AB$3,AA39/$AB$4) -> 11.658098 | AC39: Abv
A40: OtsLGRF23S | B40: OtsLGRF23S_7572 | C40: C-07572 | D40: 45186 | E40: =IF(D40<=$D$6,70,18) -> 18 | F40: F | G40: 820 | H40: =G40/10 -> 82 | I40: AI | J40: NA | K40: 3DD.003D7E546A | L40: NA | M40: F | N40: =IF(M40="U",F40,M40) -> F | O40: OtsLYON19S_1_0598 | P40: OtsLYON19S_1_0666 | Q40: OtsLYON19S_1 | R40: 4 | S40: =IFERROR($S$3-R40,"U") -> 2019 | T40: FALL | U40: 1 | V40: CJA1 | W40: =VLOOKUP(Q40,'PBT Tag Rates'!$B$5:$E$44,4,FALSE) -> 0.95971981 | X40: 1 | Y40: =IFERROR(LOOKUP(H40,{30,43,48,53,58,63,68,73,78,83,88,93,97},{42,47,52,57,62,67,72,77,82,87,92,99,100}),999) -> 82 | Z40: =IF(D40<$D$3,X40/$Z$3,X40/$Z$4) -> 5.5555556 | AA40: =Z40*(1+$AA$4) -> 5.5555556 | AB40: =IF(D40<$D$3,AA40/$AB$3,AA40/$AB$4) -> 11.658098 | AC40: Abv
...

Sheet age-length prop
G1: sum check | I1: =SUM(D5:P6) -> 25613.294 | P1: =I1+I83 -> 50160.812 | T1: sum check | V1: =SUM(Q8:AC79) -> 25613.294 | AA1: =I1+I83 -> 50160.812 | AH1: sum check | AJ1: =SUM(AE8:AQ79) -> 22065.191 | AZ1: Fallback Reacension rate | BL1: sum check | BN1: =SUM(BI8:BU77) -> 1031.0367 | CB1: sum check | CD1: =SUM(BY8:CK61) -> 418.0756 | CH1: sum check | CJ1: =CD1+CR1 -> 965.23482 | CP1: sum check | CR1: =SUM(CM8:CY61) -> 547.15922
D2: proportion NG (no genotype) fish by FL | T2: all | V2: =SUM(Q8:AC79) -> 25613.294 | AA2: 2332 | AJ2: =AJ1-BN1 -> 21034.154 | AV2: run year | BA2: adlt | BB2: jack | BD2: Final estimates of hatchery assigned fish by release site | BW2: count of AD and AI fish to est % AD, known hat fish
A3: AD | B3: NG | D3: =SUMIFS('Individual Data'!$AB$6:$AB$5544,'Individual Data'!$V$6:$V$5544,'age-length prop'!$B3,'Individual Data'!$I$6:$I$5544,'age-length prop'!$A3,'Individual Data'!$Y$6:$Y$5544,'age-length prop'!D$7,'Individual Data'!$N$6:$N$5544,'age-length prop'!$B$6) -> 0 | E3: =SUMIFS('Individual Data'!$AB$6:$AB$5544,'Individual Data'!$V$6:$V$5544,'age-length prop'!$B3,'Individual Data'!$I$6:$I$5544,'age-length prop'!$A3,'Individual Data'!$Y$6:$Y$5544,'age-length prop'!E$7,'Individual Data'!$N$6:$N$5544,'age-length prop'!$B$6) -> 0 | F3: =SUMIFS('Individual Data'!$AB$6:$AB$5544,'Individual Data'!$V$6:$V$5544,'age-length prop'!$B3,'Individual Data'!$I$6:$I$5544,'age-length prop'!$A3,'Individual Data'!$Y$6:$Y$5544,'age-length prop'!F$7,'Individual Data'!$N$6:$N$5544,'age-length prop'!$B$6) -> 0 | G3: =SUMIFS('Individual Data'!$AB$6:$AB$5544,'Individual Data'!$V$6:$V$5544,'age-length prop'!$B3,'Individual Data'!$I$6:$I$5544,'age-length prop'!$A3,'Individual Data'!$Y$6:$Y$5544,'age-length prop'!G$7,'Individual Data'!$N$6:$N$5544,'age-length prop'!$B$6) -> 0 | H3: =SUMIFS('Individual Data'!$AB$6:$AB$5544,'Individual Data'!$V$6:$V$5544,'age-length prop'!$B3,'Individual Data'!$I$6:$I$5544,'age-length prop'!$A3,'Individual Data'!$Y$6:$Y$5544,'age-length prop'!H$7,'Individual Data'!$N$6:$N$5544,'age-length prop'!$B$6) -> 0 | I3: =SUMIFS('Individual Data'!$AB$6:$AB$5544,'Individual Data'!$V$6:$V$5544,'age-length prop'!$B3,'Individual Data'!$I$6:$I$5544,'age-length prop'!$A3,'Individual Data'!$Y$6:$Y$5544,'age-length prop'!I$7,'Individual Data'!$N$6:$N$5544,'age-length prop'!$B$6) -> 0 | J3: =SUMIFS('Individual Data'!$AB$6:$AB$5544,'Individual Data'!$V$6:$V$5544,'age-length prop'!$B3,'Individual Data'!$I$6:$I$5544,'age-length prop'!$A3,'Individual Data'!$Y$6:$Y$5544,'age-length prop'!J$7,'Individual Data'!$N$6:$N$5544,'age-length prop'!$B$6) -> 11.658098 | K3: =SUMIFS('Individual Data'!$AB$6:$AB$5544,'Individual Data'!$V$6:$V$5544,'age-length prop'!$B3,'Individual Data'!$I$6:$I$5544,'age-length prop'!$A3,'Individual Data'!$Y$6:$Y$5544,'age-length prop'!K$7,'Individual Data'!$N$6:$N$5544,'age-length prop'!$B$6) -> 14.176442 | ... P3: =SUMIFS('Individual Data'!$AB$6:$AB$5544,'Individual Data'!$V$6:$V$5544,'age-length prop'!$B3,'Individual Data'!$I$6:$I$5544,'age-length prop'!$A3,'Individual Data'!$Y$6:$Y$5544,'age-length prop'!P$7,'Individual Data'!$N$6:$N$5544,'age-length prop'!$B$6) -> 0 | T3: assign only | V3: =SUM(Q8:AC77) -> 21034.154 | AE3: Expand hatchery PBT groups by tag rate. Multiply totals by tag rate for each group | AS3: sum check | AV3: 2023 | AZ3: abv | BA3: ='Individual Data'!AG3 -> 0.025 | BB3: ='Individual Data'!AF3 -> 0.047 | BI3: subtract NG proportioned cells (col Q to AC) from tag rate expanded (col AE to AQ). This is the number of fish to subtract from unassigned AD and AI groups | BY3: number of fish to subtract from unassigned AD group by FL | CM3: number of fish to subtract from unassinged AI group by FL
A4: AI | B4: NG | D4: =SUMIFS('Individual Data'!$AB$6:$AB$5544,'Individual Data'!$V$6:$V$5544,'age-length prop'!$B4,'Individual Data'!$I$6:$I$5544,'age-length prop'!$A4,'Individual Data'!$Y$6:$Y$5544,'age-length prop'!D$7,'Individual Data'!$N$6:$N$5544,'age-length prop'!$B$6) -> 0 | E4: =SUMIFS('Individual Data'!$AB$6:$AB$5544,'Individual Data'!$V$6:$V$5544,'age-length prop'!$B4,'Individual Data'!$I$6:$I$5544,'age-length prop'!$A4,'Individual Data'!$Y$6:$Y$5544,'age-length prop'!E$7,'Individual Data'!$N$6:$N$5544,'age-length prop'!$B$6) -> 0 | F4: =SUMIFS('Individual Data'!$AB$6:$AB$5544,'Individual Data'!$V$6:$V$5544,'age-length prop'!$B4,'Individual Data'!$I$6:$I$5544,'age-length prop'!$A4,'Individual Data'!$Y$6:$Y$5544,'age-length prop'!F$7,'Individual Data'!$N$6:$N$5544,'age-length prop'!$B$6) -> 0 | G4: =SUMIFS('Individual Data'!$AB$6:$AB$5544,'Individual Data'!$V$6:$V$5544,'age-length prop'!$B4,'Individual Data'!$I$6:$I$5544,'age-length prop'!$A4,'Individual Data'!$Y$6:$Y$5544,'age-length prop'!G$7,'Individual Data'!$N$6:$N$5544,'age-length prop'!$B$6) -> 0 | H4: =SUMIFS('Individual Data'!$AB$6:$AB$5544,'Individual Data'!$V$6:$V$5544,'age-length prop'!$B4,'Individual Data'!$I$6:$I$5544,'age-length prop'!$A4,'Individual Data'!$Y$6:$Y$5544,'age-length prop'!H$7,'Individual Data'!$N$6:$N$5544,'age-length prop'!$B$6) -> 0 | I4: =SUMIFS('Individual Data'!$AB$6:$AB$5544,'Individual Data'!$V$6:$V$5544,'age-length prop'!$B4,'Individual Data'!$I$6:$I$5544,'age-length prop'!$A4,'Individual Data'!$Y$6:$Y$5544,'age-length prop'!I$7,'Individual Data'!$N$6:$N$5544,'age-length prop'!$B$6) -> 0 | J4: =SUMIFS('Individual Data'!$AB$6:$AB$5544,'Individual Data'!$V$6:$V$5544,'age-length prop'!$B4,'Individual Data'!$I$6:$I$5544,'age-length prop'!$A4,'Individual Data'!$Y$6:$Y$5544,'age-length prop'!J$7,'Individual Data'!$N$6:$N$5544,'age-length prop'!$B$6) -> 37.492637 | K4: =SUMIFS('Individual Data'!$AB$6:$AB$5544,'Individual Data'!$V$6:$V$5544,'age-length prop'!$B4,'Individual Data'!$I$6:$I$5544,'age-length prop'!$A4,'Individual Data'!$Y$6:$Y$5544,'age-length prop'!K$7,'Individual Data'!$N$6:$N$5544,'age-length prop'!$B$6) -> 75.918897 | ... P4: =SUMIFS('Individual Data'!$AB$6:$AB$5544,'Individual Data'!$V$6:$V$5544,'age-length prop'!$B4,'Individual Data'!$I$6:$I$5544,'age-length prop'!$A4,'Individual Data'!$Y$6:$Y$5544,'age-length prop'!P$7,'Individual Data'!$N$6:$N$5544,'age-length prop'!$B$6) -> 0 | Q4: NG fish proportioned to known hatchery and unassigned groups by FL | AS4: =AS6+AT6 -> 22065.191 | AV4: M&F | AZ4: blw | BA4: ='Individual Data'!AG4 -> 0.249 | BB4: ='Individual Data'!AF4 -> 0.292
B5: total NG | D5: =D3+D4 -> 0 | E5: =E3+E4 -> 0 | F5: =F3+F4 -> 0 | G5: =G3+G4 -> 0 | H5: =H3+H4 -> 0 | I5: =I3+I4 -> 0 | J5: =J3+J4 -> 49.150735 | K5: =K3+K4 -> 90.095339 | ... P5: =P3+P4 -> 0 | AE5: Apply tag rate expansion: tag expanded estimates of known hatchery groups | AV5: =AS4+AS86 -> 42057.18 | AZ5: =SUM(AZ8:AZ61) -> 21052.61 | BA5: =SUM(BA8:BA61) -> 16473.703 | BB5: =SUM(BB8:BB61) -> 1972.9602 | BD5: =SUM(BD8:BD77) -> 19906.247 | BE5: =SUM(BE8:BE77) -> 16345.24 | BF5: =SUM(BF8:BF77) -> 1715.0405 | BI5: count minus tag expanded, # to subtract from unassigned groups by clip | BV5: % AD clip | BY5: AD clipped fish to subract from unassigned AD group | CM5: AI fish to subtract from unassigned group
B6: F | C6: total by FL | D6: =SUM(D8:D79) -> 0 | E6: =SUM(E8:E79) -> 0 | F6: =SUM(F8:F79) -> 0 | G6: =SUM(G8:G79) -> 69.948586 | H6: =SUM(H8:H79) -> 352.26127 | I6: =SUM(I8:I79) -> 1502.3099 | J6: =SUM(J8:J79) -> 5624.0677 | K6: =SUM(K8:K79) -> 8847.1566 | ... P6: =SUM(P8:P79) -> 0 | AS6: =SUM(AS8:AS77) -> 0 | AT6: =SUM(AT8:AT77) -> 22065.191 | BA6: =AZ5+BA5+BB5 -> 39499.273 | BE6: =BD5+BE5+BF5 -> 37966.527 | BI6: =SUM(BI8:BI61) -> 0 | BJ6: =SUM(BJ8:BJ61) -> 0 | BK6: =SUM(BK8:BK61) -> 0 | BL6: =SUM(BL8:BL61) -> 1.7126862 | BM6: =SUM(BM8:BM61) -> 8.7340488 | BN6: =SUM(BN8:BN61) -> 41.082258 | BO6: =SUM(BO8:BO61) -> 205.03486 | BP6: =SUM(BP8:BP61) -> 343.01848 | ... BU6: =SUM(BU8:BU61) -> 0 | BV6: =BW6/(BW6+BX6) -> 0.32097689 | BW6: =SUM(BW8:BW77) -> 736 | BX6: =SUM(BX8:BX77) -> 1557 | BY6: =SUM(BY8:BY77) -> 0 | BZ6: =SUM(BZ8:BZ77) -> 0 | CA6: =SUM(CA8:CA77) -> 0 | CB6: =SUM(CB8:CB77) -> 1.3717663 | CC6: =SUM(CC8:CC77) -> 5.0972324 | CD6: =SUM(CD8:CD77) -> 23.996649 | ... CK6: =SUM(CK8:CK77) -> 0 | CM6: =SUM(CM8:CM77) -> 0 | CN6: =SUM(CN8:CN77) -> 0 | CO6: =SUM(CO8:CO77) -> 0 | CP6: =SUM(CP8:CP77) -> 0.34091989 | CQ6: =SUM(CQ8:CQ77) -> 3.6368163 | CR6: =SUM(CR8:CR77) -> 19.175543 | CS6: =SUM(CS8:CS77) -> 135.72645 | CT6: =SUM(CT8:CT77) -> 226.67706 | ... CY6: =SUM(CY8:CY77) -> 0
B7: Final group | C7: agePBT | D7: 42 | E7: 47 | F7: 52 | G7: 57 | H7: 62 | I7: 67 | J7: 72 | K7: 77 | L7: 82 | M7: 87 | N7: 92 | O7: 99 | P7: 100 | Q7: 42 | R7: 47 | S7: 52 | T7: 57 | U7: 62 | V7: 67 | W7: 72 | X7: 77 | Y7: 82 | Z7: 87 | AA7: 92 | AB7: 99 | AC7: 100 | AD7: tag rate | AE7: 42 | AF7: 47 | AG7: 52 | AH7: 57 | AI7: 62 | AJ7: 67 | AK7: 72 | AL7: 77 | AM7: 82 | AN7: 87 | AO7: 92 | AP7: 99 | AQ7: 100 | AS7: F jacks | AT7: Females | AV7: Brd Yr | AW7: grp | AX7: origin | AY7: CWT code | AZ7: Female | BA7: Males | BB7: jacks | BC7: rel loc | BD7: Female | BE7: Males | BF7: jacks | BI7: 42 | BJ7: 47 | BK7: 52 | BL7: 57 | BM7: 62 | BN7: 67 | BO7: 72 | BP7: 77 | BQ7: 82 | BR7: 87 | BS7: 92 | BT7: 99 | BU7: 100 | BV7: % AD | BW7: AD | BX7: AI | BY7: 42 | BZ7: 47 | CA7: 52 | CB7: 57 | CC7: 62 | CD7: 67 | CE7: 72 | CF7: 77 | CG7: 82 | CH7: 87 | CI7: 92 | CJ7: 99 | CK7: 100 | CM7: 42 | CN7: 47 | CO7: 52 | CP7: 57 | CQ7: 62 | CR7: 67 | CS7: 72 | CT7: 77 | CU7: 82 | CV7: 87 | CW7: 92 | CX7: 99 | CY7: 100
A8: OtsLYON18S_1 | B8: BCA1 | C8: 5 | D8: =SUMIFS('Individual Data'!$AB$6:$AB$5544,'Individual Data'!$V$6:$V$5544,'age-length prop'!$B8,'Individual Data'!$Y$6:$Y$5544,'age-length prop'!D$7,'Individual Data'!$R$6:$R$5544,'age-length prop'!$C8,'Individual Data'!$N$6:$N$5544,'age-length prop'!$B$6) -> 0 | E8: =SUMIFS('Individual Data'!$AB$6:$AB$5544,'Individual Data'!$V$6:$V$5544,'age-length prop'!$B8,'Individual Data'!$Y$6:$Y$5544,'age-length prop'!E$7,'Individual Data'!$R$6:$R$5544,'age-length prop'!$C8,'Individual Data'!$N$6:$N$5544,'age-length prop'!$B$6) -> 0 | F8: =SUMIFS('Individual Data'!$AB$6:$AB$5544,'Individual Data'!$V$6:$V$5544,'age-length prop'!$B8,'Individual Data'!$Y$6:$Y$5544,'age-length prop'!F$7,'Individual Data'!$R$6:$R$5544,'age-length prop'!$C8,'Individual Data'!$N$6:$N$5544,'age-length prop'!$B$6) -> 0 | G8: =SUMIFS('Individual Data'!$AB$6:$AB$5544,'Individual Data'!$V$6:$V$5544,'age-length prop'!$B8,'Individual Data'!$Y$6:$Y$5544,'age-length prop'!G$7,'Individual Data'!$R$6:$R$5544,'age-length prop'!$C8,'Individual Data'!$N$6:$N$5544,'age-length prop'!$B$6) -> 0 | H8: =SUMIFS('Individual Data'!$AB$6:$AB$5544,'Individual Data'!$V$6:$V$5544,'age-length prop'!$B8,'Individual Data'!$Y$6:$Y$5544,'age-length prop'!H$7,'Individual Data'!$R$6:$R$5544,'age-length prop'!$C8,'Individual Data'!$N$6:$N$5544,'age-length prop'!$B$6) -> 0 | I8: =SUMIFS('Individual Data'!$AB$6:$AB$5544,'Individual Data'!$V$6:$V$5544,'age-length prop'!$B8,'Individual Data'!$Y$6:$Y$5544,'age-length prop'!I$7,'Individual Data'!$R$6:$R$5544,'age-length prop'!$C8,'Individual Data'!$N$6:$N$5544,'age-length prop'!$B$6) -> 0 | J8: =SUMIFS('Individual Data'!$AB$6:$AB$5544,'Individual Data'!$V$6:$V$5544,'age-length prop'!$B8,'Individual Data'!$Y$6:$Y$5544,'age-length prop'!J$7,'Individual Data'!$R$6:$R$5544,'age-length prop'!$C8,'Individual Data'!$N$6:$N$5544,'age-length prop'!$B$6) -> 0 | K8: =SUMIFS('Individual Data'!$AB$6:$AB$5544,'Individual Data'!$V$6:$V$5544,'age-length prop'!$B8,'Individual Data'!$Y$6:$Y$5544,'age-length prop'!K$7,'Individual Data'!$R$6:$R$5544,'age-length prop'!$C8,'Individual Data'!$N$6:$N$5544,'age-length prop'!$B$6) -> 16.694786 | ... P8: =SUMIFS('Individual Data'!$AB$6:$AB$5544,'Individual Data'!$V$6:$V$5544,'age-length prop'!$B8,'Individual Data'!$Y$6:$Y$5544,'age-length prop'!P$7,'Individual Data'!$R$6:$R$5544,'age-length prop'!$C8,'Individual Data'!$N$6:$N$5544,'age-length prop'!$B$6) -> 0 | Q8: =IFERROR(D8+(D$5*(D8/D$6)),0) -> 0 | R8: =IFERROR(E8+(E$5*(E8/E$6)),0) -> 0 | S8: =IFERROR(F8+(F$5*(F8/F$6)),0) -> 0 | T8: =IFERROR(G8+(G$5*(G8/G$6)),0) -> 0 | U8: =IFERROR(H8+(H$5*(H8/H$6)),0) -> 0 | V8: =IFERROR(I8+(I$5*(I8/I$6)),0) -> 0 | W8: =IFERROR(J8+(J$5*(J8/J$6)),0) -> 0 | X8: =IFERROR(K8+(K$5*(K8/K$6)),0) -> 16.864798 | ... AC8: =IFERROR(P8+(P$5*(P8/P$6)),0) -> 0 | AD8: =VLOOKUP(A8,'PBT Tag Rates'!$B$5:$E$44,4,FALSE) -> 0.80551598 | AE8: =Q8/$AD8 -> 0 | AF8: =R8/$AD8 -> 0 | AG8: =S8/$AD8 -> 0 | AH8: =T8/$AD8 -> 0 | AI8: =U8/$AD8 -> 0 | AJ8: =V8/$AD8 -> 0 | AK8: =W8/$AD8 -> 0 | AL8: =X8/$AD8 -> 20.936639 | ... AQ8: =AC8/$AD8 -> 0 | AS8: =SUM(AE8:AG8) -> 0 | AT8: =SUM(AH8:AQ8) -> 72.439029 | AV8: =$AV$3-C8 -> 2018 | AW8: =B8 -> BCA1 | AX8: SR | AY8: =SUMIFS('cwt rel info'!$A$6:$A$317,'cwt rel info'!$D$6:$D$317,'age-length prop'!AV8,'cwt rel info'!$E$6:$E$317,'age-length prop'!AW8) -> 220511 | AZ8: =AS8+AT8 -> 72.439029 | BA8: =AT90 -> 48.45176 | BB8: =AS90 -> 0 | BC8: =VLOOKUP(AW8,'Individual Data'!$V$5:$AC$5544,8,FALSE) -> Abv | BD8: =IF(BC8="blw",AZ8*(1-$BA$4),AZ8*(1-$BA$3)) -> 70.628053 | BE8: =IF(BC8="blw",BA8*(1-$BA$4),BA8*(1-$BA$3)) -> 47.240466 | BF8: =IF(BC8="blw",BB8*(1-$BB$4),BB8*(1-$BB$3)) -> 0 | BI8: =AE8-Q8 -> 0 | BJ8: =AF8-R8 -> 0 | BK8: =AG8-S8 -> 0 | BL8: =AH8-T8 -> 0 | BM8: =AI8-U8 -> 0 | BN8: =AJ8-V8 -> 0 | BO8: =AK8-W8 -> 0 | BP8: =AL8-X8 -> 4.0718417 | ... BU8: =AQ8-AC8 -> 0 | BV8: =IFERROR(BW8/(BW8+BX8),0) -> 0.33333333 | BW8: =SUMIFS('Individual Data'!$X$6:$X$5544,'Individual Data'!$I$6:$I$5544,'age-length prop'!BW$7,'Individual Data'!$V$6:$V$5544,'age-length prop'!$B8,'Individual Data'!$R$6:$R$5544,'age-length prop'!$C8,'Individual Data'!$N$6:$N$5544,"F") -> 4 | BX8: =SUMIFS('Individual Data'!$X$6:$X$5544,'Individual Data'!$I$6:$I$5544,'age-length prop'!BX$7,'Individual Data'!$V$6:$V$5544,'age-length prop'!$B8,'Individual Data'!$R$6:$R$5544,'age-length prop'!$C8,'Individual Data'!$N$6:$N$5544,"F") -> 8 | BY8: =BI8*$BV8 -> 0 | BZ8: =BJ8*$BV8 -> 0 | CA8: =BK8*$BV8 -> 0 | CB8: =BL8*$BV8 -> 0 | CC8: =BM8*$BV8 -> 0 | CD8: =BN8*$BV8 -> 0 | CE8: =BO8*$BV8 -> 0 | CF8: =BP8*$BV8 -> 1.3572806 | ... CK8: =BU8*$BV8 -> 0 | CM8: =BI8*(1-$BV8) -> 0 | CN8: =BJ8*(1-$BV8) -> 0 | CO8: =BK8*(1-$BV8) -> 0 | CP8: =BL8*(1-$BV8) -> 0 | CQ8: =BM8*(1-$BV8) -> 0 | CR8: =BN8*(1-$BV8) -> 0 | CS8: =BO8*(1-$BV8) -> 0 | CT8: =BP8*(1-$BV8) -> 2.7145612 | ... CY8: =BU8*(1-$BV8) -> 0
A9: OtsLYON18S_1 | B9: BCA2 | C9: 5 | D9: =SUMIFS('Individual Data'!$AB$6:$AB$5544,'Individual Data'!$V$6:$V$5544,'age-length prop'!$B9,'Individual Data'!$Y$6:$Y$5544,'age-length prop'!D$7,'Individual Data'!$R$6:$R$5544,'age-length prop'!$C9,'Individual Data'!$N$6:$N$5544,'age-length prop'!$B$6) -> 0 | E9: =SUMIFS('Individual Data'!$AB$6:$AB$5544,'Individual Data'!$V$6:$V$5544,'age-length prop'!$B9,'Individual Data'!$Y$6:$Y$5544,'age-length prop'!E$7,'Individual Data'!$R$6:$R$5544,'age-length prop'!$C9,'Individual Data'!$N$6:$N$5544,'age-length prop'!$B$6) -> 0 | F9: =SUMIFS('Individual Data'!$AB$6:$AB$5544,'Individual Data'!$V$6:$V$5544,'age-length prop'!$B9,'Individual Data'!$Y$6:$Y$5544,'age-length prop'!F$7,'Individual Data'!$R$6:$R$5544,'age-length prop'!$C9,'Individual Data'!$N$6:$N$5544,'age-length prop'!$B$6) -> 0 | G9: =SUMIFS('Individual Data'!$AB$6:$AB$5544,'Individual Data'!$V$6:$V$5544,'age-length prop'!$B9,'Individual Data'!$Y$6:$Y$5544,'age-length prop'!G$7,'Individual Data'!$R$6:$R$5544,'age-length prop'!$C9,'Individual Data'!$N$6:$N$5544,'age-length prop'!$B$6) -> 0 | H9: =SUMIFS('Individual Data'!$AB$6:$AB$5544,'Individual Data'!$V$6:$V$5544,'age-length prop'!$B9,'Individual Data'!$Y$6:$Y$5544,'age-length prop'!H$7,'Individual Data'!$R$6:$R$5544,'age-length prop'!$C9,'Individual Data'!$N$6:$N$5544,'age-length prop'!$B$6) -> 0 | I9: =SUMIFS('Individual Data'!$AB$6:$AB$5544,'Individual Data'!$V$6:$V$5544,'age-length prop'!$B9,'Individual Data'!$Y$6:$Y$5544,'age-length prop'!I$7,'Individual Data'!$R$6:$R$5544,'age-length prop'!$C9,'Individual Data'!$N$6:$N$5544,'age-length prop'!$B$6) -> 0 | J9: =SUMIFS('Individual Data'!$AB$6:$AB$5544,'Individual Data'!$V$6:$V$5544,'age-length prop'!$B9,'Individual Data'!$Y$6:$Y$5544,'age-length prop'!J$7,'Individual Data'!$R$6:$R$5544,'age-length prop'!$C9,'Individual Data'!$N$6:$N$5544,'age-length prop'!$B$6) -> 0 | K9: =SUMIFS('Individual Data'!$AB$6:$AB$5544,'Individual Data'!$V$6:$V$5544,'age-length prop'!$B9,'Individual Data'!$Y$6:$Y$5544,'age-length prop'!K$7,'Individual Data'!$R$6:$R$5544,'age-length prop'!$C9,'Individual Data'!$N$6:$N$5544,'age-length prop'!$B$6) -> 11.658098 | ... P9: =SUMIFS('Individual Data'!$AB$6:$AB$5544,'Individual Data'!$V$6:$V$5544,'age-length prop'!$B9,'Individual Data'!$Y$6:$Y$5544,'age-length prop'!P$7,'Individual Data'!$R$6:$R$5544,'age-length prop'!$C9,'Individual Data'!$N$6:$N$5544,'age-length prop'!$B$6) -> 0 | Q9: =IFERROR(D9+(D$5*(D9/D$6)),0) -> 0 | R9: =IFERROR(E9+(E$5*(E9/E$6)),0) -> 0 | S9: =IFERROR(F9+(F$5*(F9/F$6)),0) -> 0 | T9: =IFERROR(G9+(G$5*(G9/G$6)),0) -> 0 | U9: =IFERROR(H9+(H$5*(H9/H$6)),0) -> 0 | V9: =IFERROR(I9+(I$5*(I9/I$6)),0) -> 0 | W9: =IFERROR(J9+(J$5*(J9/J$6)),0) -> 0 | X9: =IFERROR(K9+(K$5*(K9/K$6)),0) -> 11.776818 | ... AC9: =IFERROR(P9+(P$5*(P9/P$6)),0) -> 0 | AD9: =VLOOKUP(A9,'PBT Tag Rates'!$B$5:$E$44,4,FALSE) -> 0.80551598 | AE9: =Q9/$AD9 -> 0 | AF9: =R9/$AD9 -> 0 | AG9: =S9/$AD9 -> 0 | AH9: =T9/$AD9 -> 0 | AI9: =U9/$AD9 -> 0 | AJ9: =V9/$AD9 -> 0 | AK9: =W9/$AD9 -> 0 | AL9: =X9/$AD9 -> 14.620217 | ... AQ9: =AC9/$AD9 -> 0 | AS9: =SUM(AE9:AG9) -> 0 | AT9: =SUM(AH9:AQ9) -> 43.960603 | AV9: =$AV$3-C9 -> 2018 | AW9: =B9 -> BCA2 | AX9: SR | AY9: =SUMIFS('cwt rel info'!$A$6:$A$317,'cwt rel info'!$D$6:$D$317,'age-length prop'!AV9,'cwt rel info'!$E$6:$E$317,'age-length prop'!AW9) -> 220512 | AZ9: =AS9+AT9 -> 43.960603 | BA9: =AT91 -> 14.595584 | BB9: =AS91 -> 0 | BC9: =VLOOKUP(AW9,'Individual Data'!$V$5:$AC$5544,8,FALSE) -> Abv | BD9: =IF(BC9="blw",AZ9*(1-$BA$4),AZ9*(1-$BA$3)) -> 42.861588 | BE9: =IF(BC9="blw",BA9*(1-$BA$4),BA9*(1-$BA$3)) -> 14.230695 | BF9: =IF(BC9="blw",BB9*(1-$BB$4),BB9*(1-$BB$3)) -> 0 | BI9: =AE9-Q9 -> 0 | BJ9: =AF9-R9 -> 0 | BK9: =AG9-S9 -> 0 | BL9: =AH9-T9 -> 0 | BM9: =AI9-U9 -> 0 | BN9: =AJ9-V9 -> 0 | BO9: =AK9-W9 -> 0 | BP9: =AL9-X9 -> 2.8433985 | ... BU9: =AQ9-AC9 -> 0 | BV9: =IFERROR(BW9/(BW9+BX9),0) -> 0.66666667 | BW9: =SUMIFS('Individual Data'!$X$6:$X$5544,'Individual Data'!$I$6:$I$5544,'age-length prop'!BW$7,'Individual Data'!$V$6:$V$5544,'age-length prop'!$B9,'Individual Data'!$R$6:$R$5544,'age-length prop'!$C9,'Individual Data'!$N$6:$N$5544,"F") -> 2 | BX9: =SUMIFS('Individual Data'!$X$6:$X$5544,'Individual Data'!$I$6:$I$5544,'age-length prop'!BX$7,'Individual Data'!$V$6:$V$5544,'age-length prop'!$B9,'Individual Data'!$R$6:$R$5544,'age-length prop'!$C9,'Individual Data'!$N$6:$N$5544,"F") -> 1 | BY9: =BI9*$BV9 -> 0 | BZ9: =BJ9*$BV9 -> 0 | CA9: =BK9*$BV9 -> 0 | CB9: =BL9*$BV9 -> 0 | CC9: =BM9*$BV9 -> 0 | CD9: =BN9*$BV9 -> 0 | CE9: =BO9*$BV9 -> 0 | CF9: =BP9*$BV9 -> 1.895599 | ... CK9: =BU9*$BV9 -> 0 | CM9: =BI9*(1-$BV9) -> 0 | CN9: =BJ9*(1-$BV9) -> 0 | CO9: =BK9*(1-$BV9) -> 0 | CP9: =BL9*(1-$BV9) -> 0 | CQ9: =BM9*(1-$BV9) -> 0 | CR9: =BN9*(1-$BV9) -> 0 | CS9: =BO9*(1-$BV9) -> 0 | CT9: =BP9*(1-$BV9) -> 0.94779949 | ... CY9: =BU9*(1-$BV9) -> 0
A10: OtsLYON18S_1 | B10: CJA1 | C10: 5 | D10: =SUMIFS('Individual Data'!$AB$6:$AB$5544,'Individual Data'!$V$6:$V$5544,'age-length prop'!$B10,'Individual Data'!$Y$6:$Y$5544,'age-length prop'!D$7,'Individual Data'!$R$6:$R$5544,'age-length prop'!$C10,'Individual Data'!$N$6:$N$5544,'age-length prop'!$B$6) -> 0 | E10: =SUMIFS('Individual Data'!$AB$6:$AB$5544,'Individual Data'!$V$6:$V$5544,'age-length prop'!$B10,'Individual Data'!$Y$6:$Y$5544,'age-length prop'!E$7,'Individual Data'!$R$6:$R$5544,'age-length prop'!$C10,'Individual Data'!$N$6:$N$5544,'age-length prop'!$B$6) -> 0 | F10: =SUMIFS('Individual Data'!$AB$6:$AB$5544,'Individual Data'!$V$6:$V$5544,'age-length prop'!$B10,'Individual Data'!$Y$6:$Y$5544,'age-length prop'!F$7,'Individual Data'!$R$6:$R$5544,'age-length prop'!$C10,'Individual Data'!$N$6:$N$5544,'age-length prop'!$B$6) -> 0 | G10: =SUMIFS('Individual Data'!$AB$6:$AB$5544,'Individual Data'!$V$6:$V$5544,'age-length prop'!$B10,'Individual Data'!$Y$6:$Y$5544,'age-length prop'!G$7,'Individual Data'!$R$6:$R$5544,'age-length prop'!$C10,'Individual Data'!$N$6:$N$5544,'age-length prop'!$B$6) -> 0 | H10: =SUMIFS('Individual Data'!$AB$6:$AB$5544,'Individual Data'!$V$6:$V$5544,'age-length prop'!$B10,'Individual Data'!$Y$6:$Y$5544,'age-length prop'!H$7,'Individual Data'!$R$6:$R$5544,'age-length prop'!$C10,'Individual Data'!$N$6:$N$5544,'age-length prop'!$B$6) -> 0 | I10: =SUMIFS('Individual Data'!$AB$6:$AB$5544,'Individual Data'!$V$6:$V$5544,'age-length prop'!$B10,'Individual Data'!$Y$6:$Y$5544,'age-length prop'!I$7,'Individual Data'!$R$6:$R$5544,'age-length prop'!$C10,'Individual Data'!$N$6:$N$5544,'age-length prop'!$B$6) -> 0 | J10: =SUMIFS('Individual Data'!$AB$6:$AB$5544,'Individual Data'!$V$6:$V$5544,'age-length prop'!$B10,'Individual Data'!$Y$6:$Y$5544,'age-length prop'!J$7,'Individual Data'!$R$6:$R$5544,'age-length prop'!$C10,'Individual Data'!$N$6:$N$5544,'age-length prop'!$B$6) -> 0 | K10: =SUMIFS('Individual Data'!$AB$6:$AB$5544,'Individual Data'!$V$6:$V$5544,'age-length prop'!$B10,'Individual Data'!$Y$6:$Y$5544,'age-length prop'!K$7,'Individual Data'!$R$6:$R$5544,'age-length prop'!$C10,'Individual Data'!$N$6:$N$5544,'age-length prop'!$B$6) -> 25.834539 | ... P10: =SUMIFS('Individual Data'!$AB$6:$AB$5544,'Individual Data'!$V$6:$V$5544,'age-length prop'!$B10,'Individual Data'!$Y$6:$Y$5544,'age-length prop'!P$7,'Individual Data'!$R$6:$R$5544,'age-length prop'!$C10,'Individual Data'!$N$6:$N$5544,'age-length prop'!$B$6) -> 0 | Q10: =IFERROR(D10+(D$5*(D10/D$6)),0) -> 0 | R10: =IFERROR(E10+(E$5*(E10/E$6)),0) -> 0 | S10: =IFERROR(F10+(F$5*(F10/F$6)),0) -> 0 | T10: =IFERROR(G10+(G$5*(G10/G$6)),0) -> 0 | U10: =IFERROR(H10+(H$5*(H10/H$6)),0) -> 0 | V10: =IFERROR(I10+(I$5*(I10/I$6)),0) -> 0 | W10: =IFERROR(J10+(J$5*(J10/J$6)),0) -> 0 | X10: =IFERROR(K10+(K$5*(K10/K$6)),0) -> 26.097626 | ... AC10: =IFERROR(P10+(P$5*(P10/P$6)),0) -> 0 | AD10: =VLOOKUP(A10,'PBT Tag Rates'!$B$5:$E$44,4,FALSE) -> 0.80551598 | AE10: =Q10/$AD10 -> 0 | AF10: =R10/$AD10 -> 0 | AG10: =S10/$AD10 -> 0 | AH10: =T10/$AD10 -> 0 | AI10: =U10/$AD10 -> 0 | AJ10: =V10/$AD10 -> 0 | AK10: =W10/$AD10 -> 0 | AL10: =X10/$AD10 -> 32.398645 | ... AQ10: =AC10/$AD10 -> 0 | AS10: =SUM(AE10:AG10) -> 0 | AT10: =SUM(AH10:AQ10) -> 98.566022 | AV10: =$AV$3-C10 -> 2018 | AW10: =B10 -> CJA1 | AX10: SR | AY10: =SUMIFS('cwt rel info'!$A$6:$A$317,'cwt rel info'!$D$6:$D$317,'age-length prop'!AV10,'cwt rel info'!$E$6:$E$317,'age-length prop'!AW10) -> 220509 | AZ10: =AS10+AT10 -> 98.566022 | BA10: =AT92 -> 52.003388 | BB10: =AS92 -> 0 | BC10: =VLOOKUP(AW10,'Individual Data'!$V$5:$AC$5544,8,FALSE) -> Abv | BD10: =IF(BC10="blw",AZ10*(1-$BA$4),AZ10*(1-$BA$3)) -> 96.101871 | BE10: =IF(BC10="blw",BA10*(1-$BA$4),BA10*(1-$BA$3)) -> 50.703304 | BF10: =IF(BC10="blw",BB10*(1-$BB$4),BB10*(1-$BB$3)) -> 0 | BI10: =AE10-Q10 -> 0 | BJ10: =AF10-R10 -> 0 | BK10: =AG10-S10 -> 0 | BL10: =AH10-T10 -> 0 | BM10: =AI10-U10 -> 0 | BN10: =AJ10-V10 -> 0 | BO10: =AK10-W10 -> 0 | BP10: =AL10-X10 -> 6.3010186 | ... BU10: =AQ10-AC10 -> 0 | BV10: =IFERROR(BW10/(BW10+BX10),0) -> 0.30769231 | BW10: =SUMIFS('Individual Data'!$X$6:$X$5544,'Individual Data'!$I$6:$I$5544,'age-length prop'!BW$7,'Individual Data'!$V$6:$V$5544,'age-length prop'!$B10,'Individual Data'!$R$6:$R$5544,'age-length prop'!$C10,'Individual Data'!$N$6:$N$5544,"F") -> 4 | BX10: =SUMIFS('Individual Data'!$X$6:$X$5544,'Individual Data'!$I$6:$I$5544,'age-length prop'!BX$7,'Individual Data'!$V$6:$V$5544,'age-length prop'!$B10,'Individual Data'!$R$6:$R$5544,'age-length prop'!$C10,'Individual Data'!$N$6:$N$5544,"F") -> 9 | BY10: =BI10*$BV10 -> 0 | BZ10: =BJ10*$BV10 -> 0 | CA10: =BK10*$BV10 -> 0 | CB10: =BL10*$BV10 -> 0 | CC10: =BM10*$BV10 -> 0 | CD10: =BN10*$BV10 -> 0 | CE10: =BO10*$BV10 -> 0 | CF10: =BP10*$BV10 -> 1.938775 | ... CK10: =BU10*$BV10 -> 0 | CM10: =BI10*(1-$BV10) -> 0 | CN10: =BJ10*(1-$BV10) -> 0 | CO10: =BK10*(1-$BV10) -> 0 | CP10: =BL10*(1-$BV10) -> 0 | CQ10: =BM10*(1-$BV10) -> 0 | CR10: =BN10*(1-$BV10) -> 0 | CS10: =BO10*(1-$BV10) -> 0 | CT10: =BP10*(1-$BV10) -> 4.3622436 | ... CY10: =BU10*(1-$BV10) -> 0
A11: OtsLYON18S_1 | B11: CJA2 | C11: 5 | D11: =SUMIFS('Individual Data'!$AB$6:$AB$5544,'Individual Data'!$V$6:$V$5544,'age-length prop'!$B11,'Individual Data'!$Y$6:$Y$5544,'age-length prop'!D$7,'Individual Data'!$R$6:$R$5544,'age-length prop'!$C11,'Individual Data'!$N$6:$N$5544,'age-length prop'!$B$6) -> 0 | E11: =SUMIFS('Individual Data'!$AB$6:$AB$5544,'Individual Data'!$V$6:$V$5544,'age-length prop'!$B11,'Individual Data'!$Y$6:$Y$5544,'age-length prop'!E$7,'Individual Data'!$R$6:$R$5544,'age-length prop'!$C11,'Individual Data'!$N$6:$N$5544,'age-length prop'!$B$6) -> 0 | F11: =SUMIFS('Individual Data'!$AB$6:$AB$5544,'Individual Data'!$V$6:$V$5544,'age-length prop'!$B11,'Individual Data'!$Y$6:$Y$5544,'age-length prop'!F$7,'Individual Data'!$R$6:$R$5544,'age-length prop'!$C11,'Individual Data'!$N$6:$N$5544,'age-length prop'!$B$6) -> 0 | G11: =SUMIFS('Individual Data'!$AB$6:$AB$5544,'Individual Data'!$V$6:$V$5544,'age-length prop'!$B11,'Individual Data'!$Y$6:$Y$5544,'age-length prop'!G$7,'Individual Data'!$R$6:$R$5544,'age-length prop'!$C11,'Individual Data'!$N$6:$N$5544,'age-length prop'!$B$6) -> 0 | H11: =SUMIFS('Individual Data'!$AB$6:$AB$5544,'Individual Data'!$V$6:$V$5544,'age-length prop'!$B11,'Individual Data'!$Y$6:$Y$5544,'age-length prop'!H$7,'Individual Data'!$R$6:$R$5544,'age-length prop'!$C11,'Individual Data'!$N$6:$N$5544,'age-length prop'!$B$6) -> 0 | I11: =SUMIFS('Individual Data'!$AB$6:$AB$5544,'Individual Data'!$V$6:$V$5544,'age-length prop'!$B11,'Individual Data'!$Y$6:$Y$5544,'age-length prop'!I$7,'Individual Data'!$R$6:$R$5544,'age-length prop'!$C11,'Individual Data'!$N$6:$N$5544,'age-length prop'!$B$6) -> 0 | J11: =SUMIFS('Individual Data'!$AB$6:$AB$5544,'Individual Data'!$V$6:$V$5544,'age-length prop'!$B11,'Individual Data'!$Y$6:$Y$5544,'age-length prop'!J$7,'Individual Data'!$R$6:$R$5544,'age-length prop'!$C11,'Individual Data'!$N$6:$N$5544,'age-length prop'!$B$6) -> 0 | K11: =SUMIFS('Individual Data'!$AB$6:$AB$5544,'Individual Data'!$V$6:$V$5544,'age-length prop'!$B11,'Individual Data'!$Y$6:$Y$5544,'age-length prop'!K$7,'Individual Data'!$R$6:$R$5544,'age-length prop'!$C11,'Individual Data'!$N$6:$N$5544,'age-length prop'!$B$6) -> 0 | ... P11: =SUMIFS('Individual Data'!$AB$6:$AB$5544,'Individual Data'!$V$6:$V$5544,'age-length prop'!$B11,'Individual Data'!$Y$6:$Y$5544,'age-length prop'!P$7,'Individual Data'!$R$6:$R$5544,'age-length prop'!$C11,'Individual Data'!$N$6:$N$5544,'age-length prop'!$B$6) -> 0 | Q11: =IFERROR(D11+(D$5*(D11/D$6)),0) -> 0 | R11: =IFERROR(E11+(E$5*(E11/E$6)),0) -> 0 | S11: =IFERROR(F11+(F$5*(F11/F$6)),0) -> 0 | T11: =IFERROR(G11+(G$5*(G11/G$6)),0) -> 0 | U11: =IFERROR(H11+(H$5*(H11/H$6)),0) -> 0 | V11: =IFERROR(I11+(I$5*(I11/I$6)),0) -> 0 | W11: =IFERROR(J11+(J$5*(J11/J$6)),0) -> 0 | X11: =IFERROR(K11+(K$5*(K11/K$6)),0) -> 0 | ... AC11: =IFERROR(P11+(P$5*(P11/P$6)),0) -> 0 | AD11: =VLOOKUP(A11,'PBT Tag Rates'!$B$5:$E$44,4,FALSE) -> 0.80551598 | AE11: =Q11/$AD11 -> 0 | AF11: =R11/$AD11 -> 0 | AG11: =S11/$AD11 -> 0 | AH11: =T11/$AD11 -> 0 | AI11: =U11/$AD11 -> 0 | AJ11: =V11/$AD11 -> 0 | AK11: =W11/$AD11 -> 0 | AL11: =X11/$AD11 -> 0 | ... AQ11: =AC11/$AD11 -> 0 | AS11: =SUM(AE11:AG11) -> 0 | AT11: =SUM(AH11:AQ11) -> 14.670193 | AV11: =$AV$3-C11 -> 2018 | AW11: =B11 -> CJA2 | AX11: SR | AY11: =SUMIFS('cwt rel info'!$A$6:$A$317,'cwt rel info'!$D$6:$D$317,'age-length prop'!AV11,'cwt rel info'!$E$6:$E$317,'age-length prop'!AW11) -> 220510 | AZ11: =AS11+AT11 -> 14.670193 | BA11: =AT93 -> 0 | BB11: =AS93 -> 0 | BC11: =VLOOKUP(AW11,'Individual Data'!$V$5:$AC$5544,8,FALSE) -> Abv | BD11: =IF(BC11="blw",AZ11*(1-$BA$4),AZ11*(1-$BA$3)) -> 14.303438 | BE11: =IF(BC11="blw",BA11*(1-$BA$4),BA11*(1-$BA$3)) -> 0 | BF11: =IF(BC11="blw",BB11*(1-$BB$4),BB11*(1-$BB$3)) -> 0 | BI11: =AE11-Q11 -> 0 | BJ11: =AF11-R11 -> 0 | BK11: =AG11-S11 -> 0 | BL11: =AH11-T11 -> 0 | BM11: =AI11-U11 -> 0 | BN11: =AJ11-V11 -> 0 | BO11: =AK11-W11 -> 0 | BP11: =AL11-X11 -> 0 | ... BU11: =AQ11-AC11 -> 0 | BV11: =IFERROR(BW11/(BW11+BX11),0) -> 1 | BW11: =SUMIFS('Individual Data'!$X$6:$X$5544,'Individual Data'!$I$6:$I$5544,'age-length prop'!BW$7,'Individual Data'!$V$6:$V$5544,'age-length prop'!$B11,'Individual Data'!$R$6:$R$5544,'age-length prop'!$C11,'Individual Data'!$N$6:$N$5544,"F") -> 1 | BX11: =SUMIFS('Individual Data'!$X$6:$X$5544,'Individual Data'!$I$6:$I$5544,'age-length prop'!BX$7,'Individual Data'!$V$6:$V$5544,'age-length prop'!$B11,'Individual Data'!$R$6:$R$5544,'age-length prop'!$C11,'Individual Data'!$N$6:$N$5544,"F") -> 0 | BY11: =BI11*$BV11 -> 0 | BZ11: =BJ11*$BV11 -> 0 | CA11: =BK11*$BV11 -> 0 | CB11: =BL11*$BV11 -> 0 | CC11: =BM11*$BV11 -> 0 | CD11: =BN11*$BV11 -> 0 | CE11: =BO11*$BV11 -> 0 | CF11: =BP11*$BV11 -> 0 | ... CK11: =BU11*$BV11 -> 0 | CM11: =BI11*(1-$BV11) -> 0 | CN11: =BJ11*(1-$BV11) -> 0 | CO11: =BK11*(1-$BV11) -> 0 | CP11: =BL11*(1-$BV11) -> 0 | CQ11: =BM11*(1-$BV11) -> 0 | CR11: =BN11*(1-$BV11) -> 0 | CS11: =BO11*(1-$BV11) -> 0 | CT11: =BP11*(1-$BV11) -> 0 | ... CY11: =BU11*(1-$BV11) -> 0
