Workbook

Sheet Column Definitions
A1: Column name | B1: Definition
A2: Population | B2: IDFG Progeny database collection ID
A3: Individual | B3: IDFG Progeny database individual ID
A4: LGRScaleGeneticsIDLink | B4: Individual genetics ID in metadata provided to IDFG Eagle Genetics Lab
A5: DateSampled | B5: Date sampled at Lower Granite Dam
A6: PhenotypicSex | B6: Sex as identified at the Dam
A7: Length | B7: Fork Length
A8: Clip | B8: Adipose fin status - AD is for Ad-clipped, AI is for ad-intact
A9: Wire | B9: 1 if CWT present, NA if absent
A10: GenComments | B10: Lists all genetic duplicates and samples that failed to genotype
A11: GenSex | B11: Genetic sex
A12: GenPa | B12: IDFG Progeny database ID of the PBT assigned sire
... A17: RepUnitProb | B17: Probability of assignment to the given GSI reporting unit

Sheet pvt tbl
A4: Count of Individual | B4: Final group
A5: pooled FL | B5: BCA1 | C5: BCA2 | D5: CJA1 | E5: CJA2 | F5: PLA1 | G5: PLA2 | H5: Grand Total
A6: 42 | B6: 1 | D6: 1 | E6: 5 | G6: 3 | H6: 10
A7: 47 | B7: 9 | C7: 1 | D7: 13 | E7: 9 | F7: 8 | G7: 7 | H7: 47
A8: 52 | B8: 9 | C8: 3 | D8: 9 | E8: 3 | F8: 12 | G8: 5 | H8: 41
A9: 57 | B9: 10 | C9: 3 | D9: 6 | E9: 2 | F9: 5 | H9: 26
A10: 62 | B10: 21 | C10: 13 | D10: 14 | E10: 8 | F10: 14 | G10: 8 | H10: 78
A11: 67 | B11: 34 | C11: 15 | D11: 40 | E11: 14 | F11: 43 | G11: 10 | H11: 156
A12: 72 | B12: 30 | C12: 13 | D12: 43 | E12: 7 | F12: 34 | G12: 17 | H12: 144
A13: 77 | B13: 41 | C13: 9 | D13: 64 | E13: 12 | F13: 27 | G13: 14 | H13: 167
A14: 82 | B14: 18 | C14: 4 | D14: 27 | E14: 9 | F14: 14 | G14: 6 | H14: 78
A15: 87 | B15: 7 | C15: 4 | D15: 13 | F15: 9 | G15: 2 | H15: 35
A16: 92 | D16: 2 | F16: 3 | H16: 5
A17: 100 | F17: 1 | H17: 1
A18: Grand Total | B18: 180 | C18: 65 | D18: 232 | E18: 69 | F18: 170 | G18: 72 | H18: 788

Sheet Individual Data
C1: TSR | D1: Trap Rate | E1: effective TR | F1: Start date | G1: # genotyped | H1: # trapped | I1: genotype rate | AC1: sum @ LGR | AD1: Window count | AP1: trap rate | AQ1: expd | AR1: window
C2: 70 | D2: 0.7 | E2: ='LGD window'!O39 -> 0.65333638 | F2: 45522 | G2: 286 | H2: 2892 | I2: =G2/H2 -> 0.098893499 | U2: NG | V2: =COUNTIF(V7:V5545,"NG") -> 36 | X2: sum | Y2: sum | Z2: sum | AA2: =SUM(AA7:AA5545) -> 11786.584 | AB2: =SUM(AB7:AB5545) -> 11786.71 | AC2: =SUM(AC7:AC5545) -> 41063.155 | AD2: =SUM('LGD window'!Q39:Q42) -> 2559 | AG2: fallback/reassension | AL2: fallback only | AP2: 70 | AQ2: =SUMIF($E$7:$E$2565,"70",$AC$7:$AC$2565) -> 4129.4151 | AR2: 4376
C3: 40 | D3: 0.4 | E3: ='LGD window'!O40 -> 0.39762975 | F3: 45531 | G3: 649 | H3: 3909 | I3: =G3/H3 -> 0.16602712 | S3: Run year | U3: total | V3: =SUM(X7:X5545) -> 2559 | X3: =SUM(X7:X5545) -> 2559 | Y3: =SUM(Y7:Y5545) -> 2559.3239 | AH3: jack | AI3: adlt | AM3: jack | AN3: adlt | AP3: 40 | AQ3: =SUMIF($E$7:$E$2565,"40",$AC$7:$AC$2565) -> 9758.8035 | AR3: 9788
C4: 18 | D4: 0.18 | E4: ='LGD window'!O41 -> 0.17875244 | F4: 45542 | G4: 1492 | H4: 4484 | I4: =G4/H4 -> 0.33273863 | S4: 2024 | U4: % NG | V4: =V2/V3 -> 0.014067995 | AG4: abv | AH4: 0.074 | AI4: 0.024 | AL4: abv | AM4: 0 | AN4: 0 | AP4: 18 | AQ4: =SUMIF($E$7:$E$2565,"18",$AC$7:$AC$2565) -> 24919.995 | AR4: 24930
C5: 9 | D5: 0.09 | E5: ='LGD window'!O42 -> 0.08412483 | F5: 45577 | G5: 132 | H5: 203 | I5: =G5/H5 -> 0.65024631 | AB5: 0 | AG5: blw | AH5: 0.29 | AI5: 0.33 | AL5: blw | AM5: 0.36 | AN5: 0.19 | AP5: 9 | AQ5: =SUMIF($E$7:$E$2565,"9",$AC$7:$AC$2565) -> 2254.9411 | AR5: 2163
A6: Population | B6: Individual | C6: LGRScaleGeneticsIDLink | D6: DateSampled | E6: sample rate | F6: PhenotypicSex | G6: FL mm | H6: FL cm | I6: Clip | J6: Wire | K6: PIT tag | L6: GenComments | M6: GenSex | N6: best sex | O6: GenPa | P6: GenMa | Q6: PopName | R6: agePBT | S6: Brd Yr | T6: GSIRepUnit | U6: RepUnitProb | V6: Final group | W6: Tag rate | X6: count | Y6: NG proportioning | Z6: pooled FL | AA6: trap rate expansion | AB6: tag rate expansion | AC6: PBT geno rate expansion | AD6: rel abv/blw LGR
A7: OtsLGRF24S | B7: OtsLGRF24S_0005 | C7: C-00005 | D7: 45522 | E7: =IF(AND(D7>=$F$2,D7<$F$3),70,IF(AND(D7>=$F$3,D7<$F$4),40,IF(AND(D7>=$F$4,D7<$F$5),18,9))) -> 70 | F7: M | G7: 700 | H7: =G7/10 -> 70 | I7: AI | J7: NA | K7: 3DD.0078C31710 | L7: NA | M7: M | N7: =IF(M7="U",F7,M7) -> M | O7: OtsNPFH20S_1_0082 | P7: OtsNPFH20S_1_0037 | Q7: OtsNPFH20S_1 | R7: 4 | S7: =IFERROR($S$4-R7,"U") -> 2020 | T7: FALL | U7: 1 | V7: NPTH | W7: =VLOOKUP(Q7,'PBT Tag Rates'!$A$6:$D$67,4,FALSE) -> 0.98845609 | X7: 1 | Y7: =IF(V7="ng",0,X7+(SUMIFS($AK$24:$AK$127,$AG$24:$AG$127,$N7,$AH$24:$AH$127,$Z7,$AF$24:$AF$127,$E7))) -> 1.0952381 | Z7: =IFERROR(LOOKUP(H7,{30,43,48,53,58,63,68,73,78,83,88,93,97},{42,47,52,57,62,67,72,77,82,87,92,99,100}),999) -> 72 | AA7: =Y7/(VLOOKUP(E7,$C$2:$I$5,2,FALSE)) -> 1.5646259 | AB7: =IFERROR(IF(I7="AI",AA7-VLOOKUP(Q7,'PBT Tag Rates'!$A$6:$L$53,11,FALSE),AA7-VLOOKUP(Q7,'PBT Tag Rates'!$A$6:$L$53,12,FALSE)),0) -> 1.5763046 | AC7: =AB7/(VLOOKUP(E7,$C$2:$I$5,7,FALSE)) -> 15.939416 | AD7: Abv | AH7: Jack fallback/reascension rate was corrected on 10/20/2026
A8: OtsLGRF24S | B8: OtsLGRF24S_0015 | C8: C-00015 | D8: 45522 | E8: =IF(AND(D8>=$F$2,D8<$F$3),70,IF(AND(D8>=$F$3,D8<$F$4),40,IF(AND(D8>=$F$4,D8<$F$5),18,9))) -> 70 | F8: F | G8: 690 | H8: =G8/10 -> 69 | I8: AD | J8: 1 | K8: NA | L8: NA | M8: F | N8: =IF(M8="U",F8,M8) -> F | O8: OtsLYON20S_1_0297 | P8: OtsLYON20S_1_1059 | Q8: OtsLYON20S_1 | R8: 4 | S8: =IFERROR($S$4-R8,"U") -> 2020 | T8: FALL | U8: 1 | V8: CJA1 | W8: =VLOOKUP(Q8,'PBT Tag Rates'!$A$6:$D$67,4,FALSE) -> 0.98961046 | X8: 1 | Y8: =IF(V8="ng",0,X8+(SUMIFS($AK$24:$AK$127,$AG$24:$AG$127,$N8,$AH$24:$AH$127,$Z8,$AF$24:$AF$127,$E8))) -> 1.0666667 | Z8: =IFERROR(LOOKUP(H8,{30,43,48,53,58,63,68,73,78,83,88,93,97},{42,47,52,57,62,67,72,77,82,87,92,99,100}),999) -> 72 | AA8: =Y8/(VLOOKUP(E8,$C$2:$I$5,2,FALSE)) -> 1.5238095 | AB8: =IFERROR(IF(I8="AI",AA8-VLOOKUP(Q8,'PBT Tag Rates'!$A$6:$L$53,11,FALSE),AA8-VLOOKUP(Q8,'PBT Tag Rates'!$A$6:$L$53,12,FALSE)),0) -> 1.5343081 | AC8: =AB8/(VLOOKUP(E8,$C$2:$I$5,7,FALSE)) -> 15.514752 | AD8: Abv | AH8: it was 0.026, not .026
A9: OtsLGRF24S | B9: OtsLGRF24S_0025 | C9: C-00025 | D9: 45522 | E9: =IF(AND(D9>=$F$2,D9<$F$3),70,IF(AND(D9>=$F$3,D9<$F$4),40,IF(AND(D9>=$F$4,D9<$F$5),18,9))) -> 70 | F9: M | G9: 740 | H9: =G9/10 -> 74 | I9: AI | J9: NA | K9: 3DD.0078C316E3 | L9: NA | M9: M | N9: =IF(M9="U",F9,M9) -> M | O9: OtsLYON20S_1_0254 | P9: OtsLYON20S_1_0133 | Q9: OtsLYON20S_1 | R9: 4 | S9: =IFERROR($S$4-R9,"U") -> 2020 | T9: FALL | U9: 1 | V9: BCA1 | W9: =VLOOKUP(Q9,'PBT Tag Rates'!$A$6:$D$67,4,FALSE) -> 0.98961046 | X9: 1 | Y9: =IF(V9="ng",0,X9+(SUMIFS($AK$24:$AK$127,$AG$24:$AG$127,$N9,$AH$24:$AH$127,$Z9,$AF$24:$AF$127,$E9))) -> 1.0555556 | Z9: =IFERROR(LOOKUP(H9,{30,43,48,53,58,63,68,73,78,83,88,93,97},{42,47,52,57,62,67,72,77,82,87,92,99,100}),999) -> 77 | AA9: =Y9/(VLOOKUP(E9,$C$2:$I$5,2,FALSE)) -> 1.5079365 | AB9: =IFERROR(IF(I9="AI",AA9-VLOOKUP(Q9,'PBT Tag Rates'!$A$6:$L$53,11,FALSE),AA9-VLOOKUP(Q9,'PBT Tag Rates'!$A$6:$L$53,12,FALSE)),0) -> 1.5184351 | AC9: =AB9/(VLOOKUP(E9,$C$2:$I$5,7,FALSE)) -> 15.354246 | AD9: Abv
A10: OtsLGRF24S | B10: OtsLGRF24S_0035 | C10: C-00035 | D10: 45522 | E10: =IF(AND(D10>=$F$2,D10<$F$3),70,IF(AND(D10>=$F$3,D10<$F$4),40,IF(AND(D10>=$F$4,D10<$F$5),18,9))) -> 70 | F10: M | G10: 700 | H10: =G10/10 -> 70 | I10: AD | J10: 1 | K10: 3DD.0078C2F0EE | L10: NA | M10: M | N10: =IF(M10="U",F10,M10) -> M | O10: OtsLYON20S_1_1446 | P10: OtsLYON20S_1_1240 | Q10: OtsLYON20S_1 | R10: 4 | S10: =IFERROR($S$4-R10,"U") -> 2020 | T10: FALL | U10: 1 | V10: LFYO | W10: =VLOOKUP(Q10,'PBT Tag Rates'!$A$6:$D$67,4,FALSE) -> 0.98961046 | X10: 1 | Y10: =IF(V10="ng",0,X10+(SUMIFS($AK$24:$AK$127,$AG$24:$AG$127,$N10,$AH$24:$AH$127,$Z10,$AF$24:$AF$127,$E10))) -> 1.0952381 | Z10: =IFERROR(LOOKUP(H10,{30,43,48,53,58,63,68,73,78,83,88,93,97},{42,47,52,57,62,67,72,77,82,87,92,99,100}),999) -> 72 | AA10: =Y10/(VLOOKUP(E10,$C$2:$I$5,2,FALSE)) -> 1.5646259 | AB10: =IFERROR(IF(I10="AI",AA10-VLOOKUP(Q10,'PBT Tag Rates'!$A$6:$L$53,11,FALSE),AA10-VLOOKUP(Q10,'PBT Tag Rates'!$A$6:$L$53,12,FALSE)),0) -> 1.5751245 | AC10: =AB10/(VLOOKUP(E10,$C$2:$I$5,7,FALSE)) -> 15.927482 | AD10: blw
A11: OtsLGRF24S | B11: OtsLGRF24S_0045 | C11: C-00045 | D11: 45522 | E11: =IF(AND(D11>=$F$2,D11<$F$3),70,IF(AND(D11>=$F$3,D11<$F$4),40,IF(AND(D11>=$F$4,D11<$F$5),18,9))) -> 70 | F11: M | G11: 470 | H11: =G11/10 -> 47 | I11: AI | J11: NA | K11: NA | L11: NA | M11: M | N11: =IF(M11="U",F11,M11) -> M | O11: OtsLYON22S_1_0434 | P11: OtsLYON22S_1_4222 | Q11: OtsLYON22S_1 | R11: 2 | S11: =IFERROR($S$4-R11,"U") -> 2022 | T11: FALL | U11: 1 | V11: IPCSR | W11: =VLOOKUP(Q11,'PBT Tag Rates'!$A$6:$D$67,4,FALSE) -> 0.98 | X11: 1 | Y11: =IF(V11="ng",0,X11+(SUMIFS($AK$24:$AK$127,$AG$24:$AG$127,$N11,$AH$24:$AH$127,$Z11,$AF$24:$AF$127,$E11))) -> 1 | Z11: =IFERROR(LOOKUP(H11,{30,43,48,53,58,63,68,73,78,83,88,93,97},{42,47,52,57,62,67,72,77,82,87,92,99,100}),999) -> 47 | AA11: =Y11/(VLOOKUP(E11,$C$2:$I$5,2,FALSE)) -> 1.4285714 | AB11: =IFERROR(IF(I11="AI",AA11-VLOOKUP(Q11,'PBT Tag Rates'!$A$6:$L$53,11,FALSE),AA11-VLOOKUP(Q11,'PBT Tag Rates'!$A$6:$L$53,12,FALSE)),0) -> 1.4489796 | AC11: =AB11/(VLOOKUP(E11,$C$2:$I$5,7,FALSE)) -> 14.65192 | AD11: Abv
A12: OtsLGRF24S | B12: OtsLGRF24S_0055 | C12: C-00055 | D12: 45522 | E12: =IF(AND(D12>=$F$2,D12<$F$3),70,IF(AND(D12>=$F$3,D12<$F$4),40,IF(AND(D12>=$F$4,D12<$F$5),18,9))) -> 70 | F12: F | G12: 850 | H12: =G12/10 -> 85 | I12: AI | J12: NA | K12: 3DD.003D7E4642 | L12: NA | M12: F | N12: =IF(M12="U",F12,M12) -> F | O12: NA | P12: NA | Q12: Unassigned | R12: NA | S12: =IFERROR($S$4-R12,"U") -> U | T12: FALL | U12: 1 | V12: NA | W12: =VLOOKUP(Q12,'PBT Tag Rates'!$A$6:$D$67,4,FALSE) -> 1 | X12: 1 | Y12: =IF(V12="ng",0,X12+(SUMIFS($AK$24:$AK$127,$AG$24:$AG$127,$N12,$AH$24:$AH$127,$Z12,$AF$24:$AF$127,$E12))) -> 1 | Z12: =IFERROR(LOOKUP(H12,{30,43,48,53,58,63,68,73,78,83,88,93,97},{42,47,52,57,62,67,72,77,82,87,92,99,100}),999) -> 87 | AA12: =Y12/(VLOOKUP(E12,$C$2:$I$5,2,FALSE)) -> 1.4285714 | AB12: =IFERROR(IF(I12="AI",AA12-VLOOKUP(Q12,'PBT Tag Rates'!$A$6:$L$53,11,FALSE),AA12-VLOOKUP(Q12,'PBT Tag Rates'!$A$6:$L$53,12,FALSE)),0) -> 1.3872683 | AC12: =AB12/(VLOOKUP(E12,$C$2:$I$5,7,FALSE)) -> 14.027902 | AD12: Abv
A13: OtsLGRF24S | B13: OtsLGRF24S_0065 | C13: C-00065 | D13: 45522 | E13: =IF(AND(D13>=$F$2,D13<$F$3),70,IF(AND(D13>=$F$3,D13<$F$4),40,IF(AND(D13>=$F$4,D13<$F$5),18,9))) -> 70 | F13: M | G13: 460 | H13: =G13/10 -> 46 | I13: AD | J13: 1 | K13: NA | L13: NA | M13: M | N13: =IF(M13="U",F13,M13) -> M | O13: OtsLYON22S_1_0238 | P13: OtsLYON22S_1_3238 | Q13: OtsLYON22S_1 | R13: 2 | S13: =IFERROR($S$4-R13,"U") -> 2022 | T13: FALL | U13: 1 | V13: CJA2 | W13: =VLOOKUP(Q13,'PBT Tag Rates'!$A$6:$D$67,4,FALSE) -> 0.98 | X13: 1 | Y13: =IF(V13="ng",0,X13+(SUMIFS($AK$24:$AK$127,$AG$24:$AG$127,$N13,$AH$24:$AH$127,$Z13,$AF$24:$AF$127,$E13))) -> 1 | Z13: =IFERROR(LOOKUP(H13,{30,43,48,53,58,63,68,73,78,83,88,93,97},{42,47,52,57,62,67,72,77,82,87,92,99,100}),999) -> 47 | AA13: =Y13/(VLOOKUP(E13,$C$2:$I$5,2,FALSE)) -> 1.4285714 | AB13: =IFERROR(IF(I13="AI",AA13-VLOOKUP(Q13,'PBT Tag Rates'!$A$6:$L$53,11,FALSE),AA13-VLOOKUP(Q13,'PBT Tag Rates'!$A$6:$L$53,12,FALSE)),0) -> 1.4489796 | AC13: =AB13/(VLOOKUP(E13,$C$2:$I$5,7,FALSE)) -> 14.65192 | AD13: Abv
A14: OtsLGRF24S | B14: OtsLGRF24S_0075 | C14: C-00075 | D14: 45522 | E14: =IF(AND(D14>=$F$2,D14<$F$3),70,IF(AND(D14>=$F$3,D14<$F$4),40,IF(AND(D14>=$F$4,D14<$F$5),18,9))) -> 70 | F14: M | G14: 820 | H14: =G14/10 -> 82 | I14: AI | J14: NA | K14: 3DD.0078C2F124 | L14: NA | M14: M | N14: =IF(M14="U",F14,M14) -> M | O14: NA | P14: NA | Q14: Unassigned | R14: NA | S14: =IFERROR($S$4-R14,"U") -> U | T14: FALL | U14: 1 | V14: NA | W14: =VLOOKUP(Q14,'PBT Tag Rates'!$A$6:$D$67,4,FALSE) -> 1 | X14: 1 | Y14: =IF(V14="ng",0,X14+(SUMIFS($AK$24:$AK$127,$AG$24:$AG$127,$N14,$AH$24:$AH$127,$Z14,$AF$24:$AF$127,$E14))) -> 1.025 | Z14: =IFERROR(LOOKUP(H14,{30,43,48,53,58,63,68,73,78,83,88,93,97},{42,47,52,57,62,67,72,77,82,87,92,99,100}),999) -> 82 | AA14: =Y14/(VLOOKUP(E14,$C$2:$I$5,2,FALSE)) -> 1.4642857 | AB14: =IFERROR(IF(I14="AI",AA14-VLOOKUP(Q14,'PBT Tag Rates'!$A$6:$L$53,11,FALSE),AA14-VLOOKUP(Q14,'PBT Tag Rates'!$A$6:$L$53,12,FALSE)),0) -> 1.4229826 | AC14: =AB14/(VLOOKUP(E14,$C$2:$I$5,7,FALSE)) -> 14.389041 | AD14: Abv
A15: OtsLGRF24S | B15: OtsLGRF24S_0085 | C15: C-00085 | D15: 45522 | E15: =IF(AND(D15>=$F$2,D15<$F$3),70,IF(AND(D15>=$F$3,D15<$F$4),40,IF(AND(D15>=$F$4,D15<$F$5),18,9))) -> 70 | F15: F | G15: 790 | H15: =G15/10 -> 79 | I15: AD | J15: 1 | K15: 3DD.0078C2F106 | L15: NA | M15: F | N15: =IF(M15="U",F15,M15) -> F | O15: OtsNPFH19S_1_3349 | P15: OtsNPFH19S_1_3107 | Q15: OtsNPFH19S_1 | R15: 5 | S15: =IFERROR($S$4-R15,"U") -> 2019 | T15: FALL | U15: 1 | V15: NLVA | W15: =VLOOKUP(Q15,'PBT Tag Rates'!$A$6:$D$67,4,FALSE) -> 0.99705232 | X15: 1 | Y15: =IF(V15="ng",0,X15+(SUMIFS($AK$24:$AK$127,$AG$24:$AG$127,$N15,$AH$24:$AH$127,$Z15,$AF$24:$AF$127,$E15))) -> 1.137931 | Z15: =IFERROR(LOOKUP(H15,{30,43,48,53,58,63,68,73,78,83,88,93,97},{42,47,52,57,62,67,72,77,82,87,92,99,100}),999) -> 82 | AA15: =Y15/(VLOOKUP(E15,$C$2:$I$5,2,FALSE)) -> 1.6256158 | AB15: =IFERROR(IF(I15="AI",AA15-VLOOKUP(Q15,'PBT Tag Rates'!$A$6:$L$53,11,FALSE),AA15-VLOOKUP(Q15,'PBT Tag Rates'!$A$6:$L$53,12,FALSE)),0) -> 1.6285722 | AC15: =AB15/(VLOOKUP(E15,$C$2:$I$5,7,FALSE)) -> 16.467939 | AD15: Abv
A16: OtsLGRF24S | B16: OtsLGRF24S_0095 | C16: C-00095 | D16: 45522 | E16: =IF(AND(D16>=$F$2,D16<$F$3),70,IF(AND(D16>=$F$3,D16<$F$4),40,IF(AND(D16>=$F$4,D16<$F$5),18,9))) -> 70 | F16: M | G16: 770 | H16: =G16/10 -> 77 | I16: AI | J16: NA | K16: 3DD.0078C31720 | L16: NA | M16: M | N16: =IF(M16="U",F16,M16) -> M | O16: OtsNPFH20S_1_0364 | P16: OtsNPFH20S_1_0329 | Q16: OtsNPFH20S_1 | R16: 4 | S16: =IFERROR($S$4-R16,"U") -> 2020 | T16: FALL | U16: 1 | V16: CFA | W16: =VLOOKUP(Q16,'PBT Tag Rates'!$A$6:$D$67,4,FALSE) -> 0.98845609 | X16: 1 | Y16: =IF(V16="ng",0,X16+(SUMIFS($AK$24:$AK$127,$AG$24:$AG$127,$N16,$AH$24:$AH$127,$Z16,$AF$24:$AF$127,$E16))) -> 1.0555556 | Z16: =IFERROR(LOOKUP(H16,{30,43,48,53,58,63,68,73,78,83,88,93,97},{42,47,52,57,62,67,72,77,82,87,92,99,100}),999) -> 77 | AA16: =Y16/(VLOOKUP(E16,$C$2:$I$5,2,FALSE)) -> 1.5079365 | AB16: =IFERROR(IF(I16="AI",AA16-VLOOKUP(Q16,'PBT Tag Rates'!$A$6:$L$53,11,FALSE),AA16-VLOOKUP(Q16,'PBT Tag Rates'!$A$6:$L$53,12,FALSE)),0) -> 1.5196152 | AC16: =AB16/(VLOOKUP(E16,$C$2:$I$5,7,FALSE)) -> 15.366179 | AD16: Abv
A17: OtsLGRF24S | B17: OtsLGRF24S_0105 | C17: C-00105 | D17: 45522 | E17: =IF(AND(D17>=$F$2,D17<$F$3),70,IF(AND(D17>=$F$3,D17<$F$4),40,IF(AND(D17>=$F$4,D17<$F$5),18,9))) -> 70 | F17: M | G17: 700 | H17: =G17/10 -> 70 | I17: AD | J17: 1 | K17: 3DD.0078C316BF | L17: NA | M17: M | N17: =IF(M17="U",F17,M17) -> M | O17: OtsLYON20S_1_1331 | P17: OtsLYON20S_1_0868 | Q17: OtsLYON20S_1 | R17: 4 | S17: =IFERROR($S$4-R17,"U") -> 2020 | T17: FALL | U17: 1 | V17: PLA2 | W17: =VLOOKUP(Q17,'PBT Tag Rates'!$A$6:$D$67,4,FALSE) -> 0.98961046 | X17: 1 | Y17: =IF(V17="ng",0,X17+(SUMIFS($AK$24:$AK$127,$AG$24:$AG$127,$N17,$AH$24:$AH$127,$Z17,$AF$24:$AF$127,$E17))) -> 1.0952381 | Z17: =IFERROR(LOOKUP(H17,{30,43,48,53,58,63,68,73,78,83,88,93,97},{42,47,52,57,62,67,72,77,82,87,92,99,100}),999) -> 72 | AA17: =Y17/(VLOOKUP(E17,$C$2:$I$5,2,FALSE)) -> 1.5646259 | AB17: =IFERROR(IF(I17="AI",AA17-VLOOKUP(Q17,'PBT Tag Rates'!$A$6:$L$53,11,FALSE),AA17-VLOOKUP(Q17,'PBT Tag Rates'!$A$6:$L$53,12,FALSE)),0) -> 1.5751245 | AC17: =AB17/(VLOOKUP(E17,$C$2:$I$5,7,FALSE)) -> 15.927482 | AD17: Abv
A18: OtsLGRF24S | B18: OtsLGRF24S_0115 | C18: C-00115 | D18: 45522 | E18: =IF(AND(D18>=$F$2,D18<$F$3),70,IF(AND(D18>=$F$3,D18<$F$4),40,IF(AND(D18>=$F$4,D18<$F$5),18,9))) -> 70 | F18: M | G18: 720 | H18: =G18/10 -> 72 | I18: AI | J18: NA | K18: 3DD.0078C31715 | L18: NA | M18: M | N18: =IF(M18="U",F18,M18) -> M | O18: NA | P18: NA | Q18: Unassigned | R18: NA | S18: =IFERROR($S$4-R18,"U") -> U | T18: FALL | U18: 1 | V18: NA | W18: =VLOOKUP(Q18,'PBT Tag Rates'!$A$6:$D$67,4,FALSE) -> 1 | X18: 1 | Y18: =IF(V18="ng",0,X18+(SUMIFS($AK$24:$AK$127,$AG$24:$AG$127,$N18,$AH$24:$AH$127,$Z18,$AF$24:$AF$127,$E18))) -> 1.0952381 | Z18: =IFERROR(LOOKUP(H18,{30,43,48,53,58,63,68,73,78,83,88,93,97},{42,47,52,57,62,67,72,77,82,87,92,99,100}),999) -> 72 | AA18: =Y18/(VLOOKUP(E18,$C$2:$I$5,2,FALSE)) -> 1.5646259 | AB18: =IFERROR(IF(I18="AI",AA18-VLOOKUP(Q18,'PBT Tag Rates'!$A$6:$L$53,11,FALSE),AA18-VLOOKUP(Q18,'PBT Tag Rates'!$A$6:$L$53,12,FALSE)),0) -> 1.5233227 | AC18: =AB18/(VLOOKUP(E18,$C$2:$I$5,7,FALSE)) -> 15.403669 | AD18: Abv
A19: OtsLGRF24S | B19: OtsLGRF24S_0125 | C19: C-00125 | D19: 45522 | E19: =IF(AND(D19>=$F$2,D19<$F$3),70,IF(AND(D19>=$F$3,D19<$F$4),40,IF(AND(D19>=$F$4,D19<$F$5),18,9))) -> 70 | F19: M | G19: 830 | H19: =G19/10 -> 83 | I19: AI | J19: NA | K19: 3DD.0078C316C7 | L19: NA | M19: M | N19: =IF(M19="U",F19,M19) -> M | O19: OtsLYON20S_1_0284 | P19: OtsLYON20S_1_1044 | Q19: OtsLYON20S_1 | R19: 4 | S19: =IFERROR($S$4-R19,"U") -> 2020 | T19: FALL | U19: 1 | V19: CJA1 | W19: =VLOOKUP(Q19,'PBT Tag Rates'!$A$6:$D$67,4,FALSE) -> 0.98961046 | X19: 1 | Y19: =IF(V19="ng",0,X19+(SUMIFS($AK$24:$AK$127,$AG$24:$AG$127,$N19,$AH$24:$AH$127,$Z19,$AF$24:$AF$127,$E19))) -> 1 | Z19: =IFERROR(LOOKUP(H19,{30,43,48,53,58,63,68,73,78,83,88,93,97},{42,47,52,57,62,67,72,77,82,87,92,99,100}),999) -> 87 | AA19: =Y19/(VLOOKUP(E19,$C$2:$I$5,2,FALSE)) -> 1.4285714 | AB19: =IFERROR(IF(I19="AI",AA19-VLOOKUP(Q19,'PBT Tag Rates'!$A$6:$L$53,11,FALSE),AA19-VLOOKUP(Q19,'PBT Tag Rates'!$A$6:$L$53,12,FALSE)),0) -> 1.43907 | AC19: =AB19/(VLOOKUP(E19,$C$2:$I$5,7,FALSE)) -> 14.551715 | AD19: Abv
A20: OtsLGRF24S | B20: OtsLGRF24S_0135 | C20: C-00135 | D20: 45522 | E20: =IF(AND(D20>=$F$2,D20<$F$3),70,IF(AND(D20>=$F$3,D20<$F$4),40,IF(AND(D20>=$F$4,D20<$F$5),18,9))) -> 70 | F20: F | G20: 780 | H20: =G20/10 -> 78 | I20: AD | J20: NA | K20: 3DD.0078C316FF | L20: NA | M20: F | N20: =IF(M20="U",F20,M20) -> F | O20: OtsLYON19S_1_1317 | P20: OtsLYON19S_1_1233 | Q20: OtsLYON19S_1 | R20: 5 | S20: =IFERROR($S$4-R20,"U") -> 2019 | T20: FALL | U20: 1 | V20: CJA2 | W20: =VLOOKUP(Q20,'PBT Tag Rates'!$A$6:$D$67,4,FALSE) -> 0.95971981 | X20: 1 | Y20: =IF(V20="ng",0,X20+(SUMIFS($AK$24:$AK$127,$AG$24:$AG$127,$N20,$AH$24:$AH$127,$Z20,$AF$24:$AF$127,$E20))) -> 1.137931 | Z20: =IFERROR(LOOKUP(H20,{30,43,48,53,58,63,68,73,78,83,88,93,97},{42,47,52,57,62,67,72,77,82,87,92,99,100}),999) -> 82 | AA20: =Y20/(VLOOKUP(E20,$C$2:$I$5,2,FALSE)) -> 1.6256158 | AB20: =IFERROR(IF(I20="AI",AA20-VLOOKUP(Q20,'PBT Tag Rates'!$A$6:$L$53,11,FALSE),AA20-VLOOKUP(Q20,'PBT Tag Rates'!$A$6:$L$53,12,FALSE)),0) -> 1.6675865 | AC20: =AB20/(VLOOKUP(E20,$C$2:$I$5,7,FALSE)) -> 16.862449 | AD20: Abv
A21: OtsLGRF24S | B21: OtsLGRF24S_0145 | C21: C-00145 | D21: 45522 | E21: =IF(AND(D21>=$F$2,D21<$F$3),70,IF(AND(D21>=$F$3,D21<$F$4),40,IF(AND(D21>=$F$4,D21<$F$5),18,9))) -> 70 | F21: F | G21: 820 | H21: =G21/10 -> 82 | I21: AI | J21: NA | K21: 3DD.0078C3171C | L21: NA | M21: F | N21: =IF(M21="U",F21,M21) -> F | O21: NA | P21: NA | Q21: Unassigned | R21: NA | S21: =IFERROR($S$4-R21,"U") -> U | T21: FALL | U21: 1 | V21: NA | W21: =VLOOKUP(Q21,'PBT Tag Rates'!$A$6:$D$67,4,FALSE) -> 1 | X21: 1 | Y21: =IF(V21="ng",0,X21+(SUMIFS($AK$24:$AK$127,$AG$24:$AG$127,$N21,$AH$24:$AH$127,$Z21,$AF$24:$AF$127,$E21))) -> 1.137931 | Z21: =IFERROR(LOOKUP(H21,{30,43,48,53,58,63,68,73,78,83,88,93,97},{42,47,52,57,62,67,72,77,82,87,92,99,100}),999) -> 82 | AA21: =Y21/(VLOOKUP(E21,$C$2:$I$5,2,FALSE)) -> 1.6256158 | AB21: =IFERROR(IF(I21="AI",AA21-VLOOKUP(Q21,'PBT Tag Rates'!$A$6:$L$53,11,FALSE),AA21-VLOOKUP(Q21,'PBT Tag Rates'!$A$6:$L$53,12,FALSE)),0) -> 1.5843126 | AC21: =AB21/(VLOOKUP(E21,$C$2:$I$5,7,FALSE)) -> 16.020392 | AD21: Abv | AF21: NG proportion table
A22: OtsLGRF24S | B22: OtsLGRF24S_0155 | C22: C-00155 | D22: 45522 | E22: =IF(AND(D22>=$F$2,D22<$F$3),70,IF(AND(D22>=$F$3,D22<$F$4),40,IF(AND(D22>=$F$4,D22<$F$5),18,9))) -> 70 | F22: F | G22: 830 | H22: =G22/10 -> 83 | I22: AI | J22: NA | K22: 3DD.0078C316E1 | L22: NA | M22: F | N22: =IF(M22="U",F22,M22) -> F | O22: NA | P22: NA | Q22: Unassigned | R22: NA | S22: =IFERROR($S$4-R22,"U") -> U | T22: FALL | U22: 1 | V22: NA | W22: =VLOOKUP(Q22,'PBT Tag Rates'!$A$6:$D$67,4,FALSE) -> 1 | X22: 1 | Y22: =IF(V22="ng",0,X22+(SUMIFS($AK$24:$AK$127,$AG$24:$AG$127,$N22,$AH$24:$AH$127,$Z22,$AF$24:$AF$127,$E22))) -> 1 | Z22: =IFERROR(LOOKUP(H22,{30,43,48,53,58,63,68,73,78,83,88,93,97},{42,47,52,57,62,67,72,77,82,87,92,99,100}),999) -> 87 | AA22: =Y22/(VLOOKUP(E22,$C$2:$I$5,2,FALSE)) -> 1.4285714 | AB22: =IFERROR(IF(I22="AI",AA22-VLOOKUP(Q22,'PBT Tag Rates'!$A$6:$L$53,11,FALSE),AA22-VLOOKUP(Q22,'PBT Tag Rates'!$A$6:$L$53,12,FALSE)),0) -> 1.3872683 | AC22: =AB22/(VLOOKUP(E22,$C$2:$I$5,7,FALSE)) -> 14.027902 | AD22: Abv | AI22: =SUM(AI24:AI127) -> 36 | AJ22: =SUM(AJ24:AJ127) -> 2558 | AK22: =SUM(AK24:AK127) -> 2.0599976 | AM22: =SUM(AM24:AM127) -> 36
A23: OtsLGRF24S | B23: OtsLGRF24S_0165 | C23: C-00165 | D23: 45522 | E23: =IF(AND(D23>=$F$2,D23<$F$3),70,IF(AND(D23>=$F$3,D23<$F$4),40,IF(AND(D23>=$F$4,D23<$F$5),18,9))) -> 70 | F23: M | G23: 840 | H23: =G23/10 -> 84 | I23: AD | J23: NA | K23: 3DD.0078C31718 | L23: NA | M23: M | N23: =IF(M23="U",F23,M23) -> M | O23: OtsLYON19S_1_0560 | P23: OtsLYON19S_1_0462 | Q23: OtsLYON19S_1 | R23: 5 | S23: =IFERROR($S$4-R23,"U") -> 2019 | T23: FALL | U23: 1 | V23: LFSO | W23: =VLOOKUP(Q23,'PBT Tag Rates'!$A$6:$D$67,4,FALSE) -> 0.95971981 | X23: 1 | Y23: =IF(V23="ng",0,X23+(SUMIFS($AK$24:$AK$127,$AG$24:$AG$127,$N23,$AH$24:$AH$127,$Z23,$AF$24:$AF$127,$E23))) -> 1 | Z23: =IFERROR(LOOKUP(H23,{30,43,48,53,58,63,68,73,78,83,88,93,97},{42,47,52,57,62,67,72,77,82,87,92,99,100}),999) -> 87 | AA23: =Y23/(VLOOKUP(E23,$C$2:$I$5,2,FALSE)) -> 1.4285714 | AB23: =IFERROR(IF(I23="AI",AA23-VLOOKUP(Q23,'PBT Tag Rates'!$A$6:$L$53,11,FALSE),AA23-VLOOKUP(Q23,'PBT Tag Rates'!$A$6:$L$53,12,FALSE)),0) -> 1.4705422 | AC23: =AB23/(VLOOKUP(E23,$C$2:$I$5,7,FALSE)) -> 14.869958 | AD23: Abv | AI23: NG | AJ23: total | AK23: Prop NG | AM23: sum NG
A24: OtsLGRF24S | B24: OtsLGRF24S_0175 | C24: C-00175 | D24: 45522 | E24: =IF(AND(D24>=$F$2,D24<$F$3),70,IF(AND(D24>=$F$3,D24<$F$4),40,IF(AND(D24>=$F$4,D24<$F$5),18,9))) -> 70 | F24: M | G24: 690 | H24: =G24/10 -> 69 | I24: AI | J24: NA | K24: NA | L24: NA | M24: M | N24: =IF(M24="U",F24,M24) -> M | O24: OtsLYON21S_1_0796 | P24: OtsLYON21S_1_1611 | Q24: OtsLYON21S_1 | R24: 3 | S24: =IFERROR($S$4-R24,"U") -> 2021 | T24: FALL | U24: 1 | V24: LFSO | W24: =VLOOKUP(Q24,'PBT Tag Rates'!$A$6:$D$67,4,FALSE) -> 0.9814 | X24: 1 | Y24: =IF(V24="ng",0,X24+(SUMIFS($AK$24:$AK$127,$AG$24:$AG$127,$N24,$AH$24:$AH$127,$Z24,$AF$24:$AF$127,$E24))) -> 1.0952381 | Z24: =IFERROR(LOOKUP(H24,{30,43,48,53,58,63,68,73,78,83,88,93,97},{42,47,52,57,62,67,72,77,82,87,92,99,100}),999) -> 72 | AA24: =Y24/(VLOOKUP(E24,$C$2:$I$5,2,FALSE)) -> 1.5646259 | AB24: =IFERROR(IF(I24="AI",AA24-VLOOKUP(Q24,'PBT Tag Rates'!$A$6:$L$53,11,FALSE),AA24-VLOOKUP(Q24,'PBT Tag Rates'!$A$6:$L$53,12,FALSE)),0) -> 1.5835784 | AC24: =AB24/(VLOOKUP(E24,$C$2:$I$5,7,FALSE)) -> 16.012967 | AD24: Abv | AF24: 18 | AG24: F | AH24: 42 | AI24: =SUMIFS($X$7:$X$5545,$Z$7:$Z$5545,$AH24,$N$6:$N$5544,$AG24,$E$6:$E$5544,$AF24,$V$7:$V$5545,"NG") -> 0 | AJ24: =(SUMIFS($X$7:$X$5545,$Z$7:$Z$5545,$AH24,$N$6:$N$5544,$AG24,$E$6:$E$5544,$AF24)) -> 21 | AK24: =IFERROR(AI24/AJ24,0) -> 0 | AM24: =AJ24*AK24 -> 0
A25: OtsLGRF24S | B25: OtsLGRF24S_0185 | C25: C-00185 | D25: 45522 | E25: =IF(AND(D25>=$F$2,D25<$F$3),70,IF(AND(D25>=$F$3,D25<$F$4),40,IF(AND(D25>=$F$4,D25<$F$5),18,9))) -> 70 | F25: F | G25: 730 | H25: =G25/10 -> 73 | I25: AI | J25: NA | K25: 3DD.0078C2F137 | L25: NA | M25: F | N25: =IF(M25="U",F25,M25) -> F | O25: OtsLYON19S_1_0519 | P25: OtsLYON19S_1_0331 | Q25: OtsLYON19S_1 | R25: 5 | S25: =IFERROR($S$4-R25,"U") -> 2019 | T25: FALL | U25: 1 | V25: BCA1 | W25: =VLOOKUP(Q25,'PBT Tag Rates'!$A$6:$D$67,4,FALSE) -> 0.95971981 | X25: 1 | Y25: =IF(V25="ng",0,X25+(SUMIFS($AK$24:$AK$127,$AG$24:$AG$127,$N25,$AH$24:$AH$127,$Z25,$AF$24:$AF$127,$E25))) -> 1.1428571 | Z25: =IFERROR(LOOKUP(H25,{30,43,48,53,58,63,68,73,78,83,88,93,97},{42,47,52,57,62,67,72,77,82,87,92,99,100}),999) -> 77 | AA25: =Y25/(VLOOKUP(E25,$C$2:$I$5,2,FALSE)) -> 1.6326531 | AB25: =IFERROR(IF(I25="AI",AA25-VLOOKUP(Q25,'PBT Tag Rates'!$A$6:$L$53,11,FALSE),AA25-VLOOKUP(Q25,'PBT Tag Rates'!$A$6:$L$53,12,FALSE)),0) -> 1.6746238 | AC25: =AB25/(VLOOKUP(E25,$C$2:$I$5,7,FALSE)) -> 16.933609 | AD25: Abv | AF25: 18 | AG25: F | AH25: 47 | AI25: =SUMIFS($X$7:$X$5545,$Z$7:$Z$5545,$AH25,$N$6:$N$5544,$AG25,$E$6:$E$5544,$AF25,$V$7:$V$5545,"NG") -> 0 | AJ25: =(SUMIFS($X$7:$X$5545,$Z$7:$Z$5545,$AH25,$N$6:$N$5544,$AG25,$E$6:$E$5544,$AF25)) -> 33 | AK25: =IFERROR(AI25/AJ25,0) -> 0 | AM25: =AJ25*AK25 -> 0
A26: OtsLGRF24S | B26: OtsLGRF24S_0195 | C26: C-00195 | D26: 45522 | E26: =IF(AND(D26>=$F$2,D26<$F$3),70,IF(AND(D26>=$F$3,D26<$F$4),40,IF(AND(D26>=$F$4,D26<$F$5),18,9))) -> 70 | F26: M | G26: 730 | H26: =G26/10 -> 73 | I26: AI | J26: NA | K26: 3DD.0078C2F10B | L26: NA | M26: M | N26: =IF(M26="U",F26,M26) -> M | O26: OtsLYON20S_1_0248 | P26: OtsLYON20S_1_0093 | Q26: OtsLYON20S_1 | R26: 4 | S26: =IFERROR($S$4-R26,"U") -> 2020 | T26: FALL | U26: 1 | V26: PLA1 | W26: =VLOOKUP(Q26,'PBT Tag Rates'!$A$6:$D$67,4,FALSE) -> 0.98961046 | X26: 1 | Y26: =IF(V26="ng",0,X26+(SUMIFS($AK$24:$AK$127,$AG$24:$AG$127,$N26,$AH$24:$AH$127,$Z26,$AF$24:$AF$127,$E26))) -> 1.0555556 | Z26: =IFERROR(LOOKUP(H26,{30,43,48,53,58,63,68,73,78,83,88,93,97},{42,47,52,57,62,67,72,77,82,87,92,99,100}),999) -> 77 | AA26: =Y26/(VLOOKUP(E26,$C$2:$I$5,2,FALSE)) -> 1.5079365 | AB26: =IFERROR(IF(I26="AI",AA26-VLOOKUP(Q26,'PBT Tag Rates'!$A$6:$L$53,11,FALSE),AA26-VLOOKUP(Q26,'PBT Tag Rates'!$A$6:$L$53,12,FALSE)),0) -> 1.5184351 | AC26: =AB26/(VLOOKUP(E26,$C$2:$I$5,7,FALSE)) -> 15.354246 | AD26: Abv | AF26: 18 | AG26: F | AH26: 52 | AI26: =SUMIFS($X$7:$X$5545,$Z$7:$Z$5545,$AH26,$N$6:$N$5544,$AG26,$E$6:$E$5544,$AF26,$V$7:$V$5545,"NG") -> 0 | AJ26: =(SUMIFS($X$7:$X$5545,$Z$7:$Z$5545,$AH26,$N$6:$N$5544,$AG26,$E$6:$E$5544,$AF26)) -> 39 | AK26: =IFERROR(AI26/AJ26,0) -> 0 | AM26: =AJ26*AK26 -> 0
A27: OtsLGRF24S | B27: OtsLGRF24S_0205 | C27: C-00205 | D27: 45522 | E27: =IF(AND(D27>=$F$2,D27<$F$3),70,IF(AND(D27>=$F$3,D27<$F$4),40,IF(AND(D27>=$F$4,D27<$F$5),18,9))) -> 70 | F27: F | G27: 770 | H27: =G27/10 -> 77 | I27: AI | J27: NA | K27: 3DD.0078C2F127 | L27: NA | M27: F | N27: =IF(M27="U",F27,M27) -> F | O27: OtsLYON20S_1_0315 | P27: OtsLYON20S_1_0043 | Q27: OtsLYON20S_1 | R27: 4 | S27: =IFERROR($S$4-R27,"U") -> 2020 | T27: FALL | U27: 1 | V27: PLA1 | W27: =VLOOKUP(Q27,'PBT Tag Rates'!$A$6:$D$67,4,FALSE) -> 0.98961046 | X27: 1 | Y27: =IF(V27="ng",0,X27+(SUMIFS($AK$24:$AK$127,$AG$24:$AG$127,$N27,$AH$24:$AH$127,$Z27,$AF$24:$AF$127,$E27))) -> 1.1428571 | Z27: =IFERROR(LOOKUP(H27,{30,43,48,53,58,63,68,73,78,83,88,93,97},{42,47,52,57,62,67,72,77,82,87,92,99,100}),999) -> 77 | AA27: =Y27/(VLOOKUP(E27,$C$2:$I$5,2,FALSE)) -> 1.6326531 | AB27: =IFERROR(IF(I27="AI",AA27-VLOOKUP(Q27,'PBT Tag Rates'!$A$6:$L$53,11,FALSE),AA27-VLOOKUP(Q27,'PBT Tag Rates'!$A$6:$L$53,12,FALSE)),0) -> 1.6431517 | AC27: =AB27/(VLOOKUP(E27,$C$2:$I$5,7,FALSE)) -> 16.615366 | AD27: Abv | AF27: 18 | AG27: F | AH27: 57 | AI27: =SUMIFS($X$7:$X$5545,$Z$7:$Z$5545,$AH27,$N$6:$N$5544,$AG27,$E$6:$E$5544,$AF27,$V$7:$V$5545,"NG") -> 0 | AJ27: =(SUMIFS($X$7:$X$5545,$Z$7:$Z$5545,$AH27,$N$6:$N$5544,$AG27,$E$6:$E$5544,$AF27)) -> 28 | AK27: =IFERROR(AI27/AJ27,0) -> 0 | AM27: =AJ27*AK27 -> 0
A28: OtsLGRF24S | B28: OtsLGRF24S_0215 | C28: C-00215 | D28: 45523 | E28: =IF(AND(D28>=$F$2,D28<$F$3),70,IF(AND(D28>=$F$3,D28<$F$4),40,IF(AND(D28>=$F$4,D28<$F$5),18,9))) -> 70 | F28: M | G28: 670 | H28: =G28/10 -> 67 | I28: AI | J28: NA | K28: NA | L28: NA | M28: M | N28: =IF(M28="U",F28,M28) -> M | O28: OtsLYON20S_1_1556 | P28: OtsLYON20S_1_1714 | Q28: OtsLYON20S_1 | R28: 4 | S28: =IFERROR($S$4-R28,"U") -> 2020 | T28: FALL | U28: 1 | V28: IPCSR | W28: =VLOOKUP(Q28,'PBT Tag Rates'!$A$6:$D$67,4,FALSE) -> 0.98961046 | X28: 1 | Y28: =IF(V28="ng",0,X28+(SUMIFS($AK$24:$AK$127,$AG$24:$AG$127,$N28,$AH$24:$AH$127,$Z28,$AF$24:$AF$127,$E28))) -> 1.0833333 | Z28: =IFERROR(LOOKUP(H28,{30,43,48,53,58,63,68,73,78,83,88,93,97},{42,47,52,57,62,67,72,77,82,87,92,99,100}),999) -> 67 | AA28: =Y28/(VLOOKUP(E28,$C$2:$I$5,2,FALSE)) -> 1.547619 | AB28: =IFERROR(IF(I28="AI",AA28-VLOOKUP(Q28,'PBT Tag Rates'!$A$6:$L$53,11,FALSE),AA28-VLOOKUP(Q28,'PBT Tag Rates'!$A$6:$L$53,12,FALSE)),0) -> 1.5581177 | AC28: =AB28/(VLOOKUP(E28,$C$2:$I$5,7,FALSE)) -> 15.755511 | AD28: Abv | AF28: 18 | AG28: F | AH28: 62 | AI28: =SUMIFS($X$7:$X$5545,$Z$7:$Z$5545,$AH28,$N$6:$N$5544,$AG28,$E$6:$E$5544,$AF28,$V$7:$V$5545,"NG") -> 1 | AJ28: =(SUMIFS($X$7:$X$5545,$Z$7:$Z$5545,$AH28,$N$6:$N$5544,$AG28,$E$6:$E$5544,$AF28)) -> 58 | AK28: =IFERROR(AI28/AJ28,0) -> 0.017241379 | AM28: =AJ28*AK28 -> 1
A29: OtsLGRF24S | B29: OtsLGRF24S_0225 | C29: C-00225 | D29: 45523 | E29: =IF(AND(D29>=$F$2,D29<$F$3),70,IF(AND(D29>=$F$3,D29<$F$4),40,IF(AND(D29>=$F$4,D29<$F$5),18,9))) -> 70 | F29: M | G29: 700 | H29: =G29/10 -> 70 | I29: AD | J29: 1 | K29: 3DD.0078C2F0FD | L29: NA | M29: M | N29: =IF(M29="U",F29,M29) -> M | O29: NA | P29: NA | Q29: Unassigned | R29: NA | S29: =IFERROR($S$4-R29,"U") -> U | T29: FALL | U29: 1 | V29: NA | W29: =VLOOKUP(Q29,'PBT Tag Rates'!$A$6:$D$67,4,FALSE) -> 1 | X29: 1 | Y29: =IF(V29="ng",0,X29+(SUMIFS($AK$24:$AK$127,$AG$24:$AG$127,$N29,$AH$24:$AH$127,$Z29,$AF$24:$AF$127,$E29))) -> 1.0952381 | Z29: =IFERROR(LOOKUP(H29,{30,43,48,53,58,63,68,73,78,83,88,93,97},{42,47,52,57,62,67,72,77,82,87,92,99,100}),999) -> 72 | AA29: =Y29/(VLOOKUP(E29,$C$2:$I$5,2,FALSE)) -> 1.5646259 | AB29: =IFERROR(IF(I29="AI",AA29-VLOOKUP(Q29,'PBT Tag Rates'!$A$6:$L$53,11,FALSE),AA29-VLOOKUP(Q29,'PBT Tag Rates'!$A$6:$L$53,12,FALSE)),0) -> 1.0483484 | AC29: =AB29/(VLOOKUP(E29,$C$2:$I$5,7,FALSE)) -> 10.600782 | AD29: Abv | AF29: 18 | AG29: F | AH29: 67 | AI29: =SUMIFS($X$7:$X$5545,$Z$7:$Z$5545,$AH29,$N$6:$N$5544,$AG29,$E$6:$E$5544,$AF29,$V$7:$V$5545,"NG") -> 0 | AJ29: =(SUMIFS($X$7:$X$5545,$Z$7:$Z$5545,$AH29,$N$6:$N$5544,$AG29,$E$6:$E$5544,$AF29)) -> 119 | AK29: =IFERROR(AI29/AJ29,0) -> 0 | AM29: =AJ29*AK29 -> 0
A30: OtsLGRF24S | B30: OtsLGRF24S_0235 | C30: C-00235 | D30: 45523 | E30: =IF(AND(D30>=$F$2,D30<$F$3),70,IF(AND(D30>=$F$3,D30<$F$4),40,IF(AND(D30>=$F$4,D30<$F$5),18,9))) -> 70 | F30: F | G30: 810 | H30: =G30/10 -> 81 | I30: AI | J30: NA | K30: 3DD.0078C2F122 | L30: NA | M30: F | N30: =IF(M30="U",F30,M30) -> F | O30: OtsNPFH19S_1_1342 | P30: OtsNPFH19S_1_1010 | Q30: OtsNPFH19S_1 | R30: 5 | S30: =IFERROR($S$4-R30,"U") -> 2019 | T30: FALL | U30: 1 | V30: NPTH | W30: =VLOOKUP(Q30,'PBT Tag Rates'!$A$6:$D$67,4,FALSE) -> 0.99705232 | X30: 1 | Y30: =IF(V30="ng",0,X30+(SUMIFS($AK$24:$AK$127,$AG$24:$AG$127,$N30,$AH$24:$AH$127,$Z30,$AF$24:$AF$127,$E30))) -> 1.137931 | Z30: =IFERROR(LOOKUP(H30,{30,43,48,53,58,63,68,73,78,83,88,93,97},{42,47,52,57,62,67,72,77,82,87,92,99,100}),999) -> 82 | AA30: =Y30/(VLOOKUP(E30,$C$2:$I$5,2,FALSE)) -> 1.6256158 | AB30: =IFERROR(IF(I30="AI",AA30-VLOOKUP(Q30,'PBT Tag Rates'!$A$6:$L$53,11,FALSE),AA30-VLOOKUP(Q30,'PBT Tag Rates'!$A$6:$L$53,12,FALSE)),0) -> 1.6285722 | AC30: =AB30/(VLOOKUP(E30,$C$2:$I$5,7,FALSE)) -> 16.467939 | AD30: Abv | AF30: 18 | AG30: F | AH30: 72 | AI30: =SUMIFS($X$7:$X$5545,$Z$7:$Z$5545,$AH30,$N$6:$N$5544,$AG30,$E$6:$E$5544,$AF30,$V$7:$V$5545,"NG") -> 1 | AJ30: =(SUMIFS($X$7:$X$5545,$Z$7:$Z$5545,$AH30,$N$6:$N$5544,$AG30,$E$6:$E$5544,$AF30)) -> 143 | AK30: =IFERROR(AI30/AJ30,0) -> 0.006993007 | AM30: =AJ30*AK30 -> 1
A31: OtsLGRF24S | B31: OtsLGRF24S_0245 | C31: C-00245 | D31: 45523 | E31: =IF(AND(D31>=$F$2,D31<$F$3),70,IF(AND(D31>=$F$3,D31<$F$4),40,IF(AND(D31>=$F$4,D31<$F$5),18,9))) -> 70 | F31: F | G31: 860 | H31: =G31/10 -> 86 | I31: AI | J31: NA | K31: 3DD.0078C2F129 | L31: NA | M31: F | N31: =IF(M31="U",F31,M31) -> F | O31: NA | P31: NA | Q31: Unassigned | R31: NA | S31: =IFERROR($S$4-R31,"U") -> U | T31: FALL | U31: 1 | V31: NA | W31: =VLOOKUP(Q31,'PBT Tag Rates'!$A$6:$D$67,4,FALSE) -> 1 | X31: 1 | Y31: =IF(V31="ng",0,X31+(SUMIFS($AK$24:$AK$127,$AG$24:$AG$127,$N31,$AH$24:$AH$127,$Z31,$AF$24:$AF$127,$E31))) -> 1 | Z31: =IFERROR(LOOKUP(H31,{30,43,48,53,58,63,68,73,78,83,88,93,97},{42,47,52,57,62,67,72,77,82,87,92,99,100}),999) -> 87 | AA31: =Y31/(VLOOKUP(E31,$C$2:$I$5,2,FALSE)) -> 1.4285714 | AB31: =IFERROR(IF(I31="AI",AA31-VLOOKUP(Q31,'PBT Tag Rates'!$A$6:$L$53,11,FALSE),AA31-VLOOKUP(Q31,'PBT Tag Rates'!$A$6:$L$53,12,FALSE)),0) -> 1.3872683 | AC31: =AB31/(VLOOKUP(E31,$C$2:$I$5,7,FALSE)) -> 14.027902 | AD31: Abv | AF31: 18 | AG31: F | AH31: 77 | AI31: =SUMIFS($X$7:$X$5545,$Z$7:$Z$5545,$AH31,$N$6:$N$5544,$AG31,$E$6:$E$5544,$AF31,$V$7:$V$5545,"NG") -> 0 | AJ31: =(SUMIFS($X$7:$X$5545,$Z$7:$Z$5545,$AH31,$N$6:$N$5544,$AG31,$E$6:$E$5544,$AF31)) -> 120 | AK31: =IFERROR(AI31/AJ31,0) -> 0 | AM31: =AJ31*AK31 -> 0
A32: OtsLGRF24S | B32: OtsLGRF24S_0255 | C32: C-00255 | D32: 45523 | E32: =IF(AND(D32>=$F$2,D32<$F$3),70,IF(AND(D32>=$F$3,D32<$F$4),40,IF(AND(D32>=$F$4,D32<$F$5),18,9))) -> 70 | F32: F | G32: 730 | H32: =G32/10 -> 73 | I32: AD | J32: 1 | K32: 3DD.0078C2F133 | L32: NA | M32: F | N32: =IF(M32="U",F32,M32) -> F | O32: OtsNPFH20S_1_0468 | P32: OtsNPFH20S_1_0422 | Q32: OtsNPFH20S_1 | R32: 4 | S32: =IFERROR($S$4-R32,"U") -> 2020 | T32: FALL | U32: 1 | V32: LGA | W32: =VLOOKUP(Q32,'PBT Tag Rates'!$A$6:$D$67,4,FALSE) -> 0.98845609 | X32: 1 | Y32: =IF(V32="ng",0,X32+(SUMIFS($AK$24:$AK$127,$AG$24:$AG$127,$N32,$AH$24:$AH$127,$Z32,$AF$24:$AF$127,$E32))) -> 1.1428571 | Z32: =IFERROR(LOOKUP(H32,{30,43,48,53,58,63,68,73,78,83,88,93,97},{42,47,52,57,62,67,72,77,82,87,92,99,100}),999) -> 77 | AA32: =Y32/(VLOOKUP(E32,$C$2:$I$5,2,FALSE)) -> 1.6326531 | AB32: =IFERROR(IF(I32="AI",AA32-VLOOKUP(Q32,'PBT Tag Rates'!$A$6:$L$53,11,FALSE),AA32-VLOOKUP(Q32,'PBT Tag Rates'!$A$6:$L$53,12,FALSE)),0) -> 1.6443318 | AC32: =AB32/(VLOOKUP(E32,$C$2:$I$5,7,FALSE)) -> 16.627299 | AD32: Abv | AF32: 18 | AG32: F | AH32: 82 | AI32: =SUMIFS($X$7:$X$5545,$Z$7:$Z$5545,$AH32,$N$6:$N$5544,$AG32,$E$6:$E$5544,$AF32,$V$7:$V$5545,"NG") -> 0 | AJ32: =(SUMIFS($X$7:$X$5545,$Z$7:$Z$5545,$AH32,$N$6:$N$5544,$AG32,$E$6:$E$5544,$AF32)) -> 67 | AK32: =IFERROR(AI32/AJ32,0) -> 0 | AM32: =AJ32*AK32 -> 0
A33: OtsLGRF24S | B33: OtsLGRF24S_0265 | C33: C-00265 | D33: 45523 | E33: =IF(AND(D33>=$F$2,D33<$F$3),70,IF(AND(D33>=$F$3,D33<$F$4),40,IF(AND(D33>=$F$4,D33<$F$5),18,9))) -> 70 | F33: F | G33: 740 | H33: =G33/10 -> 74 | I33: AI | J33: NA | K33: 3DD.0078C2F0DD | L33: NA | M33: F | N33: =IF(M33="U",F33,M33) -> F | O33: NA | P33: NA | Q33: Unassigned | R33: NA | S33: =IFERROR($S$4-R33,"U") -> U | T33: FALL | U33: 1 | V33: NA | W33: =VLOOKUP(Q33,'PBT Tag Rates'!$A$6:$D$67,4,FALSE) -> 1 | X33: 1 | Y33: =IF(V33="ng",0,X33+(SUMIFS($AK$24:$AK$127,$AG$24:$AG$127,$N33,$AH$24:$AH$127,$Z33,$AF$24:$AF$127,$E33))) -> 1.1428571 | Z33: =IFERROR(LOOKUP(H33,{30,43,48,53,58,63,68,73,78,83,88,93,97},{42,47,52,57,62,67,72,77,82,87,92,99,100}),999) -> 77 | AA33: =Y33/(VLOOKUP(E33,$C$2:$I$5,2,FALSE)) -> 1.6326531 | AB33: =IFERROR(IF(I33="AI",AA33-VLOOKUP(Q33,'PBT Tag Rates'!$A$6:$L$53,11,FALSE),AA33-VLOOKUP(Q33,'PBT Tag Rates'!$A$6:$L$53,12,FALSE)),0) -> 1.5913499 | AC33: =AB33/(VLOOKUP(E33,$C$2:$I$5,7,FALSE)) -> 16.091552 | AD33: Abv | AF33: 18 | AG33: F | AH33: 87 | AI33: =SUMIFS($X$7:$X$5545,$Z$7:$Z$5545,$AH33,$N$6:$N$5544,$AG33,$E$6:$E$5544,$AF33,$V$7:$V$5545,"NG") -> 0 | AJ33: =(SUMIFS($X$7:$X$5545,$Z$7:$Z$5545,$AH33,$N$6:$N$5544,$AG33,$E$6:$E$5544,$AF33)) -> 30 | AK33: =IFERROR(AI33/AJ33,0) -> 0 | AM33: =AJ33*AK33 -> 0
A34: OtsLGRF24S | B34: OtsLGRF24S_0275 | C34: C-00275 | D34: 45523 | E34: =IF(AND(D34>=$F$2,D34<$F$3),70,IF(AND(D34>=$F$3,D34<$F$4),40,IF(AND(D34>=$F$4,D34<$F$5),18,9))) -> 70 | F34: M | G34: 450 | H34: =G34/10 -> 45 | I34: AI | J34: NA | K34: NA | L34: NA | M34: M | N34: =IF(M34="U",F34,M34) -> M | O34: OtsLYON22S_1_0468 | P34: OtsLYON22S_1_4280 | Q34: OtsLYON22S_1 | R34: 2 | S34: =IFERROR($S$4-R34,"U") -> 2022 | T34: FALL | U34: 1 | V34: IPCSR | W34: =VLOOKUP(Q34,'PBT Tag Rates'!$A$6:$D$67,4,FALSE) -> 0.98 | X34: 1 | Y34: =IF(V34="ng",0,X34+(SUMIFS($AK$24:$AK$127,$AG$24:$AG$127,$N34,$AH$24:$AH$127,$Z34,$AF$24:$AF$127,$E34))) -> 1 | Z34: =IFERROR(LOOKUP(H34,{30,43,48,53,58,63,68,73,78,83,88,93,97},{42,47,52,57,62,67,72,77,82,87,92,99,100}),999) -> 47 | AA34: =Y34/(VLOOKUP(E34,$C$2:$I$5,2,FALSE)) -> 1.4285714 | AB34: =IFERROR(IF(I34="AI",AA34-VLOOKUP(Q34,'PBT Tag Rates'!$A$6:$L$53,11,FALSE),AA34-VLOOKUP(Q34,'PBT Tag Rates'!$A$6:$L$53,12,FALSE)),0) -> 1.4489796 | AC34: =AB34/(VLOOKUP(E34,$C$2:$I$5,7,FALSE)) -> 14.65192 | AD34: Abv | AF34: 18 | AG34: F | AH34: 92 | AI34: =SUMIFS($X$7:$X$5545,$Z$7:$Z$5545,$AH34,$N$6:$N$5544,$AG34,$E$6:$E$5544,$AF34,$V$7:$V$5545,"NG") -> 0 | AJ34: =(SUMIFS($X$7:$X$5545,$Z$7:$Z$5545,$AH34,$N$6:$N$5544,$AG34,$E$6:$E$5544,$AF34)) -> 8 | AK34: =IFERROR(AI34/AJ34,0) -> 0 | AM34: =AJ34*AK34 -> 0
A35: OtsLGRF24S | B35: OtsLGRF24S_0285 | C35: C-00285 | D35: 45523 | E35: =IF(AND(D35>=$F$2,D35<$F$3),70,IF(AND(D35>=$F$3,D35<$F$4),40,IF(AND(D35>=$F$4,D35<$F$5),18,9))) -> 70 | F35: F | G35: 770 | H35: =G35/10 -> 77 | I35: AD | J35: 1 | K35: 3DD.0078C2F109 | L35: NA | M35: F | N35: =IF(M35="U",F35,M35) -> F | O35: OtsLYON20S_1_0205 | P35: OtsLYON20S_1_0023 | Q35: OtsLYON20S_1 | R35: 4 | S35: =IFERROR($S$4-R35,"U") -> 2020 | T35: FALL | U35: 1 | V35: PLA1 | W35: =VLOOKUP(Q35,'PBT Tag Rates'!$A$6:$D$67,4,FALSE) -> 0.98961046 | X35: 1 | Y35: =IF(V35="ng",0,X35+(SUMIFS($AK$24:$AK$127,$AG$24:$AG$127,$N35,$AH$24:$AH$127,$Z35,$AF$24:$AF$127,$E35))) -> 1.1428571 | Z35: =IFERROR(LOOKUP(H35,{30,43,48,53,58,63,68,73,78,83,88,93,97},{42,47,52,57,62,67,72,77,82,87,92,99,100}),999) -> 77 | AA35: =Y35/(VLOOKUP(E35,$C$2:$I$5,2,FALSE)) -> 1.6326531 | AB35: =IFERROR(IF(I35="AI",AA35-VLOOKUP(Q35,'PBT Tag Rates'!$A$6:$L$53,11,FALSE),AA35-VLOOKUP(Q35,'PBT Tag Rates'!$A$6:$L$53,12,FALSE)),0) -> 1.6431517 | AC35: =AB35/(VLOOKUP(E35,$C$2:$I$5,7,FALSE)) -> 16.615366 | AD35: Abv | AF35: 18 | AG35: F | AH35: 99 | AI35: =SUMIFS($X$7:$X$5545,$Z$7:$Z$5545,$AH35,$N$6:$N$5544,$AG35,$E$6:$E$5544,$AF35,$V$7:$V$5545,"NG") -> 0 | AJ35: =(SUMIFS($X$7:$X$5545,$Z$7:$Z$5545,$AH35,$N$6:$N$5544,$AG35,$E$6:$E$5544,$AF35)) -> 0 | AK35: =IFERROR(AI35/AJ35,0) -> 0 | AM35: =AJ35*AK35 -> 0
A36: OtsLGRF24S | B36: OtsLGRF24S_0295 | C36: C-00295 | D36: 45523 | E36: =IF(AND(D36>=$F$2,D36<$F$3),70,IF(AND(D36>=$F$3,D36<$F$4),40,IF(AND(D36>=$F$4,D36<$F$5),18,9))) -> 70 | F36: M | G36: 720 | H36: =G36/10 -> 72 | I36: AI | J36: NA | K36: 3DD.0077B43FA6 | L36: NA | M36: M | N36: =IF(M36="U",F36,M36) -> M | O36: NA | P36: NA | Q36: Unassigned | R36: NA | S36: =IFERROR($S$4-R36,"U") -> U | T36: FALL | U36: 1 | V36: NA | W36: =VLOOKUP(Q36,'PBT Tag Rates'!$A$6:$D$67,4,FALSE) -> 1 | X36: 1 | Y36: =IF(V36="ng",0,X36+(SUMIFS($AK$24:$AK$127,$AG$24:$AG$127,$N36,$AH$24:$AH$127,$Z36,$AF$24:$AF$127,$E36))) -> 1.0952381 | Z36: =IFERROR(LOOKUP(H36,{30,43,48,53,58,63,68,73,78,83,88,93,97},{42,47,52,57,62,67,72,77,82,87,92,99,100}),999) -> 72 | AA36: =Y36/(VLOOKUP(E36,$C$2:$I$5,2,FALSE)) -> 1.5646259 | AB36: =IFERROR(IF(I36="AI",AA36-VLOOKUP(Q36,'PBT Tag Rates'!$A$6:$L$53,11,FALSE),AA36-VLOOKUP(Q36,'PBT Tag Rates'!$A$6:$L$53,12,FALSE)),0) -> 1.5233227 | AC36: =AB36/(VLOOKUP(E36,$C$2:$I$5,7,FALSE)) -> 15.403669 | AD36: Abv | AF36: 18 | AG36: F | AH36: 100 | AI36: =SUMIFS($X$7:$X$5545,$Z$7:$Z$5545,$AH36,$N$6:$N$5544,$AG36,$E$6:$E$5544,$AF36,$V$7:$V$5545,"NG") -> 0 | AJ36: =(SUMIFS($X$7:$X$5545,$Z$7:$Z$5545,$AH36,$N$6:$N$5544,$AG36,$E$6:$E$5544,$AF36)) -> 1 | AK36: =IFERROR(AI36/AJ36,0) -> 0 | AM36: =AJ36*AK36 -> 0
A37: OtsLGRF24S | B37: OtsLGRF24S_0305 | C37: C-00305 | D37: 45523 | E37: =IF(AND(D37>=$F$2,D37<$F$3),70,IF(AND(D37>=$F$3,D37<$F$4),40,IF(AND(D37>=$F$4,D37<$F$5),18,9))) -> 70 | F37: F | G37: 800 | H37: =G37/10 -> 80 | I37: AD | J37: 1 | K37: 3DD.0077CCE068 | L37: NA | M37: F | N37: =IF(M37="U",F37,M37) -> F | O37: OtsLYON20S_1_0489 | P37: OtsLYON20S_1_0537 | Q37: OtsLYON20S_1 | R37: 4 | S37: =IFERROR($S$4-R37,"U") -> 2020 | T37: FALL | U37: 1 | V37: LFSO | W37: =VLOOKUP(Q37,'PBT Tag Rates'!$A$6:$D$67,4,FALSE) -> 0.98961046 | X37: 1 | Y37: =IF(V37="ng",0,X37+(SUMIFS($AK$24:$AK$127,$AG$24:$AG$127,$N37,$AH$24:$AH$127,$Z37,$AF$24:$AF$127,$E37))) -> 1.137931 | Z37: =IFERROR(LOOKUP(H37,{30,43,48,53,58,63,68,73,78,83,88,93,97},{42,47,52,57,62,67,72,77,82,87,92,99,100}),999) -> 82 | AA37: =Y37/(VLOOKUP(E37,$C$2:$I$5,2,FALSE)) -> 1.6256158 | AB37: =IFERROR(IF(I37="AI",AA37-VLOOKUP(Q37,'PBT Tag Rates'!$A$6:$L$53,11,FALSE),AA37-VLOOKUP(Q37,'PBT Tag Rates'!$A$6:$L$53,12,FALSE)),0) -> 1.6361144 | AC37: =AB37/(VLOOKUP(E37,$C$2:$I$5,7,FALSE)) -> 16.544206 | AD37: Abv | AF37: 18 | AG37: M | AH37: 42 | AI37: =SUMIFS($X$7:$X$5545,$Z$7:$Z$5545,$AH37,$N$6:$N$5544,$AG37,$E$6:$E$5544,$AF37,$V$7:$V$5545,"NG") -> 0 | AJ37: =(SUMIFS($X$7:$X$5545,$Z$7:$Z$5545,$AH37,$N$6:$N$5544,$AG37,$E$6:$E$5544,$AF37)) -> 27 | AK37: =IFERROR(AI37/AJ37,0) -> 0 | AM37: =AJ37*AK37 -> 0
A38: OtsLGRF24S | B38: OtsLGRF24S_0315 | C38: C-00315 | D38: 45523 | E38: =IF(AND(D38>=$F$2,D38<$F$3),70,IF(AND(D38>=$F$3,D38<$F$4),40,IF(AND(D38>=$F$4,D38<$F$5),18,9))) -> 70 | F38: M | G38: 680 | H38: =G38/10 -> 68 | I38: AI | J38: NA | K38: NA | L38: NA | M38: M | N38: =IF(M38="U",F38,M38) -> M | O38: OtsLYON21S_1_0757 | P38: OtsLYON21S_1_0394 | Q38: OtsLYON21S_1 | R38: 3 | S38: =IFERROR($S$4-R38,"U") -> 2021 | T38: FALL | U38: 1 | V38: CJA1 | W38: =VLOOKUP(Q38,'PBT Tag Rates'!$A$6:$D$67,4,FALSE) -> 0.9814 | X38: 1 | Y38: =IF(V38="ng",0,X38+(SUMIFS($AK$24:$AK$127,$AG$24:$AG$127,$N38,$AH$24:$AH$127,$Z38,$AF$24:$AF$127,$E38))) -> 1.0952381 | Z38: =IFERROR(LOOKUP(H38,{30,43,48,53,58,63,68,73,78,83,88,93,97},{42,47,52,57,62,67,72,77,82,87,92,99,100}),999) -> 72 | AA38: =Y38/(VLOOKUP(E38,$C$2:$I$5,2,FALSE)) -> 1.5646259 | AB38: =IFERROR(IF(I38="AI",AA38-VLOOKUP(Q38,'PBT Tag Rates'!$A$6:$L$53,11,FALSE),AA38-VLOOKUP(Q38,'PBT Tag Rates'!$A$6:$L$53,12,FALSE)),0) -> 1.5835784 | AC38: =AB38/(VLOOKUP(E38,$C$2:$I$5,7,FALSE)) -> 16.012967 | AD38: Abv | AF38: 18 | AG38: M | AH38: 47 | AI38: =SUMIFS($X$7:$X$5545,$Z$7:$Z$5545,$AH38,$N$6:$N$5544,$AG38,$E$6:$E$5544,$AF38,$V$7:$V$5545,"NG") -> 0 | AJ38: =(SUMIFS($X$7:$X$5545,$Z$7:$Z$5545,$AH38,$N$6:$N$5544,$AG38,$E$6:$E$5544,$AF38)) -> 36 | AK38: =IFERROR(AI38/AJ38,0) -> 0 | AM38: =AJ38*AK38 -> 0
A39: OtsLGRF24S | B39: OtsLGRF24S_0325 | C39: C-00325 | D39: 45523 | E39: =IF(AND(D39>=$F$2,D39<$F$3),70,IF(AND(D39>=$F$3,D39<$F$4),40,IF(AND(D39>=$F$4,D39<$F$5),18,9))) -> 70 | F39: M | G39: 810 | H39: =G39/10 -> 81 | I39: AI | J39: NA | K39: 3DD.0077B44F47 | L39: NA | M39: M | N39: =IF(M39="U",F39,M39) -> M | O39: OtsLYON19S_1_0552 | P39: OtsLYON19S_1_0437 | Q39: OtsLYON19S_1 | R39: 5 | S39: =IFERROR($S$4-R39,"U") -> 2019 | T39: FALL | U39: 1 | V39: LFSO | W39: =VLOOKUP(Q39,'PBT Tag Rates'!$A$6:$D$67,4,FALSE) -> 0.95971981 | X39: 1 | Y39: =IF(V39="ng",0,X39+(SUMIFS($AK$24:$AK$127,$AG$24:$AG$127,$N39,$AH$24:$AH$127,$Z39,$AF$24:$AF$127,$E39))) -> 1.025 | Z39: =IFERROR(LOOKUP(H39,{30,43,48,53,58,63,68,73,78,83,88,93,97},{42,47,52,57,62,67,72,77,82,87,92,99,100}),999) -> 82 | AA39: =Y39/(VLOOKUP(E39,$C$2:$I$5,2,FALSE)) -> 1.4642857 | AB39: =IFERROR(IF(I39="AI",AA39-VLOOKUP(Q39,'PBT Tag Rates'!$A$6:$L$53,11,FALSE),AA39-VLOOKUP(Q39,'PBT Tag Rates'!$A$6:$L$53,12,FALSE)),0) -> 1.5062565 | AC39: =AB39/(VLOOKUP(E39,$C$2:$I$5,7,FALSE)) -> 15.231097 | AD39: Abv | AF39: 18 | AG39: M | AH39: 52 | AI39: =SUMIFS($X$7:$X$5545,$Z$7:$Z$5545,$AH39,$N$6:$N$5544,$AG39,$E$6:$E$5544,$AF39,$V$7:$V$5545,"NG") -> 0 | AJ39: =(SUMIFS($X$7:$X$5545,$Z$7:$Z$5545,$AH39,$N$6:$N$5544,$AG39,$E$6:$E$5544,$AF39)) -> 32 | AK39: =IFERROR(AI39/AJ39,0) -> 0 | AM39: =AJ39*AK39 -> 0
A40: OtsLGRF24S | B40: OtsLGRF24S_0335 | C40: C-00335 | D40: 45523 | E40: =IF(AND(D40>=$F$2,D40<$F$3),70,IF(AND(D40>=$F$3,D40<$F$4),40,IF(AND(D40>=$F$4,D40<$F$5),18,9))) -> 70 | F40: M | G40: 800 | H40: =G40/10 -> 80 | I40: AD | J40: 1 | K40: 3DD.0077B4596C | L40: NA | M40: F | N40: =IF(M40="U",F40,M40) -> F | O40: OtsNPFH20S_1_0362 | P40: OtsNPFH20S_1_0327 | Q40: OtsNPFH20S_1 | R40: 4 | S40: =IFERROR($S$4-R40,"U") -> 2020 | T40: FALL | U40: 1 | V40: CFA | W40: =VLOOKUP(Q40,'PBT Tag Rates'!$A$6:$D$67,4,FALSE) -> 0.98845609 | X40: 1 | Y40: =IF(V40="ng",0,X40+(SUMIFS($AK$24:$AK$127,$AG$24:$AG$127,$N40,$AH$24:$AH$127,$Z40,$AF$24:$AF$127,$E40))) -> 1.137931 | Z40: =IFERROR(LOOKUP(H40,{30,43,48,53,58,63,68,73,78,83,88,93,97},{42,47,52,57,62,67,72,77,82,87,92,99,100}),999) -> 82 | AA40: =Y40/(VLOOKUP(E40,$C$2:$I$5,2,FALSE)) -> 1.6256158 | AB40: =IFERROR(IF(I40="AI",AA40-VLOOKUP(Q40,'PBT Tag Rates'!$A$6:$L$53,11,FALSE),AA40-VLOOKUP(Q40,'PBT Tag Rates'!$A$6:$L$53,12,FALSE)),0) -> 1.6372945 | AC40: =AB40/(VLOOKUP(E40,$C$2:$I$5,7,FALSE)) -> 16.556139 | AD40: Abv | AF40: 18 | AG40: M | AH40: 57 | AI40: =SUMIFS($X$7:$X$5545,$Z$7:$Z$5545,$AH40,$N$6:$N$5544,$AG40,$E$6:$E$5544,$AF40,$V$7:$V$5545,"NG") -> 1 | AJ40: =(SUMIFS($X$7:$X$5545,$Z$7:$Z$5545,$AH40,$N$6:$N$5544,$AG40,$E$6:$E$5544,$AF40)) -> 32 | AK40: =IFERROR(AI40/AJ40,0) -> 0.03125 | AM40: =AJ40*AK40 -> 1
...

Sheet Hat by PBT
A1: ='Individual Data'!S4 -> 2024 | G1: sum check | I1: =SUM(D5:P6) -> 15085.553 | P1: =I1+I81 -> 33211.365 | Y1: Fallback Reacension rate
U2: run year | Z2: adlt | AA2: jack | AC2: Final estimates of hatchery assigned fish by release site
R3: sum check | U3: =A1 -> 2024 | Y3: abv | Z3: ='Individual Data'!AI4 -> 0.024 | AA3: ='Individual Data'!AH4 -> 0.074
R4: =R6+S6 -> 15085.553 | U4: M&F | Y4: blw | Z4: ='Individual Data'!AI5 -> 0.33 | AA4: ='Individual Data'!AH5 -> 0.29
U5: =R4+R84 -> 33211.365 | Y5: =SUM(Y8:Y75) -> 15085.553 | Z5: =SUM(Z8:Z75) -> 13989.691 | AA5: =SUM(AA8:AA75) -> 4136.1204 | AC5: =SUM(AC8:AC75) -> 14101.369 | AD5: =SUM(AD8:AD75) -> 13167.924 | AE5: =SUM(AE8:AE75) -> 3688.2321
B6: F | C6: total by FL | D6: =SUM(D8:D77) -> 0 | E6: =SUM(E8:E77) -> 0 | F6: =SUM(F8:F77) -> 16.753414 | G6: =SUM(G8:G77) -> 82.94754 | H6: =SUM(H8:H77) -> 390.5953 | I6: =SUM(I8:I77) -> 1612.7353 | J6: =SUM(J8:J77) -> 4087.4112 | K6: =SUM(K8:K77) -> 5290.8987 | ... P6: =SUM(P8:P77) -> 0 | R6: =SUM(R8:R75) -> 16.753414 | S6: =SUM(S8:S75) -> 15068.8 | Z6: =Y5+Z5+AA5 -> 33211.365 | AD6: =AC5+AD5+AE5 -> 30957.526
B7: Final group | C7: agePBT | D7: 42 | E7: 47 | F7: 52 | G7: 57 | H7: 62 | I7: 67 | J7: 72 | K7: 77 | L7: 82 | M7: 87 | N7: 92 | O7: 99 | P7: 100 | R7: F jacks | S7: Females | U7: Brd Yr | V7: grp | W7: origin | X7: CWT code | Y7: Female | Z7: Males | AA7: jacks | AB7: rel loc | AC7: Female | AD7: Males | AE7: jacks
A8: OtsLYON19S_1 | B8: BCA1 | C8: 5 | D8: =SUMIFS('Individual Data'!$AC$7:$AC$5545,'Individual Data'!$V$7:$V$5545,'Hat by PBT'!$B8,'Individual Data'!$Z$7:$Z$5545,'Hat by PBT'!D$7,'Individual Data'!$R$7:$R$5545,'Hat by PBT'!$C8,'Individual Data'!$N$7:$N$5545,'Hat by PBT'!$B$6) -> 0 | E8: =SUMIFS('Individual Data'!$AC$7:$AC$5545,'Individual Data'!$V$7:$V$5545,'Hat by PBT'!$B8,'Individual Data'!$Z$7:$Z$5545,'Hat by PBT'!E$7,'Individual Data'!$R$7:$R$5545,'Hat by PBT'!$C8,'Individual Data'!$N$7:$N$5545,'Hat by PBT'!$B$6) -> 0 | F8: =SUMIFS('Individual Data'!$AC$7:$AC$5545,'Individual Data'!$V$7:$V$5545,'Hat by PBT'!$B8,'Individual Data'!$Z$7:$Z$5545,'Hat by PBT'!F$7,'Individual Data'!$R$7:$R$5545,'Hat by PBT'!$C8,'Individual Data'!$N$7:$N$5545,'Hat by PBT'!$B$6) -> 0 | G8: =SUMIFS('Individual Data'!$AC$7:$AC$5545,'Individual Data'!$V$7:$V$5545,'Hat by PBT'!$B8,'Individual Data'!$Z$7:$Z$5545,'Hat by PBT'!G$7,'Individual Data'!$R$7:$R$5545,'Hat by PBT'!$C8,'Individual Data'!$N$7:$N$5545,'Hat by PBT'!$B$6) -> 0 | H8: =SUMIFS('Individual Data'!$AC$7:$AC$5545,'Individual Data'!$V$7:$V$5545,'Hat by PBT'!$B8,'Individual Data'!$Z$7:$Z$5545,'Hat by PBT'!H$7,'Individual Data'!$R$7:$R$5545,'Hat by PBT'!$C8,'Individual Data'!$N$7:$N$5545,'Hat by PBT'!$B$6) -> 0 | I8: =SUMIFS('Individual Data'!$AC$7:$AC$5545,'Individual Data'!$V$7:$V$5545,'Hat by PBT'!$B8,'Individual Data'!$Z$7:$Z$5545,'Hat by PBT'!I$7,'Individual Data'!$R$7:$R$5545,'Hat by PBT'!$C8,'Individual Data'!$N$7:$N$5545,'Hat by PBT'!$B$6) -> 0 | J8: =SUMIFS('Individual Data'!$AC$7:$AC$5545,'Individual Data'!$V$7:$V$5545,'Hat by PBT'!$B8,'Individual Data'!$Z$7:$Z$5545,'Hat by PBT'!J$7,'Individual Data'!$R$7:$R$5545,'Hat by PBT'!$C8,'Individual Data'!$N$7:$N$5545,'Hat by PBT'!$B$6) -> 15.832995 | K8: =SUMIFS('Individual Data'!$AC$7:$AC$5545,'Individual Data'!$V$7:$V$5545,'Hat by PBT'!$B8,'Individual Data'!$Z$7:$Z$5545,'Hat by PBT'!K$7,'Individual Data'!$R$7:$R$5545,'Hat by PBT'!$C8,'Individual Data'!$N$7:$N$5545,'Hat by PBT'!$B$6) -> 130.26672 | ... P8: =SUMIFS('Individual Data'!$AC$7:$AC$5545,'Individual Data'!$V$7:$V$5545,'Hat by PBT'!$B8,'Individual Data'!$Z$7:$Z$5545,'Hat by PBT'!P$7,'Individual Data'!$R$7:$R$5545,'Hat by PBT'!$C8,'Individual Data'!$N$7:$N$5545,'Hat by PBT'!$B$6) -> 0 | R8: =SUM(D8:F8) -> 0 | S8: =SUM(G8:P8) -> 292.74966 | U8: =$U$3-C8 -> 2019 | V8: =B8 -> BCA1 | W8: SR | X8: =SUMIFS('cwt rel info'!$A$6:$A$317,'cwt rel info'!$D$6:$D$317,'Hat by PBT'!U8,'cwt rel info'!$E$6:$E$317,'Hat by PBT'!V8) -> 220197 | Y8: =R8+S8 -> 292.74966 | Z8: =S88 -> 127.62552 | AA8: =R88 -> 0 | AB8: =VLOOKUP(V8,'Individual Data'!$V$6:$AD$5545,9,FALSE) -> Abv | AC8: =IF(AB8="blw",Y8*(1-$Z$4),Y8*(1-$Z$3)) -> 285.72366 | AD8: =IF(AB8="blw",Z8*(1-$Z$4),Z8*(1-$Z$3)) -> 124.56251 | AE8: =IF(AB8="blw",AA8*(1-$AA$4),AA8*(1-$AA$3)) -> 0
A9: OtsLYON19S_1 | B9: BCA2 | C9: 5 | D9: =SUMIFS('Individual Data'!$AC$7:$AC$5545,'Individual Data'!$V$7:$V$5545,'Hat by PBT'!$B9,'Individual Data'!$Z$7:$Z$5545,'Hat by PBT'!D$7,'Individual Data'!$R$7:$R$5545,'Hat by PBT'!$C9,'Individual Data'!$N$7:$N$5545,'Hat by PBT'!$B$6) -> 0 | E9: =SUMIFS('Individual Data'!$AC$7:$AC$5545,'Individual Data'!$V$7:$V$5545,'Hat by PBT'!$B9,'Individual Data'!$Z$7:$Z$5545,'Hat by PBT'!E$7,'Individual Data'!$R$7:$R$5545,'Hat by PBT'!$C9,'Individual Data'!$N$7:$N$5545,'Hat by PBT'!$B$6) -> 0 | F9: =SUMIFS('Individual Data'!$AC$7:$AC$5545,'Individual Data'!$V$7:$V$5545,'Hat by PBT'!$B9,'Individual Data'!$Z$7:$Z$5545,'Hat by PBT'!F$7,'Individual Data'!$R$7:$R$5545,'Hat by PBT'!$C9,'Individual Data'!$N$7:$N$5545,'Hat by PBT'!$B$6) -> 0 | G9: =SUMIFS('Individual Data'!$AC$7:$AC$5545,'Individual Data'!$V$7:$V$5545,'Hat by PBT'!$B9,'Individual Data'!$Z$7:$Z$5545,'Hat by PBT'!G$7,'Individual Data'!$R$7:$R$5545,'Hat by PBT'!$C9,'Individual Data'!$N$7:$N$5545,'Hat by PBT'!$B$6) -> 0 | H9: =SUMIFS('Individual Data'!$AC$7:$AC$5545,'Individual Data'!$V$7:$V$5545,'Hat by PBT'!$B9,'Individual Data'!$Z$7:$Z$5545,'Hat by PBT'!H$7,'Individual Data'!$R$7:$R$5545,'Hat by PBT'!$C9,'Individual Data'!$N$7:$N$5545,'Hat by PBT'!$B$6) -> 0 | I9: =SUMIFS('Individual Data'!$AC$7:$AC$5545,'Individual Data'!$V$7:$V$5545,'Hat by PBT'!$B9,'Individual Data'!$Z$7:$Z$5545,'Hat by PBT'!I$7,'Individual Data'!$R$7:$R$5545,'Hat by PBT'!$C9,'Individual Data'!$N$7:$N$5545,'Hat by PBT'!$B$6) -> 16.822593 | J9: =SUMIFS('Individual Data'!$AC$7:$AC$5545,'Individual Data'!$V$7:$V$5545,'Hat by PBT'!$B9,'Individual Data'!$Z$7:$Z$5545,'Hat by PBT'!J$7,'Individual Data'!$R$7:$R$5545,'Hat by PBT'!$C9,'Individual Data'!$N$7:$N$5545,'Hat by PBT'!$B$6) -> 51.03079 | K9: =SUMIFS('Individual Data'!$AC$7:$AC$5545,'Individual Data'!$V$7:$V$5545,'Hat by PBT'!$B9,'Individual Data'!$Z$7:$Z$5545,'Hat by PBT'!K$7,'Individual Data'!$R$7:$R$5545,'Hat by PBT'!$C9,'Individual Data'!$N$7:$N$5545,'Hat by PBT'!$B$6) -> 48.955761 | ... P9: =SUMIFS('Individual Data'!$AC$7:$AC$5545,'Individual Data'!$V$7:$V$5545,'Hat by PBT'!$B9,'Individual Data'!$Z$7:$Z$5545,'Hat by PBT'!P$7,'Individual Data'!$R$7:$R$5545,'Hat by PBT'!$C9,'Individual Data'!$N$7:$N$5545,'Hat by PBT'!$B$6) -> 0 | R9: =SUM(D9:F9) -> 0 | S9: =SUM(G9:P9) -> 116.80914 | U9: =$U$3-C9 -> 2019 | V9: =B9 -> BCA2 | W9: SR | X9: =SUMIFS('cwt rel info'!$A$6:$A$317,'cwt rel info'!$D$6:$D$317,'Hat by PBT'!U9,'cwt rel info'!$E$6:$E$317,'Hat by PBT'!V9) -> 220198 | Y9: =R9+S9 -> 116.80914 | Z9: =S89 -> 33.645185 | AA9: =R89 -> 0 | AB9: =VLOOKUP(V9,'Individual Data'!$V$6:$AD$5545,9,FALSE) -> Abv | AC9: =IF(AB9="blw",Y9*(1-$Z$4),Y9*(1-$Z$3)) -> 114.00572 | AD9: =IF(AB9="blw",Z9*(1-$Z$4),Z9*(1-$Z$3)) -> 32.837701 | AE9: =IF(AB9="blw",AA9*(1-$AA$4),AA9*(1-$AA$3)) -> 0
A10: OtsLYON19S_1 | B10: CJA1 | C10: 5 | D10: =SUMIFS('Individual Data'!$AC$7:$AC$5545,'Individual Data'!$V$7:$V$5545,'Hat by PBT'!$B10,'Individual Data'!$Z$7:$Z$5545,'Hat by PBT'!D$7,'Individual Data'!$R$7:$R$5545,'Hat by PBT'!$C10,'Individual Data'!$N$7:$N$5545,'Hat by PBT'!$B$6) -> 0 | E10: =SUMIFS('Individual Data'!$AC$7:$AC$5545,'Individual Data'!$V$7:$V$5545,'Hat by PBT'!$B10,'Individual Data'!$Z$7:$Z$5545,'Hat by PBT'!E$7,'Individual Data'!$R$7:$R$5545,'Hat by PBT'!$C10,'Individual Data'!$N$7:$N$5545,'Hat by PBT'!$B$6) -> 0 | F10: =SUMIFS('Individual Data'!$AC$7:$AC$5545,'Individual Data'!$V$7:$V$5545,'Hat by PBT'!$B10,'Individual Data'!$Z$7:$Z$5545,'Hat by PBT'!F$7,'Individual Data'!$R$7:$R$5545,'Hat by PBT'!$C10,'Individual Data'!$N$7:$N$5545,'Hat by PBT'!$B$6) -> 0 | G10: =SUMIFS('Individual Data'!$AC$7:$AC$5545,'Individual Data'!$V$7:$V$5545,'Hat by PBT'!$B10,'Individual Data'!$Z$7:$Z$5545,'Hat by PBT'!G$7,'Individual Data'!$R$7:$R$5545,'Hat by PBT'!$C10,'Individual Data'!$N$7:$N$5545,'Hat by PBT'!$B$6) -> 0 | H10: =SUMIFS('Individual Data'!$AC$7:$AC$5545,'Individual Data'!$V$7:$V$5545,'Hat by PBT'!$B10,'Individual Data'!$Z$7:$Z$5545,'Hat by PBT'!H$7,'Individual Data'!$R$7:$R$5545,'Hat by PBT'!$C10,'Individual Data'!$N$7:$N$5545,'Hat by PBT'!$B$6) -> 0 | I10: =SUMIFS('Individual Data'!$AC$7:$AC$5545,'Individual Data'!$V$7:$V$5545,'Hat by PBT'!$B10,'Individual Data'!$Z$7:$Z$5545,'Hat by PBT'!I$7,'Individual Data'!$R$7:$R$5545,'Hat by PBT'!$C10,'Individual Data'!$N$7:$N$5545,'Hat by PBT'!$B$6) -> 0 | J10: =SUMIFS('Individual Data'!$AC$7:$AC$5545,'Individual Data'!$V$7:$V$5545,'Hat by PBT'!$B10,'Individual Data'!$Z$7:$Z$5545,'Hat by PBT'!J$7,'Individual Data'!$R$7:$R$5545,'Hat by PBT'!$C10,'Individual Data'!$N$7:$N$5545,'Hat by PBT'!$B$6) -> 64.499854 | K10: =SUMIFS('Individual Data'!$AC$7:$AC$5545,'Individual Data'!$V$7:$V$5545,'Hat by PBT'!$B10,'Individual Data'!$Z$7:$Z$5545,'Hat by PBT'!K$7,'Individual Data'!$R$7:$R$5545,'Hat by PBT'!$C10,'Individual Data'!$N$7:$N$5545,'Hat by PBT'!$B$6) -> 183.5365 | ... P10: =SUMIFS('Individual Data'!$AC$7:$AC$5545,'Individual Data'!$V$7:$V$5545,'Hat by PBT'!$B10,'Individual Data'!$Z$7:$Z$5545,'Hat by PBT'!P$7,'Individual Data'!$R$7:$R$5545,'Hat by PBT'!$C10,'Individual Data'!$N$7:$N$5545,'Hat by PBT'!$B$6) -> 0 | R10: =SUM(D10:F10) -> 0 | S10: =SUM(G10:P10) -> 424.91006 | U10: =$U$3-C10 -> 2019 | V10: =B10 -> CJA1 | W10: SR | X10: =SUMIFS('cwt rel info'!$A$6:$A$317,'cwt rel info'!$D$6:$D$317,'Hat by PBT'!U10,'cwt rel info'!$E$6:$E$317,'Hat by PBT'!V10) -> 220195 | Y10: =R10+S10 -> 424.91006 | Z10: =S90 -> 82.586896 | AA10: =R90 -> 0 | AB10: =VLOOKUP(V10,'Individual Data'!$V$6:$AD$5545,9,FALSE) -> Abv | AC10: =IF(AB10="blw",Y10*(1-$Z$4),Y10*(1-$Z$3)) -> 414.71222 | AD10: =IF(AB10="blw",Z10*(1-$Z$4),Z10*(1-$Z$3)) -> 80.604811 | AE10: =IF(AB10="blw",AA10*(1-$AA$4),AA10*(1-$AA$3)) -> 0
A11: OtsLYON19S_1 | B11: CJA2 | C11: 5 | D11: =SUMIFS('Individual Data'!$AC$7:$AC$5545,'Individual Data'!$V$7:$V$5545,'Hat by PBT'!$B11,'Individual Data'!$Z$7:$Z$5545,'Hat by PBT'!D$7,'Individual Data'!$R$7:$R$5545,'Hat by PBT'!$C11,'Individual Data'!$N$7:$N$5545,'Hat by PBT'!$B$6) -> 0 | E11: =SUMIFS('Individual Data'!$AC$7:$AC$5545,'Individual Data'!$V$7:$V$5545,'Hat by PBT'!$B11,'Individual Data'!$Z$7:$Z$5545,'Hat by PBT'!E$7,'Individual Data'!$R$7:$R$5545,'Hat by PBT'!$C11,'Individual Data'!$N$7:$N$5545,'Hat by PBT'!$B$6) -> 0 | F11: =SUMIFS('Individual Data'!$AC$7:$AC$5545,'Individual Data'!$V$7:$V$5545,'Hat by PBT'!$B11,'Individual Data'!$Z$7:$Z$5545,'Hat by PBT'!F$7,'Individual Data'!$R$7:$R$5545,'Hat by PBT'!$C11,'Individual Data'!$N$7:$N$5545,'Hat by PBT'!$B$6) -> 0 | G11: =SUMIFS('Individual Data'!$AC$7:$AC$5545,'Individual Data'!$V$7:$V$5545,'Hat by PBT'!$B11,'Individual Data'!$Z$7:$Z$5545,'Hat by PBT'!G$7,'Individual Data'!$R$7:$R$5545,'Hat by PBT'!$C11,'Individual Data'!$N$7:$N$5545,'Hat by PBT'!$B$6) -> 0 | H11: =SUMIFS('Individual Data'!$AC$7:$AC$5545,'Individual Data'!$V$7:$V$5545,'Hat by PBT'!$B11,'Individual Data'!$Z$7:$Z$5545,'Hat by PBT'!H$7,'Individual Data'!$R$7:$R$5545,'Hat by PBT'!$C11,'Individual Data'!$N$7:$N$5545,'Hat by PBT'!$B$6) -> 0 | I11: =SUMIFS('Individual Data'!$AC$7:$AC$5545,'Individual Data'!$V$7:$V$5545,'Hat by PBT'!$B11,'Individual Data'!$Z$7:$Z$5545,'Hat by PBT'!I$7,'Individual Data'!$R$7:$R$5545,'Hat by PBT'!$C11,'Individual Data'!$N$7:$N$5545,'Hat by PBT'!$B$6) -> 0 | J11: =SUMIFS('Individual Data'!$AC$7:$AC$5545,'Individual Data'!$V$7:$V$5545,'Hat by PBT'!$B11,'Individual Data'!$Z$7:$Z$5545,'Hat by PBT'!J$7,'Individual Data'!$R$7:$R$5545,'Hat by PBT'!$C11,'Individual Data'!$N$7:$N$5545,'Hat by PBT'!$B$6) -> 0 | K11: =SUMIFS('Individual Data'!$AC$7:$AC$5545,'Individual Data'!$V$7:$V$5545,'Hat by PBT'!$B11,'Individual Data'!$Z$7:$Z$5545,'Hat by PBT'!K$7,'Individual Data'!$R$7:$R$5545,'Hat by PBT'!$C11,'Individual Data'!$N$7:$N$5545,'Hat by PBT'!$B$6) -> 84.112963 | ... P11: =SUMIFS('Individual Data'!$AC$7:$AC$5545,'Individual Data'!$V$7:$V$5545,'Hat by PBT'!$B11,'Individual Data'!$Z$7:$Z$5545,'Hat by PBT'!P$7,'Individual Data'!$R$7:$R$5545,'Hat by PBT'!$C11,'Individual Data'!$N$7:$N$5545,'Hat by PBT'!$B$6) -> 0 | R11: =SUM(D11:F11) -> 0 | S11: =SUM(G11:P11) -> 199.92355 | U11: =$U$3-C11 -> 2019 | V11: =B11 -> CJA2 | W11: SR | X11: =SUMIFS('cwt rel info'!$A$6:$A$317,'cwt rel info'!$D$6:$D$317,'Hat by PBT'!U11,'cwt rel info'!$E$6:$E$317,'Hat by PBT'!V11) -> 220196 | Y11: =R11+S11 -> 199.92355 | Z11: =S91 -> 32.228577 | AA11: =R91 -> 0 | AB11: =VLOOKUP(V11,'Individual Data'!$V$6:$AD$5545,9,FALSE) -> Abv | AC11: =IF(AB11="blw",Y11*(1-$Z$4),Y11*(1-$Z$3)) -> 195.12538 | AD11: =IF(AB11="blw",Z11*(1-$Z$4),Z11*(1-$Z$3)) -> 31.455091 | AE11: =IF(AB11="blw",AA11*(1-$AA$4),AA11*(1-$AA$3)) -> 0
