Workbook

Sheet Column Definitions
A1: Column name | B1: Definition
A2: Population | B2: IDFG Progeny database collection ID
A3: Individual | B3: IDFG Progeny database individual ID
A4: LGRScaleGeneticsIDLink | B4: Individual genetics ID in metadata provided to IDFG Eagle Genetics Lab
A5: DateSampled | B5: Date sampled at Lower Granite Dam
A6: PhenotypicSex | B6: Sex as identified at the Dam
A7: Length | B7: Fork Length
A8: Clip | B8: Adipose fin status - AD is for Ad-clipped, AI is for ad-intact
A9: Wire | B9: 1 if CWT present, NA if absent
A10: GenComments | B10: Lists all genetic duplicates and samples that failed to genotype
A11: GenSex | B11: Genetic sex
A12: GenPa | B12: IDFG Progeny database ID of the PBT assigned sire
... A17: RepUnitProb | B17: Probability of assignment to the given GSI reporting unit
A21: BY - Deleted records of 3 summer chnk: 2 from PahFH and 1 from Powel
A22: BY - changed unknown clips (NA) to AD for all LFH yrlg and PRH fish. Changed about 15 records since these groups are all clipped at released
A23: removed one minijack <30 cm
A24: BY- changed unknown sex fish based on sex ratio at FL pools (changed text red)
B25: 62 cm - 10% F: changed 17 "U" records to 2 F and 15 M
B26: 67 cm - 30% F: changed 22 "U" records to 6 F and 16 M
B27: 72 cm - 50% F: changed 6 "U" records to 3 F and 3 M
A28: Changed 3 unknown clip records
B29: 58% of fish were AI, so changed 3 records to 2 AI and 1 AD (changed text red)

Sheet pvt tbl
A2: PopName | B2: (Multiple Items)
B4: Clip
B5: AD | C5: AI | D5: Grand Total
A6: Sum of PBT geno rate expansion | B6: 18465.909 | C6: 21107.955 | D6: 39573.864

Sheet Individual Data
W1: sum | Y1: sum | Z1: night passage rate | AA1: sum @ LGR | AD1: fallback/reassension | AI1: fallback only
R2: Run year | W2: =SUM(W6:W3142) -> 3137 | Y2: =SUM(Y6:Y3142) -> 16667.771 | AA2: =SUM(AA6:AA3142) -> 53490.452 | AE2: jack | AF2: adlt | AJ2: jack | AK2: adlt
D3: 44803 | R3: 2022 | X3: 60% period | Y3: 0.576 | AA3: =1/9 -> 0.11111111 | AD3: abv | AE3: 0.06 | AF3: 0.04 | AI3: abv | AJ3: 0 | AK3: 0
X4: 18% period | Y4: 0.176 | Z4: 0.0082 | AA4: =1/3 -> 0.33333333 | AD4: blw | AE4: 0.75 | AF4: 0.45 | AI4: blw | AJ4: 0.58 | AK4: 0.37
A5: Population | B5: Individual | C5: LGRScaleGeneticsIDLink | D5: DateSampled | E5: sample rate | F5: PhenotypicSex | G5: FL mm | H5: FL cm | I5: Clip | J5: Wire | K5: GenComments | L5: GenSex | M5: best sex | N5: GenPa | O5: GenMa | P5: PopName | Q5: agePBT | R5: Brd Yr | S5: GSIRepUnit | T5: RepUnitProb | U5: Final group | V5: Tag rate | W5: count | X5: pooled FL | Y5: trap rate expansion | Z5: Night passage expansion | AA5: PBT geno rate expansion | AB5: rel abv/blw LGR
A6: OtsLGRF22S | B6: OtsLGRF22S_0002 | C6: C-00002 | D6: 44791 | E6: =IF(D6<=$D$3,60,18) -> 60 | F6: M | G6: 910 | H6: =G6/10 -> 91 | I6: AD | J6: 1 | L6: M | M6: =IF(L6="U",F6,L6) -> M | N6: OtsLYON18S_1_0133 | O6: OtsLYON18S_1_0282 | P6: OtsLYON18S_1 | Q6: 4 | R6: =IFERROR($R$3-Q6,"U") -> 2018 | S6: NA | T6: NA | U6: BCAe | V6: =VLOOKUP(P6,'PBT Tag Rates'!$B$5:$E$34,4,FALSE) -> 0.80551598 | W6: 1 | X6: =IFERROR(LOOKUP(H6,{30,43,48,53,58,63,68,73,78,83,88,93,97},{42,47,52,57,62,67,72,77,82,87,92,99,100}),999) -> 92 | Y6: =IF(D6<$D$3,W6/$Y$3,W6/$Y$4) -> 1.7361111 | Z6: =Y6*(1+$Z$4) -> 1.7503472 | AA6: =IF(D6<$D$3,Z6/$AA$3,Z6/$AA$4) -> 15.753125 | AB6: abv
A7: OtsLGRF22S | B7: OtsLGRF22S_0010 | C7: C-00010 | D7: 44791 | E7: =IF(D7<=$D$3,60,18) -> 60 | F7: U | G7: 650 | H7: =G7/10 -> 65 | I7: AI | J7: NA | L7: M | M7: =IF(L7="U",F7,L7) -> M | N7: OtsLYON19S_1_0141 | O7: OtsLYON19S_1_0227 | P7: OtsLYON19S_1 | Q7: 3 | R7: =IFERROR($R$3-Q7,"U") -> 2019 | S7: NA | T7: NA | U7: BCAe | V7: =VLOOKUP(P7,'PBT Tag Rates'!$B$5:$E$34,4,FALSE) -> 0.95971981 | W7: 1 | X7: =IFERROR(LOOKUP(H7,{30,43,48,53,58,63,68,73,78,83,88,93,97},{42,47,52,57,62,67,72,77,82,87,92,99,100}),999) -> 67 | Y7: =IF(D7<$D$3,W7/$Y$3,W7/$Y$4) -> 1.7361111 | Z7: =Y7*(1+$Z$4) -> 1.7503472 | AA7: =IF(D7<$D$3,Z7/$AA$3,Z7/$AA$4) -> 15.753125 | AB7: abv
A8: OtsLGRF22S | B8: OtsLGRF22S_0019 | C8: C-00019 | D8: 44791 | E8: =IF(D8<=$D$3,60,18) -> 60 | F8: M | G8: 840 | H8: =G8/10 -> 84 | I8: AI | J8: NA | L8: M | M8: =IF(L8="U",F8,L8) -> M | N8: NA | O8: NA | P8: Unassigned | Q8: NA | R8: =IFERROR($R$3-Q8,"U") -> U | S8: FALL | T8: 1 | U8: Unassigned | V8: =VLOOKUP(P8,'PBT Tag Rates'!$B$5:$E$34,4,FALSE) -> #N/A | W8: 1 | X8: =IFERROR(LOOKUP(H8,{30,43,48,53,58,63,68,73,78,83,88,93,97},{42,47,52,57,62,67,72,77,82,87,92,99,100}),999) -> 87 | Y8: =IF(D8<$D$3,W8/$Y$3,W8/$Y$4) -> 1.7361111 | Z8: =Y8*(1+$Z$4) -> 1.7503472 | AA8: =IF(D8<$D$3,Z8/$AA$3,Z8/$AA$4) -> 15.753125 | AB8: abv
A9: OtsLGRF22S | B9: OtsLGRF22S_0028 | C9: C-00028 | D9: 44791 | E9: =IF(D9<=$D$3,60,18) -> 60 | F9: F | G9: 810 | H9: =G9/10 -> 81 | I9: AD | J9: 1 | L9: F | M9: =IF(L9="U",F9,L9) -> F | N9: OtsNPFH18S_1_2308 | O9: OtsNPFH18S_1_2062 | P9: OtsNPFH18S_1 | Q9: 4 | R9: =IFERROR($R$3-Q9,"U") -> 2018 | S9: NA | T9: NA | U9: LGA | V9: =VLOOKUP(P9,'PBT Tag Rates'!$B$5:$E$34,4,FALSE) -> 0.96828397 | W9: 1 | X9: =IFERROR(LOOKUP(H9,{30,43,48,53,58,63,68,73,78,83,88,93,97},{42,47,52,57,62,67,72,77,82,87,92,99,100}),999) -> 82 | Y9: =IF(D9<$D$3,W9/$Y$3,W9/$Y$4) -> 1.7361111 | Z9: =Y9*(1+$Z$4) -> 1.7503472 | AA9: =IF(D9<$D$3,Z9/$AA$3,Z9/$AA$4) -> 15.753125 | AB9: abv
A10: OtsLGRF22S | B10: OtsLGRF22S_0037 | C10: C-00037 | D10: 44791 | E10: =IF(D10<=$D$3,60,18) -> 60 | F10: F | G10: 820 | H10: =G10/10 -> 82 | I10: AI | J10: NA | L10: F | M10: =IF(L10="U",F10,L10) -> F | N10: NA | O10: NA | P10: Unassigned | Q10: NA | R10: =IFERROR($R$3-Q10,"U") -> U | S10: FALL | T10: 1 | U10: Unassigned | V10: =VLOOKUP(P10,'PBT Tag Rates'!$B$5:$E$34,4,FALSE) -> #N/A | W10: 1 | X10: =IFERROR(LOOKUP(H10,{30,43,48,53,58,63,68,73,78,83,88,93,97},{42,47,52,57,62,67,72,77,82,87,92,99,100}),999) -> 82 | Y10: =IF(D10<$D$3,W10/$Y$3,W10/$Y$4) -> 1.7361111 | Z10: =Y10*(1+$Z$4) -> 1.7503472 | AA10: =IF(D10<$D$3,Z10/$AA$3,Z10/$AA$4) -> 15.753125 | AB10: abv
A11: OtsLGRF22S | B11: OtsLGRF22S_0046 | C11: C-00046 | D11: 44791 | E11: =IF(D11<=$D$3,60,18) -> 60 | F11: F | G11: 760 | H11: =G11/10 -> 76 | I11: AI | J11: NA | L11: F | M11: =IF(L11="U",F11,L11) -> F | N11: OtsLYON18S_1_0707 | O11: OtsLYON18S_1_0550 | P11: OtsLYON18S_1 | Q11: 4 | R11: =IFERROR($R$3-Q11,"U") -> 2018 | S11: NA | T11: NA | U11: BCAe | V11: =VLOOKUP(P11,'PBT Tag Rates'!$B$5:$E$34,4,FALSE) -> 0.80551598 | W11: 1 | X11: =IFERROR(LOOKUP(H11,{30,43,48,53,58,63,68,73,78,83,88,93,97},{42,47,52,57,62,67,72,77,82,87,92,99,100}),999) -> 77 | Y11: =IF(D11<$D$3,W11/$Y$3,W11/$Y$4) -> 1.7361111 | Z11: =Y11*(1+$Z$4) -> 1.7503472 | AA11: =IF(D11<$D$3,Z11/$AA$3,Z11/$AA$4) -> 15.753125 | AB11: abv
A12: OtsLGRF22S | B12: OtsLGRF22S_0055 | C12: C-00055 | D12: 44791 | E12: =IF(D12<=$D$3,60,18) -> 60 | F12: F | G12: 810 | H12: =G12/10 -> 81 | I12: AI | J12: NA | L12: F | M12: =IF(L12="U",F12,L12) -> F | N12: OtsLYON18S_1_0768 | O12: OtsLYON18S_1_0923 | P12: OtsLYON18S_1 | Q12: 4 | R12: =IFERROR($R$3-Q12,"U") -> 2018 | S12: NA | T12: NA | U12: LFHs | V12: =VLOOKUP(P12,'PBT Tag Rates'!$B$5:$E$34,4,FALSE) -> 0.80551598 | W12: 1 | X12: =IFERROR(LOOKUP(H12,{30,43,48,53,58,63,68,73,78,83,88,93,97},{42,47,52,57,62,67,72,77,82,87,92,99,100}),999) -> 82 | Y12: =IF(D12<$D$3,W12/$Y$3,W12/$Y$4) -> 1.7361111 | Z12: =Y12*(1+$Z$4) -> 1.7503472 | AA12: =IF(D12<$D$3,Z12/$AA$3,Z12/$AA$4) -> 15.753125 | AB12: blw
A13: OtsLGRF22S | B13: OtsLGRF22S_0064 | C13: C-00064 | D13: 44791 | E13: =IF(D13<=$D$3,60,18) -> 60 | F13: F | G13: 740 | H13: =G13/10 -> 74 | I13: AI | J13: NA | L13: F | M13: =IF(L13="U",F13,L13) -> F | N13: OtsLYON18S_1_1377 | O13: OtsLYON18S_1_1745 | P13: OtsLYON18S_1 | Q13: 4 | R13: =IFERROR($R$3-Q13,"U") -> 2018 | S13: NA | T13: NA | U13: LFH Ukn | V13: =VLOOKUP(P13,'PBT Tag Rates'!$B$5:$E$34,4,FALSE) -> 0.80551598 | W13: 1 | X13: =IFERROR(LOOKUP(H13,{30,43,48,53,58,63,68,73,78,83,88,93,97},{42,47,52,57,62,67,72,77,82,87,92,99,100}),999) -> 77 | Y13: =IF(D13<$D$3,W13/$Y$3,W13/$Y$4) -> 1.7361111 | Z13: =Y13*(1+$Z$4) -> 1.7503472 | AA13: =IF(D13<$D$3,Z13/$AA$3,Z13/$AA$4) -> 15.753125 | AB13: blw
A14: OtsLGRF22S | B14: OtsLGRF22S_0073 | C14: C-00073 | D14: 44791 | E14: =IF(D14<=$D$3,60,18) -> 60 | F14: F | G14: 810 | H14: =G14/10 -> 81 | I14: AI | J14: NA | L14: F | M14: =IF(L14="U",F14,L14) -> F | N14: OtsNPFH18S_1_3330 | O14: OtsNPFH18S_1_3037 | P14: OtsNPFH18S_1 | Q14: 4 | R14: =IFERROR($R$3-Q14,"U") -> 2018 | S14: NA | T14: NA | U14: LGA | V14: =VLOOKUP(P14,'PBT Tag Rates'!$B$5:$E$34,4,FALSE) -> 0.96828397 | W14: 1 | X14: =IFERROR(LOOKUP(H14,{30,43,48,53,58,63,68,73,78,83,88,93,97},{42,47,52,57,62,67,72,77,82,87,92,99,100}),999) -> 82 | Y14: =IF(D14<$D$3,W14/$Y$3,W14/$Y$4) -> 1.7361111 | Z14: =Y14*(1+$Z$4) -> 1.7503472 | AA14: =IF(D14<$D$3,Z14/$AA$3,Z14/$AA$4) -> 15.753125 | AB14: abv
A15: OtsLGRF22S | B15: OtsLGRF22S_0082 | C15: C-00082 | D15: 44791 | E15: =IF(D15<=$D$3,60,18) -> 60 | F15: M | G15: 830 | H15: =G15/10 -> 83 | I15: AI | J15: NA | L15: M | M15: =IF(L15="U",F15,L15) -> M | N15: OtsLYON18S_1_1358 | O15: OtsLYON18S_1_1724 | P15: OtsLYON18S_1 | Q15: 4 | R15: =IFERROR($R$3-Q15,"U") -> 2018 | S15: NA | T15: NA | U15: LFH Ukn | V15: =VLOOKUP(P15,'PBT Tag Rates'!$B$5:$E$34,4,FALSE) -> 0.80551598 | W15: 1 | X15: =IFERROR(LOOKUP(H15,{30,43,48,53,58,63,68,73,78,83,88,93,97},{42,47,52,57,62,67,72,77,82,87,92,99,100}),999) -> 87 | Y15: =IF(D15<$D$3,W15/$Y$3,W15/$Y$4) -> 1.7361111 | Z15: =Y15*(1+$Z$4) -> 1.7503472 | AA15: =IF(D15<$D$3,Z15/$AA$3,Z15/$AA$4) -> 15.753125 | AB15: blw
A16: OtsLGRF22S | B16: OtsLGRF22S_0091 | C16: C-00091 | D16: 44791 | E16: =IF(D16<=$D$3,60,18) -> 60 | F16: F | G16: 760 | H16: =G16/10 -> 76 | I16: AI | J16: NA | L16: F | M16: =IF(L16="U",F16,L16) -> F | N16: OtsNPFH18S_1_6322 | O16: OtsNPFH18S_1_6030 | P16: OtsNPFH18S_1 | Q16: 4 | R16: =IFERROR($R$3-Q16,"U") -> 2018 | S16: NA | T16: NA | U16: LGA | V16: =VLOOKUP(P16,'PBT Tag Rates'!$B$5:$E$34,4,FALSE) -> 0.96828397 | W16: 1 | X16: =IFERROR(LOOKUP(H16,{30,43,48,53,58,63,68,73,78,83,88,93,97},{42,47,52,57,62,67,72,77,82,87,92,99,100}),999) -> 77 | Y16: =IF(D16<$D$3,W16/$Y$3,W16/$Y$4) -> 1.7361111 | Z16: =Y16*(1+$Z$4) -> 1.7503472 | AA16: =IF(D16<$D$3,Z16/$AA$3,Z16/$AA$4) -> 15.753125 | AB16: abv
A17: OtsLGRF22S | B17: OtsLGRF22S_0100 | C17: C-00100 | D17: 44792 | E17: =IF(D17<=$D$3,60,18) -> 60 | F17: M | G17: 790 | H17: =G17/10 -> 79 | I17: AD | J17: 1 | L17: M | M17: =IF(L17="U",F17,L17) -> M | N17: OtsLYON18S_1_0735 | O17: OtsLYON18S_1_0840 | P17: OtsLYON18S_1 | Q17: 4 | R17: =IFERROR($R$3-Q17,"U") -> 2018 | S17: NA | T17: NA | U17: CJAe | V17: =VLOOKUP(P17,'PBT Tag Rates'!$B$5:$E$34,4,FALSE) -> 0.80551598 | W17: 1 | X17: =IFERROR(LOOKUP(H17,{30,43,48,53,58,63,68,73,78,83,88,93,97},{42,47,52,57,62,67,72,77,82,87,92,99,100}),999) -> 82 | Y17: =IF(D17<$D$3,W17/$Y$3,W17/$Y$4) -> 1.7361111 | Z17: =Y17*(1+$Z$4) -> 1.7503472 | AA17: =IF(D17<$D$3,Z17/$AA$3,Z17/$AA$4) -> 15.753125 | AB17: abv
A18: OtsLGRF22S | B18: OtsLGRF22S_0109 | C18: C-00109 | D18: 44792 | E18: =IF(D18<=$D$3,60,18) -> 60 | F18: M | G18: 860 | H18: =G18/10 -> 86 | I18: AD | J18: 1 | L18: M | M18: =IF(L18="U",F18,L18) -> M | N18: NA | O18: NA | P18: Unassigned | Q18: NA | R18: =IFERROR($R$3-Q18,"U") -> U | S18: FALL | T18: 1 | U18: Unassigned AD | V18: =VLOOKUP(P18,'PBT Tag Rates'!$B$5:$E$34,4,FALSE) -> #N/A | W18: 1 | X18: =IFERROR(LOOKUP(H18,{30,43,48,53,58,63,68,73,78,83,88,93,97},{42,47,52,57,62,67,72,77,82,87,92,99,100}),999) -> 87 | Y18: =IF(D18<$D$3,W18/$Y$3,W18/$Y$4) -> 1.7361111 | Z18: =Y18*(1+$Z$4) -> 1.7503472 | AA18: =IF(D18<$D$3,Z18/$AA$3,Z18/$AA$4) -> 15.753125 | AB18: abv
A19: OtsLGRF22S | B19: OtsLGRF22S_0118 | C19: C-00118 | D19: 44792 | E19: =IF(D19<=$D$3,60,18) -> 60 | F19: M | G19: 850 | H19: =G19/10 -> 85 | I19: AI | J19: NA | L19: M | M19: =IF(L19="U",F19,L19) -> M | N19: OtsLYON18S_1_0102 | O19: OtsLYON18S_1_0084 | P19: OtsLYON18S_1 | Q19: 4 | R19: =IFERROR($R$3-Q19,"U") -> 2018 | S19: NA | T19: NA | U19: PLAe | V19: =VLOOKUP(P19,'PBT Tag Rates'!$B$5:$E$34,4,FALSE) -> 0.80551598 | W19: 1 | X19: =IFERROR(LOOKUP(H19,{30,43,48,53,58,63,68,73,78,83,88,93,97},{42,47,52,57,62,67,72,77,82,87,92,99,100}),999) -> 87 | Y19: =IF(D19<$D$3,W19/$Y$3,W19/$Y$4) -> 1.7361111 | Z19: =Y19*(1+$Z$4) -> 1.7503472 | AA19: =IF(D19<$D$3,Z19/$AA$3,Z19/$AA$4) -> 15.753125 | AB19: abv
A20: OtsLGRF22S | B20: OtsLGRF22S_0127 | C20: C-00127 | D20: 44792 | E20: =IF(D20<=$D$3,60,18) -> 60 | F20: M | G20: 670 | H20: =G20/10 -> 67 | I20: AD | J20: 1 | L20: M | M20: =IF(L20="U",F20,L20) -> M | N20: OtsLYON19S_1_0124 | O20: OtsLYON19S_1_0071 | P20: OtsLYON19S_1 | Q20: 3 | R20: =IFERROR($R$3-Q20,"U") -> 2019 | S20: NA | T20: NA | U20: PLAe | V20: =VLOOKUP(P20,'PBT Tag Rates'!$B$5:$E$34,4,FALSE) -> 0.95971981 | W20: 1 | X20: =IFERROR(LOOKUP(H20,{30,43,48,53,58,63,68,73,78,83,88,93,97},{42,47,52,57,62,67,72,77,82,87,92,99,100}),999) -> 67 | Y20: =IF(D20<$D$3,W20/$Y$3,W20/$Y$4) -> 1.7361111 | Z20: =Y20*(1+$Z$4) -> 1.7503472 | AA20: =IF(D20<$D$3,Z20/$AA$3,Z20/$AA$4) -> 15.753125 | AB20: abv
A21: OtsLGRF22S | B21: OtsLGRF22S_0136 | C21: C-00136 | D21: 44792 | E21: =IF(D21<=$D$3,60,18) -> 60 | F21: F | G21: 710 | H21: =G21/10 -> 71 | I21: AI | J21: NA | L21: F | M21: =IF(L21="U",F21,L21) -> F | N21: NA | O21: NA | P21: Unassigned | Q21: NA | R21: =IFERROR($R$3-Q21,"U") -> U | S21: FALL | T21: 1 | U21: Unassigned | V21: =VLOOKUP(P21,'PBT Tag Rates'!$B$5:$E$34,4,FALSE) -> #N/A | W21: 1 | X21: =IFERROR(LOOKUP(H21,{30,43,48,53,58,63,68,73,78,83,88,93,97},{42,47,52,57,62,67,72,77,82,87,92,99,100}),999) -> 72 | Y21: =IF(D21<$D$3,W21/$Y$3,W21/$Y$4) -> 1.7361111 | Z21: =Y21*(1+$Z$4) -> 1.7503472 | AA21: =IF(D21<$D$3,Z21/$AA$3,Z21/$AA$4) -> 15.753125 | AB21: abv
A22: OtsLGRF22S | B22: OtsLGRF22S_0145 | C22: C-00145 | D22: 44792 | E22: =IF(D22<=$D$3,60,18) -> 60 | F22: U | G22: 610 | H22: =G22/10 -> 61 | I22: AD | J22: 1 | L22: M | M22: =IF(L22="U",F22,L22) -> M | N22: NA | O22: NA | P22: Unassigned | Q22: NA | R22: =IFERROR($R$3-Q22,"U") -> U | S22: FALL | T22: 1 | U22: Unassigned AD | V22: =VLOOKUP(P22,'PBT Tag Rates'!$B$5:$E$34,4,FALSE) -> #N/A | W22: 1 | X22: =IFERROR(LOOKUP(H22,{30,43,48,53,58,63,68,73,78,83,88,93,97},{42,47,52,57,62,67,72,77,82,87,92,99,100}),999) -> 62 | Y22: =IF(D22<$D$3,W22/$Y$3,W22/$Y$4) -> 1.7361111 | Z22: =Y22*(1+$Z$4) -> 1.7503472 | AA22: =IF(D22<$D$3,Z22/$AA$3,Z22/$AA$4) -> 15.753125 | AB22: abv
A23: OtsLGRF22S | B23: OtsLGRF22S_0154 | C23: C-00154 | D23: 44792 | E23: =IF(D23<=$D$3,60,18) -> 60 | F23: F | G23: 880 | H23: =G23/10 -> 88 | I23: AI | J23: NA | L23: F | M23: =IF(L23="U",F23,L23) -> F | N23: OtsNPFH17S_1_4336 | O23: OtsNPFH17S_1_4110 | P23: OtsNPFH17S_1 | Q23: 5 | R23: =IFERROR($R$3-Q23,"U") -> 2017 | S23: NA | T23: NA | U23: NPTH | V23: =VLOOKUP(P23,'PBT Tag Rates'!$B$5:$E$34,4,FALSE) -> 0.98821807 | W23: 1 | X23: =IFERROR(LOOKUP(H23,{30,43,48,53,58,63,68,73,78,83,88,93,97},{42,47,52,57,62,67,72,77,82,87,92,99,100}),999) -> 92 | Y23: =IF(D23<$D$3,W23/$Y$3,W23/$Y$4) -> 1.7361111 | Z23: =Y23*(1+$Z$4) -> 1.7503472 | AA23: =IF(D23<$D$3,Z23/$AA$3,Z23/$AA$4) -> 15.753125 | AB23: abv
A24: OtsLGRF22S | B24: OtsLGRF22S_0163 | C24: C-00163 | D24: 44792 | E24: =IF(D24<=$D$3,60,18) -> 60 | F24: M | G24: 760 | H24: =G24/10 -> 76 | I24: AI | J24: NA | L24: F | M24: =IF(L24="U",F24,L24) -> F | N24: OtsLYON18S_1_0109 | O24: OtsLYON18S_1_0033 | P24: OtsLYON18S_1 | Q24: 4 | R24: =IFERROR($R$3-Q24,"U") -> 2018 | S24: NA | T24: NA | U24: PLAe | V24: =VLOOKUP(P24,'PBT Tag Rates'!$B$5:$E$34,4,FALSE) -> 0.80551598 | W24: 1 | X24: =IFERROR(LOOKUP(H24,{30,43,48,53,58,63,68,73,78,83,88,93,97},{42,47,52,57,62,67,72,77,82,87,92,99,100}),999) -> 77 | Y24: =IF(D24<$D$3,W24/$Y$3,W24/$Y$4) -> 1.7361111 | Z24: =Y24*(1+$Z$4) -> 1.7503472 | AA24: =IF(D24<$D$3,Z24/$AA$3,Z24/$AA$4) -> 15.753125 | AB24: abv
A25: OtsLGRF22S | B25: OtsLGRF22S_0172 | C25: C-00172 | D25: 44792 | E25: =IF(D25<=$D$3,60,18) -> 60 | F25: F | G25: 790 | H25: =G25/10 -> 79 | I25: AD | J25: 1 | L25: F | M25: =IF(L25="U",F25,L25) -> F | N25: OtsLYON18S_1_1353 | O25: OtsLYON18S_1_1789 | P25: OtsLYON18S_1 | Q25: 4 | R25: =IFERROR($R$3-Q25,"U") -> 2018 | S25: NA | T25: NA | U25: LFH Ukn | V25: =VLOOKUP(P25,'PBT Tag Rates'!$B$5:$E$34,4,FALSE) -> 0.80551598 | W25: 1 | X25: =IFERROR(LOOKUP(H25,{30,43,48,53,58,63,68,73,78,83,88,93,97},{42,47,52,57,62,67,72,77,82,87,92,99,100}),999) -> 82 | Y25: =IF(D25<$D$3,W25/$Y$3,W25/$Y$4) -> 1.7361111 | Z25: =Y25*(1+$Z$4) -> 1.7503472 | AA25: =IF(D25<$D$3,Z25/$AA$3,Z25/$AA$4) -> 15.753125 | AB25: blw
A26: OtsLGRF22S | B26: OtsLGRF22S_0181 | C26: C-00181 | D26: 44792 | E26: =IF(D26<=$D$3,60,18) -> 60 | F26: M | G26: 750 | H26: =G26/10 -> 75 | I26: AI | J26: NA | L26: M | M26: =IF(L26="U",F26,L26) -> M | N26: OtsNPFH18S_1_5326 | O26: OtsNPFH18S_1_5031 | P26: OtsNPFH18S_1 | Q26: 4 | R26: =IFERROR($R$3-Q26,"U") -> 2018 | S26: NA | T26: NA | U26: NPTH | V26: =VLOOKUP(P26,'PBT Tag Rates'!$B$5:$E$34,4,FALSE) -> 0.96828397 | W26: 1 | X26: =IFERROR(LOOKUP(H26,{30,43,48,53,58,63,68,73,78,83,88,93,97},{42,47,52,57,62,67,72,77,82,87,92,99,100}),999) -> 77 | Y26: =IF(D26<$D$3,W26/$Y$3,W26/$Y$4) -> 1.7361111 | Z26: =Y26*(1+$Z$4) -> 1.7503472 | AA26: =IF(D26<$D$3,Z26/$AA$3,Z26/$AA$4) -> 15.753125 | AB26: abv
A27: OtsLGRF22S | B27: OtsLGRF22S_0190 | C27: C-00190 | D27: 44792 | E27: =IF(D27<=$D$3,60,18) -> 60 | F27: M | G27: 850 | H27: =G27/10 -> 85 | I27: AI | J27: NA | L27: M | M27: =IF(L27="U",F27,L27) -> M | N27: OtsLYON18S_1_0726 | O27: OtsLYON18S_1_0856 | P27: OtsLYON18S_1 | Q27: 4 | R27: =IFERROR($R$3-Q27,"U") -> 2018 | S27: NA | T27: NA | U27: CJAe | V27: =VLOOKUP(P27,'PBT Tag Rates'!$B$5:$E$34,4,FALSE) -> 0.80551598 | W27: 1 | X27: =IFERROR(LOOKUP(H27,{30,43,48,53,58,63,68,73,78,83,88,93,97},{42,47,52,57,62,67,72,77,82,87,92,99,100}),999) -> 87 | Y27: =IF(D27<$D$3,W27/$Y$3,W27/$Y$4) -> 1.7361111 | Z27: =Y27*(1+$Z$4) -> 1.7503472 | AA27: =IF(D27<$D$3,Z27/$AA$3,Z27/$AA$4) -> 15.753125 | AB27: abv
A28: OtsLGRF22S | B28: OtsLGRF22S_0199 | C28: C-00199 | D28: 44792 | E28: =IF(D28<=$D$3,60,18) -> 60 | F28: F | G28: 750 | H28: =G28/10 -> 75 | I28: AD | J28: 1 | L28: F | M28: =IF(L28="U",F28,L28) -> F | N28: OtsNPFH18S_1_2308 | O28: OtsNPFH18S_1_2062 | P28: OtsNPFH18S_1 | Q28: 4 | R28: =IFERROR($R$3-Q28,"U") -> 2018 | S28: NA | T28: NA | U28: LGA | V28: =VLOOKUP(P28,'PBT Tag Rates'!$B$5:$E$34,4,FALSE) -> 0.96828397 | W28: 1 | X28: =IFERROR(LOOKUP(H28,{30,43,48,53,58,63,68,73,78,83,88,93,97},{42,47,52,57,62,67,72,77,82,87,92,99,100}),999) -> 77 | Y28: =IF(D28<$D$3,W28/$Y$3,W28/$Y$4) -> 1.7361111 | Z28: =Y28*(1+$Z$4) -> 1.7503472 | AA28: =IF(D28<$D$3,Z28/$AA$3,Z28/$AA$4) -> 15.753125 | AB28: abv
A29: OtsLGRF22S | B29: OtsLGRF22S_0208 | C29: C-00208 | D29: 44792 | E29: =IF(D29<=$D$3,60,18) -> 60 | F29: F | G29: 860 | H29: =G29/10 -> 86 | I29: AD | J29: 1 | L29: M | M29: =IF(L29="U",F29,L29) -> M | N29: OtsLYON18S_1_0735 | O29: OtsLYON18S_1_0840 | P29: OtsLYON18S_1 | Q29: 4 | R29: =IFERROR($R$3-Q29,"U") -> 2018 | S29: NA | T29: NA | U29: CJAe | V29: =VLOOKUP(P29,'PBT Tag Rates'!$B$5:$E$34,4,FALSE) -> 0.80551598 | W29: 1 | X29: =IFERROR(LOOKUP(H29,{30,43,48,53,58,63,68,73,78,83,88,93,97},{42,47,52,57,62,67,72,77,82,87,92,99,100}),999) -> 87 | Y29: =IF(D29<$D$3,W29/$Y$3,W29/$Y$4) -> 1.7361111 | Z29: =Y29*(1+$Z$4) -> 1.7503472 | AA29: =IF(D29<$D$3,Z29/$AA$3,Z29/$AA$4) -> 15.753125 | AB29: abv
A30: OtsLGRF22S | B30: OtsLGRF22S_0217 | C30: C-00217 | D30: 44793 | E30: =IF(D30<=$D$3,60,18) -> 60 | F30: M | G30: 740 | H30: =G30/10 -> 74 | I30: AI | J30: NA | L30: M | M30: =IF(L30="U",F30,L30) -> M | N30: OtsLYON18S_1_0731 | O30: OtsLYON18S_1_0851 | P30: OtsLYON18S_1 | Q30: 4 | R30: =IFERROR($R$3-Q30,"U") -> 2018 | S30: NA | T30: NA | U30: CJAe | V30: =VLOOKUP(P30,'PBT Tag Rates'!$B$5:$E$34,4,FALSE) -> 0.80551598 | W30: 1 | X30: =IFERROR(LOOKUP(H30,{30,43,48,53,58,63,68,73,78,83,88,93,97},{42,47,52,57,62,67,72,77,82,87,92,99,100}),999) -> 77 | Y30: =IF(D30<$D$3,W30/$Y$3,W30/$Y$4) -> 1.7361111 | Z30: =Y30*(1+$Z$4) -> 1.7503472 | AA30: =IF(D30<$D$3,Z30/$AA$3,Z30/$AA$4) -> 15.753125 | AB30: abv
A31: OtsLGRF22S | B31: OtsLGRF22S_0226 | C31: C-00226 | D31: 44793 | E31: =IF(D31<=$D$3,60,18) -> 60 | F31: U | G31: 660 | H31: =G31/10 -> 66 | I31: AD | J31: 1 | L31: M | M31: =IF(L31="U",F31,L31) -> M | N31: OtsLYON18S_1_2351 | O31: OtsLYON18S_1_2721 | P31: OtsLYON18S_1 | Q31: 4 | R31: =IFERROR($R$3-Q31,"U") -> 2018 | S31: NA | T31: NA | U31: LFHy | V31: =VLOOKUP(P31,'PBT Tag Rates'!$B$5:$E$34,4,FALSE) -> 0.80551598 | W31: 1 | X31: =IFERROR(LOOKUP(H31,{30,43,48,53,58,63,68,73,78,83,88,93,97},{42,47,52,57,62,67,72,77,82,87,92,99,100}),999) -> 67 | Y31: =IF(D31<$D$3,W31/$Y$3,W31/$Y$4) -> 1.7361111 | Z31: =Y31*(1+$Z$4) -> 1.7503472 | AA31: =IF(D31<$D$3,Z31/$AA$3,Z31/$AA$4) -> 15.753125 | AB31: blw
A32: OtsLGRF22S | B32: OtsLGRF22S_0235 | C32: C-00235 | D32: 44793 | E32: =IF(D32<=$D$3,60,18) -> 60 | F32: F | G32: 880 | H32: =G32/10 -> 88 | I32: AI | J32: NA | L32: F | M32: =IF(L32="U",F32,L32) -> F | N32: NA | O32: NA | P32: Unassigned | Q32: NA | R32: =IFERROR($R$3-Q32,"U") -> U | S32: FALL | T32: 1 | U32: Unassigned | V32: =VLOOKUP(P32,'PBT Tag Rates'!$B$5:$E$34,4,FALSE) -> #N/A | W32: 1 | X32: =IFERROR(LOOKUP(H32,{30,43,48,53,58,63,68,73,78,83,88,93,97},{42,47,52,57,62,67,72,77,82,87,92,99,100}),999) -> 92 | Y32: =IF(D32<$D$3,W32/$Y$3,W32/$Y$4) -> 1.7361111 | Z32: =Y32*(1+$Z$4) -> 1.7503472 | AA32: =IF(D32<$D$3,Z32/$AA$3,Z32/$AA$4) -> 15.753125 | AB32: abv
A33: OtsLGRF22S | B33: OtsLGRF22S_0244 | C33: C-00244 | D33: 44793 | E33: =IF(D33<=$D$3,60,18) -> 60 | F33: F | G33: 790 | H33: =G33/10 -> 79 | I33: AD | J33: 1 | L33: F | M33: =IF(L33="U",F33,L33) -> F | N33: OtsNPFH18S_1_4337 | O33: OtsNPFH18S_1_4090 | P33: OtsNPFH18S_1 | Q33: 4 | R33: =IFERROR($R$3-Q33,"U") -> 2018 | S33: NA | T33: NA | U33: NPTH | V33: =VLOOKUP(P33,'PBT Tag Rates'!$B$5:$E$34,4,FALSE) -> 0.96828397 | W33: 1 | X33: =IFERROR(LOOKUP(H33,{30,43,48,53,58,63,68,73,78,83,88,93,97},{42,47,52,57,62,67,72,77,82,87,92,99,100}),999) -> 82 | Y33: =IF(D33<$D$3,W33/$Y$3,W33/$Y$4) -> 1.7361111 | Z33: =Y33*(1+$Z$4) -> 1.7503472 | AA33: =IF(D33<$D$3,Z33/$AA$3,Z33/$AA$4) -> 15.753125 | AB33: abv
A34: OtsLGRF22S | B34: OtsLGRF22S_0253 | C34: C-00253 | D34: 44793 | E34: =IF(D34<=$D$3,60,18) -> 60 | F34: U | G34: 610 | H34: =G34/10 -> 61 | I34: AD | J34: 1 | L34: M | M34: =IF(L34="U",F34,L34) -> M | N34: OtsLYON19S_1_0714 | O34: OtsLYON19S_1_0814 | P34: OtsLYON19S_1 | Q34: 3 | R34: =IFERROR($R$3-Q34,"U") -> 2019 | S34: NA | T34: NA | U34: CJAe | V34: =VLOOKUP(P34,'PBT Tag Rates'!$B$5:$E$34,4,FALSE) -> 0.95971981 | W34: 1 | X34: =IFERROR(LOOKUP(H34,{30,43,48,53,58,63,68,73,78,83,88,93,97},{42,47,52,57,62,67,72,77,82,87,92,99,100}),999) -> 62 | Y34: =IF(D34<$D$3,W34/$Y$3,W34/$Y$4) -> 1.7361111 | Z34: =Y34*(1+$Z$4) -> 1.7503472 | AA34: =IF(D34<$D$3,Z34/$AA$3,Z34/$AA$4) -> 15.753125 | AB34: abv
A35: OtsLGRF22S | B35: OtsLGRF22S_0262 | C35: C-00262 | D35: 44793 | E35: =IF(D35<=$D$3,60,18) -> 60 | F35: F | G35: 730 | H35: =G35/10 -> 73 | I35: AD | J35: 1 | L35: F | M35: =IF(L35="U",F35,L35) -> F | N35: OtsLYON18S_1_0747 | O35: OtsLYON18S_1_0622 | P35: OtsLYON18S_1 | Q35: 4 | R35: =IFERROR($R$3-Q35,"U") -> 2018 | S35: NA | T35: NA | U35: LFHs | V35: =VLOOKUP(P35,'PBT Tag Rates'!$B$5:$E$34,4,FALSE) -> 0.80551598 | W35: 1 | X35: =IFERROR(LOOKUP(H35,{30,43,48,53,58,63,68,73,78,83,88,93,97},{42,47,52,57,62,67,72,77,82,87,92,99,100}),999) -> 77 | Y35: =IF(D35<$D$3,W35/$Y$3,W35/$Y$4) -> 1.7361111 | Z35: =Y35*(1+$Z$4) -> 1.7503472 | AA35: =IF(D35<$D$3,Z35/$AA$3,Z35/$AA$4) -> 15.753125 | AB35: blw
A36: OtsLGRF22S | B36: OtsLGRF22S_0271 | C36: C-00271 | D36: 44793 | E36: =IF(D36<=$D$3,60,18) -> 60 | F36: U | G36: 430 | H36: =G36/10 -> 43 | I36: AI | J36: NA | L36: M | M36: =IF(L36="U",F36,L36) -> M | N36: NA | O36: NA | P36: Unassigned | Q36: NA | R36: =IFERROR($R$3-Q36,"U") -> U | S36: FALL | T36: 1 | U36: Unassigned | V36: =VLOOKUP(P36,'PBT Tag Rates'!$B$5:$E$34,4,FALSE) -> #N/A | W36: 1 | X36: =IFERROR(LOOKUP(H36,{30,43,48,53,58,63,68,73,78,83,88,93,97},{42,47,52,57,62,67,72,77,82,87,92,99,100}),999) -> 47 | Y36: =IF(D36<$D$3,W36/$Y$3,W36/$Y$4) -> 1.7361111 | Z36: =Y36*(1+$Z$4) -> 1.7503472 | AA36: =IF(D36<$D$3,Z36/$AA$3,Z36/$AA$4) -> 15.753125 | AB36: abv
A37: OtsLGRF22S | B37: OtsLGRF22S_0280 | C37: C-00280 | D37: 44794 | E37: =IF(D37<=$D$3,60,18) -> 60 | F37: F | G37: 770 | H37: =G37/10 -> 77 | I37: AI | J37: NA | L37: M | M37: =IF(L37="U",F37,L37) -> M | N37: OtsLYON18S_1_0059 | O37: OtsLYON18S_1_0100 | P37: OtsLYON18S_1 | Q37: 4 | R37: =IFERROR($R$3-Q37,"U") -> 2018 | S37: NA | T37: NA | U37: PLAe | V37: =VLOOKUP(P37,'PBT Tag Rates'!$B$5:$E$34,4,FALSE) -> 0.80551598 | W37: 1 | X37: =IFERROR(LOOKUP(H37,{30,43,48,53,58,63,68,73,78,83,88,93,97},{42,47,52,57,62,67,72,77,82,87,92,99,100}),999) -> 77 | Y37: =IF(D37<$D$3,W37/$Y$3,W37/$Y$4) -> 1.7361111 | Z37: =Y37*(1+$Z$4) -> 1.7503472 | AA37: =IF(D37<$D$3,Z37/$AA$3,Z37/$AA$4) -> 15.753125 | AB37: abv
A38: OtsLGRF22S | B38: OtsLGRF22S_0289 | C38: C-00289 | D38: 44794 | E38: =IF(D38<=$D$3,60,18) -> 60 | F38: M | G38: 720 | H38: =G38/10 -> 72 | I38: AI | J38: NA | L38: M | M38: =IF(L38="U",F38,L38) -> M | N38: OtsLYON18S_1_0727 | O38: OtsLYON18S_1_0831 | P38: OtsLYON18S_1 | Q38: 4 | R38: =IFERROR($R$3-Q38,"U") -> 2018 | S38: NA | T38: NA | U38: CJAe | V38: =VLOOKUP(P38,'PBT Tag Rates'!$B$5:$E$34,4,FALSE) -> 0.80551598 | W38: 1 | X38: =IFERROR(LOOKUP(H38,{30,43,48,53,58,63,68,73,78,83,88,93,97},{42,47,52,57,62,67,72,77,82,87,92,99,100}),999) -> 72 | Y38: =IF(D38<$D$3,W38/$Y$3,W38/$Y$4) -> 1.7361111 | Z38: =Y38*(1+$Z$4) -> 1.7503472 | AA38: =IF(D38<$D$3,Z38/$AA$3,Z38/$AA$4) -> 15.753125 | AB38: abv
A39: OtsLGRF22S | B39: OtsLGRF22S_0298 | C39: C-00298 | D39: 44794 | E39: =IF(D39<=$D$3,60,18) -> 60 | F39: F | G39: 840 | H39: =G39/10 -> 84 | I39: AI | J39: NA | L39: F | M39: =IF(L39="U",F39,L39) -> F | N39: OtsNPFH18S_1_3333 | O39: OtsNPFH18S_1_3086 | P39: OtsNPFH18S_1 | Q39: 4 | R39: =IFERROR($R$3-Q39,"U") -> 2018 | S39: NA | T39: NA | U39: NLVA | V39: =VLOOKUP(P39,'PBT Tag Rates'!$B$5:$E$34,4,FALSE) -> 0.96828397 | W39: 1 | X39: =IFERROR(LOOKUP(H39,{30,43,48,53,58,63,68,73,78,83,88,93,97},{42,47,52,57,62,67,72,77,82,87,92,99,100}),999) -> 87 | Y39: =IF(D39<$D$3,W39/$Y$3,W39/$Y$4) -> 1.7361111 | Z39: =Y39*(1+$Z$4) -> 1.7503472 | AA39: =IF(D39<$D$3,Z39/$AA$3,Z39/$AA$4) -> 15.753125 | AB39: abv
A40: OtsLGRF22S | B40: OtsLGRF22S_0307 | C40: C-00307 | D40: 44794 | E40: =IF(D40<=$D$3,60,18) -> 60 | F40: F | G40: 860 | H40: =G40/10 -> 86 | I40: AD | J40: 1 | L40: F | M40: =IF(L40="U",F40,L40) -> F | N40: OtsNPFH18S_1_2307 | O40: OtsNPFH18S_1_2014 | P40: OtsNPFH18S_1 | Q40: 4 | R40: =IFERROR($R$3-Q40,"U") -> 2018 | S40: NA | T40: NA | U40: CFA | V40: =VLOOKUP(P40,'PBT Tag Rates'!$B$5:$E$34,4,FALSE) -> 0.96828397 | W40: 1 | X40: =IFERROR(LOOKUP(H40,{30,43,48,53,58,63,68,73,78,83,88,93,97},{42,47,52,57,62,67,72,77,82,87,92,99,100}),999) -> 87 | Y40: =IF(D40<$D$3,W40/$Y$3,W40/$Y$4) -> 1.7361111 | Z40: =Y40*(1+$Z$4) -> 1.7503472 | AA40: =IF(D40<$D$3,Z40/$AA$3,Z40/$AA$4) -> 15.753125 | AB40: abv
...

Sheet age-length prop
G1: sum check | I1: =SUM(D5:P6) -> 19018.318 | P1: =I1+I65 -> 53490.452 | T1: sum check | V1: =SUM(Q8:AC63) -> 19018.318 | AH1: sum check | AJ1: =SUM(AE8:AQ63) -> 16065.029 | AZ1: Fallback Reacension rate | BN1: sum check | BP1: =SUM(BK8:BW63) -> 2137.9731 | CD1: sum check | CF1: =SUM(CA8:CM61) -> 1178.6157 | CJ1: sum check | CL1: =CF1+CT1 -> 2137.9731 | CR1: sum check | CT1: =SUM(CO8:DA61) -> 959.35732
D2: proportion NG (no genotype) fish by FL | T2: all | V2: =SUM(Q8:AC63) -> 19018.318 | AJ2: =AJ1-BP1 -> 13927.055 | AV2: run year | BA2: adlt | BB2: jack | BD2: Final estimates of hatchery assigned fish by release site | BY2: count of AD and AI fish to est % AD, known hat fish
A3: AD | B3: NG | D3: =SUMIFS('Individual Data'!$AA$6:$AA$3142,'Individual Data'!$U$6:$U$3142,'age-length prop'!$B3,'Individual Data'!$I$6:$I$3142,'age-length prop'!$A3,'Individual Data'!$X$6:$X$3142,'age-length prop'!D$7,'Individual Data'!$M$6:$M$3142,'age-length prop'!$B$6) -> 0 | E3: =SUMIFS('Individual Data'!$AA$6:$AA$3142,'Individual Data'!$U$6:$U$3142,'age-length prop'!$B3,'Individual Data'!$I$6:$I$3142,'age-length prop'!$A3,'Individual Data'!$X$6:$X$3142,'age-length prop'!E$7,'Individual Data'!$M$6:$M$3142,'age-length prop'!$B$6) -> 0 | F3: =SUMIFS('Individual Data'!$AA$6:$AA$3142,'Individual Data'!$U$6:$U$3142,'age-length prop'!$B3,'Individual Data'!$I$6:$I$3142,'age-length prop'!$A3,'Individual Data'!$X$6:$X$3142,'age-length prop'!F$7,'Individual Data'!$M$6:$M$3142,'age-length prop'!$B$6) -> 0 | G3: =SUMIFS('Individual Data'!$AA$6:$AA$3142,'Individual Data'!$U$6:$U$3142,'age-length prop'!$B3,'Individual Data'!$I$6:$I$3142,'age-length prop'!$A3,'Individual Data'!$X$6:$X$3142,'age-length prop'!G$7,'Individual Data'!$M$6:$M$3142,'age-length prop'!$B$6) -> 0 | H3: =SUMIFS('Individual Data'!$AA$6:$AA$3142,'Individual Data'!$U$6:$U$3142,'age-length prop'!$B3,'Individual Data'!$I$6:$I$3142,'age-length prop'!$A3,'Individual Data'!$X$6:$X$3142,'age-length prop'!H$7,'Individual Data'!$M$6:$M$3142,'age-length prop'!$B$6) -> 0 | I3: =SUMIFS('Individual Data'!$AA$6:$AA$3142,'Individual Data'!$U$6:$U$3142,'age-length prop'!$B3,'Individual Data'!$I$6:$I$3142,'age-length prop'!$A3,'Individual Data'!$X$6:$X$3142,'age-length prop'!I$7,'Individual Data'!$M$6:$M$3142,'age-length prop'!$B$6) -> 68.740909 | J3: =SUMIFS('Individual Data'!$AA$6:$AA$3142,'Individual Data'!$U$6:$U$3142,'age-length prop'!$B3,'Individual Data'!$I$6:$I$3142,'age-length prop'!$A3,'Individual Data'!$X$6:$X$3142,'age-length prop'!J$7,'Individual Data'!$M$6:$M$3142,'age-length prop'!$B$6) -> 68.740909 | K3: =SUMIFS('Individual Data'!$AA$6:$AA$3142,'Individual Data'!$U$6:$U$3142,'age-length prop'!$B3,'Individual Data'!$I$6:$I$3142,'age-length prop'!$A3,'Individual Data'!$X$6:$X$3142,'age-length prop'!K$7,'Individual Data'!$M$6:$M$3142,'age-length prop'!$B$6) -> 85.926136 | ... P3: =SUMIFS('Individual Data'!$AA$6:$AA$3142,'Individual Data'!$U$6:$U$3142,'age-length prop'!$B3,'Individual Data'!$I$6:$I$3142,'age-length prop'!$A3,'Individual Data'!$X$6:$X$3142,'age-length prop'!P$7,'Individual Data'!$M$6:$M$3142,'age-length prop'!$B$6) -> 0 | T3: assign only | V3: =SUM(Q8:AC61) -> 13927.055 | AE3: Expand hatchery PBT groups by tag rate. Multiply totals by tag rate for each group | AS3: sum check | AV3: 2022 | AZ3: abv | BA3: ='Individual Data'!AF3 -> 0.04 | BB3: ='Individual Data'!AE3 -> 0.06 | BK3: subtract NG proportioned cells (col Q to AC) from tag rate expanded (col AE to AQ). This is the number of fish to subtract from unassigned AD and AI groups | CA3: number of fish to subtract from unassigned AD group by FL | CO3: number of fish to subtract from unassinged AI group by FL
A4: AI | B4: NG | D4: =SUMIFS('Individual Data'!$AA$6:$AA$3142,'Individual Data'!$U$6:$U$3142,'age-length prop'!$B4,'Individual Data'!$I$6:$I$3142,'age-length prop'!$A4,'Individual Data'!$X$6:$X$3142,'age-length prop'!D$7,'Individual Data'!$M$6:$M$3142,'age-length prop'!$B$6) -> 0 | E4: =SUMIFS('Individual Data'!$AA$6:$AA$3142,'Individual Data'!$U$6:$U$3142,'age-length prop'!$B4,'Individual Data'!$I$6:$I$3142,'age-length prop'!$A4,'Individual Data'!$X$6:$X$3142,'age-length prop'!E$7,'Individual Data'!$M$6:$M$3142,'age-length prop'!$B$6) -> 0 | F4: =SUMIFS('Individual Data'!$AA$6:$AA$3142,'Individual Data'!$U$6:$U$3142,'age-length prop'!$B4,'Individual Data'!$I$6:$I$3142,'age-length prop'!$A4,'Individual Data'!$X$6:$X$3142,'age-length prop'!F$7,'Individual Data'!$M$6:$M$3142,'age-length prop'!$B$6) -> 0 | G4: =SUMIFS('Individual Data'!$AA$6:$AA$3142,'Individual Data'!$U$6:$U$3142,'age-length prop'!$B4,'Individual Data'!$I$6:$I$3142,'age-length prop'!$A4,'Individual Data'!$X$6:$X$3142,'age-length prop'!G$7,'Individual Data'!$M$6:$M$3142,'age-length prop'!$B$6) -> 0 | H4: =SUMIFS('Individual Data'!$AA$6:$AA$3142,'Individual Data'!$U$6:$U$3142,'age-length prop'!$B4,'Individual Data'!$I$6:$I$3142,'age-length prop'!$A4,'Individual Data'!$X$6:$X$3142,'age-length prop'!H$7,'Individual Data'!$M$6:$M$3142,'age-length prop'!$B$6) -> 34.370455 | I4: =SUMIFS('Individual Data'!$AA$6:$AA$3142,'Individual Data'!$U$6:$U$3142,'age-length prop'!$B4,'Individual Data'!$I$6:$I$3142,'age-length prop'!$A4,'Individual Data'!$X$6:$X$3142,'age-length prop'!I$7,'Individual Data'!$M$6:$M$3142,'age-length prop'!$B$6) -> 103.11136 | J4: =SUMIFS('Individual Data'!$AA$6:$AA$3142,'Individual Data'!$U$6:$U$3142,'age-length prop'!$B4,'Individual Data'!$I$6:$I$3142,'age-length prop'!$A4,'Individual Data'!$X$6:$X$3142,'age-length prop'!J$7,'Individual Data'!$M$6:$M$3142,'age-length prop'!$B$6) -> 103.11136 | K4: =SUMIFS('Individual Data'!$AA$6:$AA$3142,'Individual Data'!$U$6:$U$3142,'age-length prop'!$B4,'Individual Data'!$I$6:$I$3142,'age-length prop'!$A4,'Individual Data'!$X$6:$X$3142,'age-length prop'!K$7,'Individual Data'!$M$6:$M$3142,'age-length prop'!$B$6) -> 51.555682 | ... P4: =SUMIFS('Individual Data'!$AA$6:$AA$3142,'Individual Data'!$U$6:$U$3142,'age-length prop'!$B4,'Individual Data'!$I$6:$I$3142,'age-length prop'!$A4,'Individual Data'!$X$6:$X$3142,'age-length prop'!P$7,'Individual Data'!$M$6:$M$3142,'age-length prop'!$B$6) -> 0 | Q4: NG fish proportioned to known hatchery and unassigned groups by FL | AS4: =AS6+AT6 -> 16065.029 | AZ4: blw | BA4: ='Individual Data'!AF4 -> 0.45 | BB4: ='Individual Data'!AE4 -> 0.75
B5: total NG | D5: =D3+D4 -> 0 | E5: =E3+E4 -> 0 | F5: =F3+F4 -> 0 | G5: =G3+G4 -> 0 | H5: =H3+H4 -> 34.370455 | I5: =I3+I4 -> 171.85227 | J5: =J3+J4 -> 171.85227 | K5: =K3+K4 -> 137.48182 | ... P5: =P3+P4 -> 0 | AE5: Apply tag rate expansion: tag expanded estimates of known hatchery groups | AV5: =AS4+AS68 -> 46598.943 | AZ5: =SUM(AZ8:AZ61) -> 16065.029 | BA5: =SUM(BA8:BA61) -> 25591.204 | BB5: =SUM(BB8:BB61) -> 4942.7104 | BD5: =SUM(BD8:BD61) -> 12012.802 | BE5: =SUM(BE8:BE61) -> 20882.011 | BF5: =SUM(BF8:BF61) -> 3088.0973 | BK5: count minus tag expanded, # to subtract from unassigned groups by clip | CA5: AD clipped fish to subract from unassigned AD group | CO5: AI fish to subtract from unassigned group
B6: F | C6: total by FL | D6: =SUM(D8:D63) -> 34.370455 | E6: =SUM(E8:E63) -> 0 | F6: =SUM(F8:F63) -> 17.185227 | G6: =SUM(G8:G63) -> 68.740909 | H6: =SUM(H8:H63) -> 857.82926 | I6: =SUM(I8:I63) -> 3070.4273 | J6: =SUM(J8:J63) -> 4163.1213 | K6: =SUM(K8:K63) -> 4831.9131 | ... P6: =SUM(P8:P63) -> 17.185227 | AS6: =SUM(AS8:AS61) -> 52.096945 | AT6: =SUM(AT8:AT61) -> 16012.932 | BA6: =AZ5+BA5+BB5 -> 46598.943 | BE6: =BD5+BE5+BF5 -> 35982.91 | BK6: =SUM(BK8:BK61) -> 0.3608422 | BL6: =SUM(BL8:BL61) -> 0 | BM6: =SUM(BM8:BM61) -> 0.1804211 | BN6: =SUM(BN8:BN61) -> 6.1546614 | BO6: =SUM(BO8:BO61) -> 61.680558 | BP6: =SUM(BP8:BP61) -> 277.8458 | BQ6: =SUM(BQ8:BQ61) -> 489.0448 | BR6: =SUM(BR8:BR61) -> 704.07148 | ... BW6: =SUM(BW8:BW61) -> 0 | CA6: =SUM(CA8:CA61) -> 0.35492675 | CB6: =SUM(CB8:CB61) -> 0 | CC6: =SUM(CC8:CC61) -> 0.1804211 | CD6: =SUM(CD8:CD61) -> 1.898208 | CE6: =SUM(CE8:CE61) -> 42.042752 | CF6: =SUM(CF8:CF61) -> 189.81691 | CG6: =SUM(CG8:CG61) -> 345.58412 | CH6: =SUM(CH8:CH61) -> 343.08438 | ... CM6: =SUM(CM8:CM61) -> 0 | CO6: =SUM(CO8:CO61) -> 0.0059154458 | CP6: =SUM(CP8:CP61) -> 0 | CQ6: =SUM(CQ8:CQ61) -> 0 | CR6: =SUM(CR8:CR61) -> 4.2564534 | CS6: =SUM(CS8:CS61) -> 19.637806 | CT6: =SUM(CT8:CT61) -> 88.028896 | CU6: =SUM(CU8:CU61) -> 143.46069 | CV6: =SUM(CV8:CV61) -> 360.98709 | ... DA6: =SUM(DA8:DA61) -> 0
B7: Final group | C7: agePBT | D7: 42 | E7: 47 | F7: 52 | G7: 57 | H7: 62 | I7: 67 | J7: 72 | K7: 77 | L7: 82 | M7: 87 | N7: 92 | O7: 99 | P7: 100 | Q7: 42 | R7: 47 | S7: 52 | T7: 57 | U7: 62 | V7: 67 | W7: 72 | X7: 77 | Y7: 82 | Z7: 87 | AA7: 92 | AB7: 99 | AC7: 100 | AD7: tag rate | AE7: 42 | AF7: 47 | AG7: 52 | AH7: 57 | AI7: 62 | AJ7: 67 | AK7: 72 | AL7: 77 | AM7: 82 | AN7: 87 | AO7: 92 | AP7: 99 | AQ7: 100 | AS7: F jacks | AT7: Females | AV7: Brd Yr | AW7: grp | AX7: origin | AY7: CWT code | AZ7: Female | BA7: Males | BB7: jacks | BC7: rel loc | BD7: Female | BE7: Males | BF7: jacks | BK7: 42 | BL7: 47 | BM7: 52 | BN7: 57 | BO7: 62 | BP7: 67 | BQ7: 72 | BR7: 77 | BS7: 82 | BT7: 87 | BU7: 92 | BV7: 99 | BW7: 100 | BX7: % AD | BY7: AD | BZ7: AI | CA7: 42 | CB7: 47 | CC7: 52 | CD7: 57 | CE7: 62 | CF7: 67 | CG7: 72 | CH7: 77 | CI7: 82 | CJ7: 87 | CK7: 92 | CL7: 99 | CM7: 100 | CO7: 42 | CP7: 47 | CQ7: 52 | CR7: 57 | CS7: 62 | CT7: 67 | CU7: 72 | CV7: 77 | CW7: 82 | CX7: 87 | CY7: 92 | CZ7: 99 | DA7: 100
A8: OtsLYON17S_1 | B8: LFH Ukn | C8: 5 | D8: =SUMIFS('Individual Data'!$AA$6:$AA$3142,'Individual Data'!$U$6:$U$3142,'age-length prop'!$B8,'Individual Data'!$X$6:$X$3142,'age-length prop'!D$7,'Individual Data'!$Q$6:$Q$3142,'age-length prop'!$C8,'Individual Data'!$M$6:$M$3142,'age-length prop'!$B$6) -> 0 | E8: =SUMIFS('Individual Data'!$AA$6:$AA$3142,'Individual Data'!$U$6:$U$3142,'age-length prop'!$B8,'Individual Data'!$X$6:$X$3142,'age-length prop'!E$7,'Individual Data'!$Q$6:$Q$3142,'age-length prop'!$C8,'Individual Data'!$M$6:$M$3142,'age-length prop'!$B$6) -> 0 | F8: =SUMIFS('Individual Data'!$AA$6:$AA$3142,'Individual Data'!$U$6:$U$3142,'age-length prop'!$B8,'Individual Data'!$X$6:$X$3142,'age-length prop'!F$7,'Individual Data'!$Q$6:$Q$3142,'age-length prop'!$C8,'Individual Data'!$M$6:$M$3142,'age-length prop'!$B$6) -> 0 | G8: =SUMIFS('Individual Data'!$AA$6:$AA$3142,'Individual Data'!$U$6:$U$3142,'age-length prop'!$B8,'Individual Data'!$X$6:$X$3142,'age-length prop'!G$7,'Individual Data'!$Q$6:$Q$3142,'age-length prop'!$C8,'Individual Data'!$M$6:$M$3142,'age-length prop'!$B$6) -> 0 | H8: =SUMIFS('Individual Data'!$AA$6:$AA$3142,'Individual Data'!$U$6:$U$3142,'age-length prop'!$B8,'Individual Data'!$X$6:$X$3142,'age-length prop'!H$7,'Individual Data'!$Q$6:$Q$3142,'age-length prop'!$C8,'Individual Data'!$M$6:$M$3142,'age-length prop'!$B$6) -> 0 | I8: =SUMIFS('Individual Data'!$AA$6:$AA$3142,'Individual Data'!$U$6:$U$3142,'age-length prop'!$B8,'Individual Data'!$X$6:$X$3142,'age-length prop'!I$7,'Individual Data'!$Q$6:$Q$3142,'age-length prop'!$C8,'Individual Data'!$M$6:$M$3142,'age-length prop'!$B$6) -> 0 | J8: =SUMIFS('Individual Data'!$AA$6:$AA$3142,'Individual Data'!$U$6:$U$3142,'age-length prop'!$B8,'Individual Data'!$X$6:$X$3142,'age-length prop'!J$7,'Individual Data'!$Q$6:$Q$3142,'age-length prop'!$C8,'Individual Data'!$M$6:$M$3142,'age-length prop'!$B$6) -> 51.555682 | K8: =SUMIFS('Individual Data'!$AA$6:$AA$3142,'Individual Data'!$U$6:$U$3142,'age-length prop'!$B8,'Individual Data'!$X$6:$X$3142,'age-length prop'!K$7,'Individual Data'!$Q$6:$Q$3142,'age-length prop'!$C8,'Individual Data'!$M$6:$M$3142,'age-length prop'!$B$6) -> 120.29659 | ... P8: =SUMIFS('Individual Data'!$AA$6:$AA$3142,'Individual Data'!$U$6:$U$3142,'age-length prop'!$B8,'Individual Data'!$X$6:$X$3142,'age-length prop'!P$7,'Individual Data'!$Q$6:$Q$3142,'age-length prop'!$C8,'Individual Data'!$M$6:$M$3142,'age-length prop'!$B$6) -> 0 | Q8: =IFERROR(D8+(D$5*(D8/D$6)),0) -> 0 | R8: =IFERROR(E8+(E$5*(E8/E$6)),0) -> 0 | S8: =IFERROR(F8+(F$5*(F8/F$6)),0) -> 0 | T8: =IFERROR(G8+(G$5*(G8/G$6)),0) -> 0 | U8: =IFERROR(H8+(H$5*(H8/H$6)),0) -> 0 | V8: =IFERROR(I8+(I$5*(I8/I$6)),0) -> 0 | W8: =IFERROR(J8+(J$5*(J8/J$6)),0) -> 53.683883 | X8: =IFERROR(K8+(K$5*(K8/K$6)),0) -> 123.71937 | ... AC8: =IFERROR(P8+(P$5*(P8/P$6)),0) -> 0 | AD8: =VLOOKUP(A8,'PBT Tag Rates'!$B$5:$E$34,4,FALSE) -> 0.76170174 | AE8: =Q8/$AD8 -> 0 | AF8: =R8/$AD8 -> 0 | AG8: =S8/$AD8 -> 0 | AH8: =T8/$AD8 -> 0 | AI8: =U8/$AD8 -> 0 | AJ8: =V8/$AD8 -> 0 | AK8: =W8/$AD8 -> 70.478877 | AL8: =X8/$AD8 -> 162.42496 | ... AQ8: =AC8/$AD8 -> 0 | AS8: =SUM(AE8:AG8) -> 0 | AT8: =SUM(AH8:AQ8) -> 643.14814 | AV8: =$AV$3-C8 -> 2017 | AW8: =B8 -> LFH Ukn | AX8: SR | AY8: =SUMIFS('cwt rel info'!$A$6:$A$217,'cwt rel info'!$D$6:$D$217,'age-length prop'!AV8,'cwt rel info'!$E$6:$E$217,'age-length prop'!AW8) -> 0 | AZ8: =AS8+AT8 -> 643.14814 | BA8: =AT72 -> 114.46357 | BB8: =AS72 -> 0 | BC8: =VLOOKUP(AW8,'Individual Data'!$U$5:$AB$3142,8,FALSE) -> blw | BD8: =IF(BC8="blw",AZ8*(1-$BA$4),AZ8*(1-$BA$3)) -> 353.73148 | BE8: =IF(BC8="blw",BA8*(1-$BA$4),BA8*(1-$BA$3)) -> 62.954966 | BF8: =IF(BC8="blw",BB8*(1-$BB$4),BB8*(1-$BB$3)) -> 0 | BK8: =AE8-Q8 -> 0 | BL8: =AF8-R8 -> 0 | BM8: =AG8-S8 -> 0 | BN8: =AH8-T8 -> 0 | BO8: =AI8-U8 -> 0 | BP8: =AJ8-V8 -> 0 | BQ8: =AK8-W8 -> 16.794994 | BR8: =AL8-X8 -> 38.705585 | ... BW8: =AQ8-AC8 -> 0 | BX8: =BY8/(BY8+BZ8) -> 0.57575758 | BY8: =SUMIFS('Individual Data'!$W$6:$W$3142,'Individual Data'!$I$6:$I$3142,'age-length prop'!BY$7,'Individual Data'!$U$6:$U$3142,'age-length prop'!$B8,'Individual Data'!$Q$6:$Q$3142,'age-length prop'!$C8) -> 19 | BZ8: =SUMIFS('Individual Data'!$W$6:$W$3142,'Individual Data'!$I$6:$I$3142,'age-length prop'!BZ$7,'Individual Data'!$U$6:$U$3142,'age-length prop'!$B8,'Individual Data'!$Q$6:$Q$3142,'age-length prop'!$C8) -> 14 | CA8: =BK8*$BX8 -> 0 | CB8: =BL8*$BX8 -> 0 | CC8: =BM8*$BX8 -> 0 | CD8: =BN8*$BX8 -> 0 | CE8: =BO8*$BX8 -> 0 | CF8: =BP8*$BX8 -> 0 | CG8: =BQ8*$BX8 -> 9.6698448 | CH8: =BR8*$BX8 -> 22.285034 | ... CM8: =BW8*$BX8 -> 0 | CO8: =BK8*(1-$BX8) -> 0 | CP8: =BL8*(1-$BX8) -> 0 | CQ8: =BM8*(1-$BX8) -> 0 | CR8: =BN8*(1-$BX8) -> 0 | CS8: =BO8*(1-$BX8) -> 0 | CT8: =BP8*(1-$BX8) -> 0 | CU8: =BQ8*(1-$BX8) -> 7.1251488 | CV8: =BR8*(1-$BX8) -> 16.420551 | ... DA8: =BW8*(1-$BX8) -> 0
A9: OtsLYON18S_1 | B9: BCAe | C9: 4 | D9: =SUMIFS('Individual Data'!$AA$6:$AA$3142,'Individual Data'!$U$6:$U$3142,'age-length prop'!$B9,'Individual Data'!$X$6:$X$3142,'age-length prop'!D$7,'Individual Data'!$Q$6:$Q$3142,'age-length prop'!$C9,'Individual Data'!$M$6:$M$3142,'age-length prop'!$B$6) -> 0 | E9: =SUMIFS('Individual Data'!$AA$6:$AA$3142,'Individual Data'!$U$6:$U$3142,'age-length prop'!$B9,'Individual Data'!$X$6:$X$3142,'age-length prop'!E$7,'Individual Data'!$Q$6:$Q$3142,'age-length prop'!$C9,'Individual Data'!$M$6:$M$3142,'age-length prop'!$B$6) -> 0 | F9: =SUMIFS('Individual Data'!$AA$6:$AA$3142,'Individual Data'!$U$6:$U$3142,'age-length prop'!$B9,'Individual Data'!$X$6:$X$3142,'age-length prop'!F$7,'Individual Data'!$Q$6:$Q$3142,'age-length prop'!$C9,'Individual Data'!$M$6:$M$3142,'age-length prop'!$B$6) -> 0 | G9: =SUMIFS('Individual Data'!$AA$6:$AA$3142,'Individual Data'!$U$6:$U$3142,'age-length prop'!$B9,'Individual Data'!$X$6:$X$3142,'age-length prop'!G$7,'Individual Data'!$Q$6:$Q$3142,'age-length prop'!$C9,'Individual Data'!$M$6:$M$3142,'age-length prop'!$B$6) -> 0 | H9: =SUMIFS('Individual Data'!$AA$6:$AA$3142,'Individual Data'!$U$6:$U$3142,'age-length prop'!$B9,'Individual Data'!$X$6:$X$3142,'age-length prop'!H$7,'Individual Data'!$Q$6:$Q$3142,'age-length prop'!$C9,'Individual Data'!$M$6:$M$3142,'age-length prop'!$B$6) -> 0 | I9: =SUMIFS('Individual Data'!$AA$6:$AA$3142,'Individual Data'!$U$6:$U$3142,'age-length prop'!$B9,'Individual Data'!$X$6:$X$3142,'age-length prop'!I$7,'Individual Data'!$Q$6:$Q$3142,'age-length prop'!$C9,'Individual Data'!$M$6:$M$3142,'age-length prop'!$B$6) -> 17.185227 | J9: =SUMIFS('Individual Data'!$AA$6:$AA$3142,'Individual Data'!$U$6:$U$3142,'age-length prop'!$B9,'Individual Data'!$X$6:$X$3142,'age-length prop'!J$7,'Individual Data'!$Q$6:$Q$3142,'age-length prop'!$C9,'Individual Data'!$M$6:$M$3142,'age-length prop'!$B$6) -> 85.926136 | K9: =SUMIFS('Individual Data'!$AA$6:$AA$3142,'Individual Data'!$U$6:$U$3142,'age-length prop'!$B9,'Individual Data'!$X$6:$X$3142,'age-length prop'!K$7,'Individual Data'!$Q$6:$Q$3142,'age-length prop'!$C9,'Individual Data'!$M$6:$M$3142,'age-length prop'!$B$6) -> 302.17358 | ... P9: =SUMIFS('Individual Data'!$AA$6:$AA$3142,'Individual Data'!$U$6:$U$3142,'age-length prop'!$B9,'Individual Data'!$X$6:$X$3142,'age-length prop'!P$7,'Individual Data'!$Q$6:$Q$3142,'age-length prop'!$C9,'Individual Data'!$M$6:$M$3142,'age-length prop'!$B$6) -> 0 | Q9: =IFERROR(D9+(D$5*(D9/D$6)),0) -> 0 | R9: =IFERROR(E9+(E$5*(E9/E$6)),0) -> 0 | S9: =IFERROR(F9+(F$5*(F9/F$6)),0) -> 0 | T9: =IFERROR(G9+(G$5*(G9/G$6)),0) -> 0 | U9: =IFERROR(H9+(H$5*(H9/H$6)),0) -> 0 | V9: =IFERROR(I9+(I$5*(I9/I$6)),0) -> 18.147087 | W9: =IFERROR(J9+(J$5*(J9/J$6)),0) -> 89.473139 | X9: =IFERROR(K9+(K$5*(K9/K$6)),0) -> 310.77129 | ... AC9: =IFERROR(P9+(P$5*(P9/P$6)),0) -> 0 | AD9: =VLOOKUP(A9,'PBT Tag Rates'!$B$5:$E$34,4,FALSE) -> 0.80551598 | AE9: =Q9/$AD9 -> 0 | AF9: =R9/$AD9 -> 0 | AG9: =S9/$AD9 -> 0 | AH9: =T9/$AD9 -> 0 | AI9: =U9/$AD9 -> 0 | AJ9: =V9/$AD9 -> 22.528525 | AK9: =W9/$AD9 -> 111.07556 | AL9: =X9/$AD9 -> 385.804 | ... AQ9: =AC9/$AD9 -> 0 | AS9: =SUM(AE9:AG9) -> 0 | AT9: =SUM(AH9:AQ9) -> 665.61052 | AV9: =$AV$3-C9 -> 2018 | AW9: =B9 -> BCAe | AX9: SR | AY9: =SUMIFS('cwt rel info'!$A$6:$A$217,'cwt rel info'!$D$6:$D$217,'age-length prop'!AV9,'cwt rel info'!$E$6:$E$217,'age-length prop'!AW9) -> 220511 | AZ9: =AS9+AT9 -> 665.61052 | BA9: =AT73 -> 412.64665 | BB9: =AS73 -> 0 | BC9: =VLOOKUP(AW9,'Individual Data'!$U$5:$AB$3142,8,FALSE) -> abv | BD9: =IF(BC9="blw",AZ9*(1-$BA$4),AZ9*(1-$BA$3)) -> 638.9861 | BE9: =IF(BC9="blw",BA9*(1-$BA$4),BA9*(1-$BA$3)) -> 396.14079 | BF9: =IF(BC9="blw",BB9*(1-$BB$4),BB9*(1-$BB$3)) -> 0 | BK9: =AE9-Q9 -> 0 | BL9: =AF9-R9 -> 0 | BM9: =AG9-S9 -> 0 | BN9: =AH9-T9 -> 0 | BO9: =AI9-U9 -> 0 | BP9: =AJ9-V9 -> 4.381438 | BQ9: =AK9-W9 -> 21.602421 | BR9: =AL9-X9 -> 75.032711 | ... BW9: =AQ9-AC9 -> 0 | BX9: =BY9/(BY9+BZ9) -> 0.48 | BY9: =SUMIFS('Individual Data'!$W$6:$W$3142,'Individual Data'!$I$6:$I$3142,'age-length prop'!BY$7,'Individual Data'!$U$6:$U$3142,'age-length prop'!$B9,'Individual Data'!$Q$6:$Q$3142,'age-length prop'!$C9) -> 24 | BZ9: =SUMIFS('Individual Data'!$W$6:$W$3142,'Individual Data'!$I$6:$I$3142,'age-length prop'!BZ$7,'Individual Data'!$U$6:$U$3142,'age-length prop'!$B9,'Individual Data'!$Q$6:$Q$3142,'age-length prop'!$C9) -> 26 | CA9: =BK9*$BX9 -> 0 | CB9: =BL9*$BX9 -> 0 | CC9: =BM9*$BX9 -> 0 | CD9: =BN9*$BX9 -> 0 | CE9: =BO9*$BX9 -> 0 | CF9: =BP9*$BX9 -> 2.1030903 | CG9: =BQ9*$BX9 -> 10.369162 | CH9: =BR9*$BX9 -> 36.015701 | ... CM9: =BW9*$BX9 -> 0 | CO9: =BK9*(1-$BX9) -> 0 | CP9: =BL9*(1-$BX9) -> 0 | CQ9: =BM9*(1-$BX9) -> 0 | CR9: =BN9*(1-$BX9) -> 0 | CS9: =BO9*(1-$BX9) -> 0 | CT9: =BP9*(1-$BX9) -> 2.2783478 | CU9: =BQ9*(1-$BX9) -> 11.233259 | CV9: =BR9*(1-$BX9) -> 39.01701 | ... DA9: =BW9*(1-$BX9) -> 0
A10: OtsLYON18S_1 | B10: BCAl | C10: 4 | D10: =SUMIFS('Individual Data'!$AA$6:$AA$3142,'Individual Data'!$U$6:$U$3142,'age-length prop'!$B10,'Individual Data'!$X$6:$X$3142,'age-length prop'!D$7,'Individual Data'!$Q$6:$Q$3142,'age-length prop'!$C10,'Individual Data'!$M$6:$M$3142,'age-length prop'!$B$6) -> 0 | E10: =SUMIFS('Individual Data'!$AA$6:$AA$3142,'Individual Data'!$U$6:$U$3142,'age-length prop'!$B10,'Individual Data'!$X$6:$X$3142,'age-length prop'!E$7,'Individual Data'!$Q$6:$Q$3142,'age-length prop'!$C10,'Individual Data'!$M$6:$M$3142,'age-length prop'!$B$6) -> 0 | F10: =SUMIFS('Individual Data'!$AA$6:$AA$3142,'Individual Data'!$U$6:$U$3142,'age-length prop'!$B10,'Individual Data'!$X$6:$X$3142,'age-length prop'!F$7,'Individual Data'!$Q$6:$Q$3142,'age-length prop'!$C10,'Individual Data'!$M$6:$M$3142,'age-length prop'!$B$6) -> 0 | G10: =SUMIFS('Individual Data'!$AA$6:$AA$3142,'Individual Data'!$U$6:$U$3142,'age-length prop'!$B10,'Individual Data'!$X$6:$X$3142,'age-length prop'!G$7,'Individual Data'!$Q$6:$Q$3142,'age-length prop'!$C10,'Individual Data'!$M$6:$M$3142,'age-length prop'!$B$6) -> 0 | H10: =SUMIFS('Individual Data'!$AA$6:$AA$3142,'Individual Data'!$U$6:$U$3142,'age-length prop'!$B10,'Individual Data'!$X$6:$X$3142,'age-length prop'!H$7,'Individual Data'!$Q$6:$Q$3142,'age-length prop'!$C10,'Individual Data'!$M$6:$M$3142,'age-length prop'!$B$6) -> 0 | I10: =SUMIFS('Individual Data'!$AA$6:$AA$3142,'Individual Data'!$U$6:$U$3142,'age-length prop'!$B10,'Individual Data'!$X$6:$X$3142,'age-length prop'!I$7,'Individual Data'!$Q$6:$Q$3142,'age-length prop'!$C10,'Individual Data'!$M$6:$M$3142,'age-length prop'!$B$6) -> 0 | J10: =SUMIFS('Individual Data'!$AA$6:$AA$3142,'Individual Data'!$U$6:$U$3142,'age-length prop'!$B10,'Individual Data'!$X$6:$X$3142,'age-length prop'!J$7,'Individual Data'!$Q$6:$Q$3142,'age-length prop'!$C10,'Individual Data'!$M$6:$M$3142,'age-length prop'!$B$6) -> 17.185227 | K10: =SUMIFS('Individual Data'!$AA$6:$AA$3142,'Individual Data'!$U$6:$U$3142,'age-length prop'!$B10,'Individual Data'!$X$6:$X$3142,'age-length prop'!K$7,'Individual Data'!$Q$6:$Q$3142,'age-length prop'!$C10,'Individual Data'!$M$6:$M$3142,'age-length prop'!$B$6) -> 17.185227 | ... P10: =SUMIFS('Individual Data'!$AA$6:$AA$3142,'Individual Data'!$U$6:$U$3142,'age-length prop'!$B10,'Individual Data'!$X$6:$X$3142,'age-length prop'!P$7,'Individual Data'!$Q$6:$Q$3142,'age-length prop'!$C10,'Individual Data'!$M$6:$M$3142,'age-length prop'!$B$6) -> 0 | Q10: =IFERROR(D10+(D$5*(D10/D$6)),0) -> 0 | R10: =IFERROR(E10+(E$5*(E10/E$6)),0) -> 0 | S10: =IFERROR(F10+(F$5*(F10/F$6)),0) -> 0 | T10: =IFERROR(G10+(G$5*(G10/G$6)),0) -> 0 | U10: =IFERROR(H10+(H$5*(H10/H$6)),0) -> 0 | V10: =IFERROR(I10+(I$5*(I10/I$6)),0) -> 0 | W10: =IFERROR(J10+(J$5*(J10/J$6)),0) -> 17.894628 | X10: =IFERROR(K10+(K$5*(K10/K$6)),0) -> 17.674196 | ... AC10: =IFERROR(P10+(P$5*(P10/P$6)),0) -> 0 | AD10: =VLOOKUP(A10,'PBT Tag Rates'!$B$5:$E$34,4,FALSE) -> 0.80551598 | AE10: =Q10/$AD10 -> 0 | AF10: =R10/$AD10 -> 0 | AG10: =S10/$AD10 -> 0 | AH10: =T10/$AD10 -> 0 | AI10: =U10/$AD10 -> 0 | AJ10: =V10/$AD10 -> 0 | AK10: =W10/$AD10 -> 22.215112 | AL10: =X10/$AD10 -> 21.94146 | ... AQ10: =AC10/$AD10 -> 0 | AS10: =SUM(AE10:AG10) -> 0 | AT10: =SUM(AH10:AQ10) -> 44.156572 | AV10: =$AV$3-C10 -> 2018 | AW10: =B10 -> BCAl | AX10: SR | AY10: =SUMIFS('cwt rel info'!$A$6:$A$217,'cwt rel info'!$D$6:$D$217,'age-length prop'!AV10,'cwt rel info'!$E$6:$E$217,'age-length prop'!AW10) -> 220512 | AZ10: =AS10+AT10 -> 44.156572 | BA10: =AT74 -> 44.19887 | BB10: =AS74 -> 0 | BC10: =VLOOKUP(AW10,'Individual Data'!$U$5:$AB$3142,8,FALSE) -> abv | BD10: =IF(BC10="blw",AZ10*(1-$BA$4),AZ10*(1-$BA$3)) -> 42.390309 | BE10: =IF(BC10="blw",BA10*(1-$BA$4),BA10*(1-$BA$3)) -> 42.430916 | BF10: =IF(BC10="blw",BB10*(1-$BB$4),BB10*(1-$BB$3)) -> 0 | BK10: =AE10-Q10 -> 0 | BL10: =AF10-R10 -> 0 | BM10: =AG10-S10 -> 0 | BN10: =AH10-T10 -> 0 | BO10: =AI10-U10 -> 0 | BP10: =AJ10-V10 -> 0 | BQ10: =AK10-W10 -> 4.3204842 | BR10: =AL10-X10 -> 4.2672632 | ... BW10: =AQ10-AC10 -> 0 | BX10: =BY10/(BY10+BZ10) -> 1 | BY10: =SUMIFS('Individual Data'!$W$6:$W$3142,'Individual Data'!$I$6:$I$3142,'age-length prop'!BY$7,'Individual Data'!$U$6:$U$3142,'age-length prop'!$B10,'Individual Data'!$Q$6:$Q$3142,'age-length prop'!$C10) -> 4 | BZ10: =SUMIFS('Individual Data'!$W$6:$W$3142,'Individual Data'!$I$6:$I$3142,'age-length prop'!BZ$7,'Individual Data'!$U$6:$U$3142,'age-length prop'!$B10,'Individual Data'!$Q$6:$Q$3142,'age-length prop'!$C10) -> 0 | CA10: =BK10*$BX10 -> 0 | CB10: =BL10*$BX10 -> 0 | CC10: =BM10*$BX10 -> 0 | CD10: =BN10*$BX10 -> 0 | CE10: =BO10*$BX10 -> 0 | CF10: =BP10*$BX10 -> 0 | CG10: =BQ10*$BX10 -> 4.3204842 | CH10: =BR10*$BX10 -> 4.2672632 | ... CM10: =BW10*$BX10 -> 0 | CO10: =BK10*(1-$BX10) -> 0 | CP10: =BL10*(1-$BX10) -> 0 | CQ10: =BM10*(1-$BX10) -> 0 | CR10: =BN10*(1-$BX10) -> 0 | CS10: =BO10*(1-$BX10) -> 0 | CT10: =BP10*(1-$BX10) -> 0 | CU10: =BQ10*(1-$BX10) -> 0 | CV10: =BR10*(1-$BX10) -> 0 | ... DA10: =BW10*(1-$BX10) -> 0
A11: OtsLYON18S_1 | B11: CJAe | C11: 4 | D11: =SUMIFS('Individual Data'!$AA$6:$AA$3142,'Individual Data'!$U$6:$U$3142,'age-length prop'!$B11,'Individual Data'!$X$6:$X$3142,'age-length prop'!D$7,'Individual Data'!$Q$6:$Q$3142,'age-length prop'!$C11,'Individual Data'!$M$6:$M$3142,'age-length prop'!$B$6) -> 0 | E11: =SUMIFS('Individual Data'!$AA$6:$AA$3142,'Individual Data'!$U$6:$U$3142,'age-length prop'!$B11,'Individual Data'!$X$6:$X$3142,'age-length prop'!E$7,'Individual Data'!$Q$6:$Q$3142,'age-length prop'!$C11,'Individual Data'!$M$6:$M$3142,'age-length prop'!$B$6) -> 0 | F11: =SUMIFS('Individual Data'!$AA$6:$AA$3142,'Individual Data'!$U$6:$U$3142,'age-length prop'!$B11,'Individual Data'!$X$6:$X$3142,'age-length prop'!F$7,'Individual Data'!$Q$6:$Q$3142,'age-length prop'!$C11,'Individual Data'!$M$6:$M$3142,'age-length prop'!$B$6) -> 0 | G11: =SUMIFS('Individual Data'!$AA$6:$AA$3142,'Individual Data'!$U$6:$U$3142,'age-length prop'!$B11,'Individual Data'!$X$6:$X$3142,'age-length prop'!G$7,'Individual Data'!$Q$6:$Q$3142,'age-length prop'!$C11,'Individual Data'!$M$6:$M$3142,'age-length prop'!$B$6) -> 0 | H11: =SUMIFS('Individual Data'!$AA$6:$AA$3142,'Individual Data'!$U$6:$U$3142,'age-length prop'!$B11,'Individual Data'!$X$6:$X$3142,'age-length prop'!H$7,'Individual Data'!$Q$6:$Q$3142,'age-length prop'!$C11,'Individual Data'!$M$6:$M$3142,'age-length prop'!$B$6) -> 17.185227 | I11: =SUMIFS('Individual Data'!$AA$6:$AA$3142,'Individual Data'!$U$6:$U$3142,'age-length prop'!$B11,'Individual Data'!$X$6:$X$3142,'age-length prop'!I$7,'Individual Data'!$Q$6:$Q$3142,'age-length prop'!$C11,'Individual Data'!$M$6:$M$3142,'age-length prop'!$B$6) -> 0 | J11: =SUMIFS('Individual Data'!$AA$6:$AA$3142,'Individual Data'!$U$6:$U$3142,'age-length prop'!$B11,'Individual Data'!$X$6:$X$3142,'age-length prop'!J$7,'Individual Data'!$Q$6:$Q$3142,'age-length prop'!$C11,'Individual Data'!$M$6:$M$3142,'age-length prop'!$B$6) -> 118.86449 | K11: =SUMIFS('Individual Data'!$AA$6:$AA$3142,'Individual Data'!$U$6:$U$3142,'age-length prop'!$B11,'Individual Data'!$X$6:$X$3142,'age-length prop'!K$7,'Individual Data'!$Q$6:$Q$3142,'age-length prop'!$C11,'Individual Data'!$M$6:$M$3142,'age-length prop'!$B$6) -> 269.23523 | ... P11: =SUMIFS('Individual Data'!$AA$6:$AA$3142,'Individual Data'!$U$6:$U$3142,'age-length prop'!$B11,'Individual Data'!$X$6:$X$3142,'age-length prop'!P$7,'Individual Data'!$Q$6:$Q$3142,'age-length prop'!$C11,'Individual Data'!$M$6:$M$3142,'age-length prop'!$B$6) -> 0 | Q11: =IFERROR(D11+(D$5*(D11/D$6)),0) -> 0 | R11: =IFERROR(E11+(E$5*(E11/E$6)),0) -> 0 | S11: =IFERROR(F11+(F$5*(F11/F$6)),0) -> 0 | T11: =IFERROR(G11+(G$5*(G11/G$6)),0) -> 0 | U11: =IFERROR(H11+(H$5*(H11/H$6)),0) -> 17.873784 | V11: =IFERROR(I11+(I$5*(I11/I$6)),0) -> 0 | W11: =IFERROR(J11+(J$5*(J11/J$6)),0) -> 123.77118 | X11: =IFERROR(K11+(K$5*(K11/K$6)),0) -> 276.89574 | ... AC11: =IFERROR(P11+(P$5*(P11/P$6)),0) -> 0 | AD11: =VLOOKUP(A11,'PBT Tag Rates'!$B$5:$E$34,4,FALSE) -> 0.80551598 | AE11: =Q11/$AD11 -> 0 | AF11: =R11/$AD11 -> 0 | AG11: =S11/$AD11 -> 0 | AH11: =T11/$AD11 -> 0 | AI11: =U11/$AD11 -> 22.189236 | AJ11: =V11/$AD11 -> 0 | AK11: =W11/$AD11 -> 153.65452 | AL11: =X11/$AD11 -> 343.74953 | ... AQ11: =AC11/$AD11 -> 0 | AS11: =SUM(AE11:AG11) -> 0 | AT11: =SUM(AH11:AQ11) -> 1066.3352 | AV11: =$AV$3-C11 -> 2018 | AW11: =B11 -> CJAe | AX11: SR | AY11: =SUMIFS('cwt rel info'!$A$6:$A$217,'cwt rel info'!$D$6:$D$217,'age-length prop'!AV11,'cwt rel info'!$E$6:$E$217,'age-length prop'!AW11) -> 220509 | AZ11: =AS11+AT11 -> 1066.3352 | BA11: =AT75 -> 833.90136 | BB11: =AS75 -> 0 | BC11: =VLOOKUP(AW11,'Individual Data'!$U$5:$AB$3142,8,FALSE) -> abv | BD11: =IF(BC11="blw",AZ11*(1-$BA$4),AZ11*(1-$BA$3)) -> 1023.6818 | BE11: =IF(BC11="blw",BA11*(1-$BA$4),BA11*(1-$BA$3)) -> 800.54531 | BF11: =IF(BC11="blw",BB11*(1-$BB$4),BB11*(1-$BB$3)) -> 0 | BK11: =AE11-Q11 -> 0 | BL11: =AF11-R11 -> 0 | BM11: =AG11-S11 -> 0 | BN11: =AH11-T11 -> 0 | BO11: =AI11-U11 -> 4.3154517 | BP11: =AJ11-V11 -> 0 | BQ11: =AK11-W11 -> 29.883349 | BR11: =AL11-X11 -> 66.85379 | ... BW11: =AQ11-AC11 -> 0 | BX11: =BY11/(BY11+BZ11) -> 0.43820225 | BY11: =SUMIFS('Individual Data'!$W$6:$W$3142,'Individual Data'!$I$6:$I$3142,'age-length prop'!BY$7,'Individual Data'!$U$6:$U$3142,'age-length prop'!$B11,'Individual Data'!$Q$6:$Q$3142,'age-length prop'!$C11) -> 39 | BZ11: =SUMIFS('Individual Data'!$W$6:$W$3142,'Individual Data'!$I$6:$I$3142,'age-length prop'!BZ$7,'Individual Data'!$U$6:$U$3142,'age-length prop'!$B11,'Individual Data'!$Q$6:$Q$3142,'age-length prop'!$C11) -> 50 | CA11: =BK11*$BX11 -> 0 | CB11: =BL11*$BX11 -> 0 | CC11: =BM11*$BX11 -> 0 | CD11: =BN11*$BX11 -> 0 | CE11: =BO11*$BX11 -> 1.8910406 | CF11: =BP11*$BX11 -> 0 | CG11: =BQ11*$BX11 -> 13.094951 | CH11: =BR11*$BX11 -> 29.295481 | ... CM11: =BW11*$BX11 -> 0 | CO11: =BK11*(1-$BX11) -> 0 | CP11: =BL11*(1-$BX11) -> 0 | CQ11: =BM11*(1-$BX11) -> 0 | CR11: =BN11*(1-$BX11) -> 0 | CS11: =BO11*(1-$BX11) -> 2.424411 | CT11: =BP11*(1-$BX11) -> 0 | CU11: =BQ11*(1-$BX11) -> 16.788398 | CV11: =BR11*(1-$BX11) -> 37.558309 | ... DA11: =BW11*(1-$BX11) -> 0
